The following modules were not unloaded:
  (Use "module --force purge" to unload all):

  1) StdEnv
Restoring modules from user's cuda, for system: "grace-rhel7"
2018-05-22 20:46:38.056411: I tensorflow/core/platform/cpu_feature_guard.cc:140] Your CPU supports instructions that this TensorFlow binary was not compiled to use: AVX2 FMA
/home/fas/leonard/swk2/miniconda3/envs/maskRCNN/lib/python3.6/site-packages/h5py/__init__.py:36: FutureWarning: Conversion of the second argument of issubdtype from `float` to `np.floating` is deprecated. In future, it will be treated as `np.float64 == np.dtype(float).type`.
  from ._conv import register_converters as _register_converters
Using TensorFlow backend.
WARNING:tensorflow:From /home/fas/leonard/swk2/miniconda3/envs/maskRCNN/lib/python3.6/site-packages/tensorflow/contrib/learn/python/learn/datasets/base.py:198: retry (from tensorflow.contrib.learn.python.learn.datasets.base) is deprecated and will be removed in a future version.
Instructions for updating:
Use the retry module or similar alternatives.
Weights:  coco
Dataset:  ../../datasets/illustrations
Logs:  /gpfs/loomis/project/fas/leonard/swk2/Mask_RCNN/logs

Configurations:
BACKBONE                       resnet101
BACKBONE_STRIDES               [4, 8, 16, 32, 64]
BATCH_SIZE                     2
BBOX_STD_DEV                   [0.1 0.1 0.2 0.2]
DETECTION_MAX_INSTANCES        100
DETECTION_MIN_CONFIDENCE       0.9
DETECTION_NMS_THRESHOLD        0.3
GPU_COUNT                      1
GRADIENT_CLIP_NORM             5.0
IMAGES_PER_GPU                 2
IMAGE_MAX_DIM                  1024
IMAGE_META_SIZE                14
IMAGE_MIN_DIM                  800
IMAGE_MIN_SCALE                0
IMAGE_RESIZE_MODE              square
IMAGE_SHAPE                    [1024 1024    3]
LEARNING_MOMENTUM              0.9
LEARNING_RATE                  0.001
LOSS_WEIGHTS                   {'rpn_class_loss': 1.0, 'rpn_bbox_loss': 1.0, 'mrcnn_class_loss': 1.0, 'mrcnn_bbox_loss': 1.0, 'mrcnn_mask_loss': 1.0}
MASK_POOL_SIZE                 14
MASK_SHAPE                     [28, 28]
MAX_GT_INSTANCES               100
MEAN_PIXEL                     [123.7 116.8 103.9]
MINI_MASK_SHAPE                (56, 56)
NAME                           balloon
NUM_CLASSES                    2
POOL_SIZE                      7
POST_NMS_ROIS_INFERENCE        1000
POST_NMS_ROIS_TRAINING         2000
ROI_POSITIVE_RATIO             0.33
RPN_ANCHOR_RATIOS              [0.5, 1, 2]
RPN_ANCHOR_SCALES              (32, 64, 128, 256, 512)
RPN_ANCHOR_STRIDE              1
RPN_BBOX_STD_DEV               [0.1 0.1 0.2 0.2]
RPN_NMS_THRESHOLD              0.7
RPN_TRAIN_ANCHORS_PER_IMAGE    256
STEPS_PER_EPOCH                100
TRAIN_BN                       False
TRAIN_ROIS_PER_IMAGE           200
USE_MINI_MASK                  True
USE_RPN_ROIS                   True
VALIDATION_STEPS               50
WEIGHT_DECAY                   0.0001


Loading weights  /gpfs/loomis/project/fas/leonard/swk2/Mask_RCNN/mask_rcnn_coco.h5
Training network heads

Starting at epoch 0. LR=0.001

Checkpoint Path: /gpfs/loomis/project/fas/leonard/swk2/Mask_RCNN/logs/balloon20180522T2046/mask_rcnn_balloon_{epoch:04d}.h5
Selecting layers to train
fpn_c5p5               (Conv2D)
fpn_c4p4               (Conv2D)
fpn_c3p3               (Conv2D)
fpn_c2p2               (Conv2D)
fpn_p5                 (Conv2D)
fpn_p2                 (Conv2D)
fpn_p3                 (Conv2D)
fpn_p4                 (Conv2D)
In model:  rpn_model
    rpn_conv_shared        (Conv2D)
    rpn_class_raw          (Conv2D)
    rpn_bbox_pred          (Conv2D)
mrcnn_mask_conv1       (TimeDistributed)
mrcnn_mask_bn1         (TimeDistributed)
mrcnn_mask_conv2       (TimeDistributed)
mrcnn_mask_bn2         (TimeDistributed)
mrcnn_class_conv1      (TimeDistributed)
mrcnn_class_bn1        (TimeDistributed)
mrcnn_mask_conv3       (TimeDistributed)
mrcnn_mask_bn3         (TimeDistributed)
mrcnn_class_conv2      (TimeDistributed)
mrcnn_class_bn2        (TimeDistributed)
mrcnn_mask_conv4       (TimeDistributed)
mrcnn_mask_bn4         (TimeDistributed)
mrcnn_bbox_fc          (TimeDistributed)
mrcnn_mask_deconv      (TimeDistributed)
mrcnn_class_logits     (TimeDistributed)
mrcnn_mask             (TimeDistributed)
/home/fas/leonard/swk2/miniconda3/envs/maskRCNN/lib/python3.6/site-packages/tensorflow/python/ops/gradients_impl.py:100: UserWarning: Converting sparse IndexedSlices to a dense Tensor of unknown shape. This may consume a large amount of memory.
  "Converting sparse IndexedSlices to a dense Tensor of unknown shape. "
/home/fas/leonard/swk2/miniconda3/envs/maskRCNN/lib/python3.6/site-packages/keras/engine/training.py:2087: UserWarning: Using a generator with `use_multiprocessing=True` and multiple workers may duplicate your data. Please consider using the`keras.utils.Sequence class.
  UserWarning('Using a generator with `use_multiprocessing=True`'
ERROR:root:Error processing image {'id': 'textbookofbotany00strauoft_0604.jpg', 'source': 'balloon', 'path': '../../datasets/illustrations/train/textbookofbotany00strauoft_0604.jpg', 'width': 1918, 'height': 3216, 'polygons': [{'name': 'rect', 'x': 261, 'y': 2208, 'width': 398, 'height': 421}, {'name': 'rect', 'x': 857, 'y': 510, 'width': 873, 'height': 2179}]}
Traceback (most recent call last):
  File "/home/fas/leonard/swk2/miniconda3/envs/maskRCNN/lib/python3.6/site-packages/mask_rcnn-2.1-py3.6.egg/mrcnn/model.py", line 1695, in data_generator
    use_mini_mask=config.USE_MINI_MASK)
  File "/home/fas/leonard/swk2/miniconda3/envs/maskRCNN/lib/python3.6/site-packages/mask_rcnn-2.1-py3.6.egg/mrcnn/model.py", line 1210, in load_image_gt
    mask, class_ids = dataset.load_mask(image_id)
  File "balloon.py", line 171, in load_mask
    mask[rr, cc, i] = 1
IndexError: index 2208 is out of bounds for axis 1 with size 1918
ERROR:root:Error processing image {'id': 'b21303502_0001_0191.jpg', 'source': 'balloon', 'path': '../../datasets/illustrations/train/b21303502_0001_0191.jpg', 'width': 1790, 'height': 3122, 'polygons': [{'name': 'rect', 'x': 297, 'y': 1011, 'width': 1085, 'height': 1029}]}
Traceback (most recent call last):
  File "/home/fas/leonard/swk2/miniconda3/envs/maskRCNN/lib/python3.6/site-packages/mask_rcnn-2.1-py3.6.egg/mrcnn/model.py", line 1695, in data_generator
    use_mini_mask=config.USE_MINI_MASK)
  File "/home/fas/leonard/swk2/miniconda3/envs/maskRCNN/lib/python3.6/site-packages/mask_rcnn-2.1-py3.6.egg/mrcnn/model.py", line 1210, in load_image_gt
    mask, class_ids = dataset.load_mask(image_id)
  File "balloon.py", line 171, in load_mask
    mask[rr, cc, i] = 1
IndexError: index 1790 is out of bounds for axis 1 with size 1790
ERROR:root:Error processing image {'id': 'b21303502_0001_0191.jpg', 'source': 'balloon', 'path': '../../datasets/illustrations/train/b21303502_0001_0191.jpg', 'width': 1790, 'height': 3122, 'polygons': [{'name': 'rect', 'x': 297, 'y': 1011, 'width': 1085, 'height': 1029}]}
Traceback (most recent call last):
  File "/home/fas/leonard/swk2/miniconda3/envs/maskRCNN/lib/python3.6/site-packages/mask_rcnn-2.1-py3.6.egg/mrcnn/model.py", line 1695, in data_generator
    use_mini_mask=config.USE_MINI_MASK)
  File "/home/fas/leonard/swk2/miniconda3/envs/maskRCNN/lib/python3.6/site-packages/mask_rcnn-2.1-py3.6.egg/mrcnn/model.py", line 1210, in load_image_gt
    mask, class_ids = dataset.load_mask(image_id)
  File "balloon.py", line 171, in load_mask
    mask[rr, cc, i] = 1
IndexError: index 1790 is out of bounds for axis 1 with size 1790
ERROR:root:Error processing image {'id': 'differentialdiag002cabo_0623.jpg', 'source': 'balloon', 'path': '../../datasets/illustrations/train/differentialdiag002cabo_0623.jpg', 'width': 2041, 'height': 3441, 'polygons': [{'name': 'rect', 'x': 460, 'y': 1046, 'width': 1145, 'height': 1250}]}
Traceback (most recent call last):
  File "/home/fas/leonard/swk2/miniconda3/envs/maskRCNN/lib/python3.6/site-packages/mask_rcnn-2.1-py3.6.egg/mrcnn/model.py", line 1695, in data_generator
    use_mini_mask=config.USE_MINI_MASK)
  File "/home/fas/leonard/swk2/miniconda3/envs/maskRCNN/lib/python3.6/site-packages/mask_rcnn-2.1-py3.6.egg/mrcnn/model.py", line 1210, in load_image_gt
    mask, class_ids = dataset.load_mask(image_id)
  File "balloon.py", line 171, in load_mask
    mask[rr, cc, i] = 1
IndexError: index 2041 is out of bounds for axis 1 with size 2041
ERROR:root:Error processing image {'id': 'b21932323_0188.jpg', 'source': 'balloon', 'path': '../../datasets/illustrations/train/b21932323_0188.jpg', 'width': 1811, 'height': 2946, 'polygons': [{'name': 'rect', 'x': 271, 'y': 612, 'width': 1315, 'height': 1362}]}
Traceback (most recent call last):
  File "/home/fas/leonard/swk2/miniconda3/envs/maskRCNN/lib/python3.6/site-packages/mask_rcnn-2.1-py3.6.egg/mrcnn/model.py", line 1695, in data_generator
    use_mini_mask=config.USE_MINI_MASK)
  File "/home/fas/leonard/swk2/miniconda3/envs/maskRCNN/lib/python3.6/site-packages/mask_rcnn-2.1-py3.6.egg/mrcnn/model.py", line 1210, in load_image_gt
    mask, class_ids = dataset.load_mask(image_id)
  File "balloon.py", line 171, in load_mask
    mask[rr, cc, i] = 1
IndexError: index 1811 is out of bounds for axis 1 with size 1811
ERROR:root:Error processing image {'id': 'lehrbuchderspeci001strm_0639.jpg', 'source': 'balloon', 'path': '../../datasets/illustrations/train/lehrbuchderspeci001strm_0639.jpg', 'width': 2065, 'height': 3269, 'polygons': [{'name': 'rect', 'x': 1314, 'y': 469, 'width': 320, 'height': 414}, {'name': 'rect', 'x': 1172, 'y': 1042, 'width': 641, 'height': 1660}]}
Traceback (most recent call last):
  File "/home/fas/leonard/swk2/miniconda3/envs/maskRCNN/lib/python3.6/site-packages/mask_rcnn-2.1-py3.6.egg/mrcnn/model.py", line 1695, in data_generator
    use_mini_mask=config.USE_MINI_MASK)
  File "/home/fas/leonard/swk2/miniconda3/envs/maskRCNN/lib/python3.6/site-packages/mask_rcnn-2.1-py3.6.egg/mrcnn/model.py", line 1210, in load_image_gt
    mask, class_ids = dataset.load_mask(image_id)
  File "balloon.py", line 171, in load_mask
    mask[rr, cc, i] = 1
IndexError: index 2065 is out of bounds for axis 1 with size 2065
ERROR:root:Error processing image {'id': 'textbookofdental00burc_0367.jpg', 'source': 'balloon', 'path': '../../datasets/illustrations/train/textbookofdental00burc_0367.jpg', 'width': 1990, 'height': 3381, 'polygons': [{'name': 'rect', 'x': 211, 'y': 905, 'width': 1568, 'height': 1276}]}
Traceback (most recent call last):
  File "/home/fas/leonard/swk2/miniconda3/envs/maskRCNN/lib/python3.6/site-packages/mask_rcnn-2.1-py3.6.egg/mrcnn/model.py", line 1695, in data_generator
    use_mini_mask=config.USE_MINI_MASK)
  File "/home/fas/leonard/swk2/miniconda3/envs/maskRCNN/lib/python3.6/site-packages/mask_rcnn-2.1-py3.6.egg/mrcnn/model.py", line 1210, in load_image_gt
    mask, class_ids = dataset.load_mask(image_id)
  File "balloon.py", line 171, in load_mask
    mask[rr, cc, i] = 1
IndexError: index 1990 is out of bounds for axis 1 with size 1990
ERROR:root:Error processing image {'id': 'b21357298_0133.jpg', 'source': 'balloon', 'path': '../../datasets/illustrations/train/b21357298_0133.jpg', 'width': 1660, 'height': 2826, 'polygons': [{'name': 'rect', 'x': 115, 'y': 647, 'width': 1257, 'height': 1366}]}
Traceback (most recent call last):
  File "/home/fas/leonard/swk2/miniconda3/envs/maskRCNN/lib/python3.6/site-packages/mask_rcnn-2.1-py3.6.egg/mrcnn/model.py", line 1695, in data_generator
    use_mini_mask=config.USE_MINI_MASK)
  File "/home/fas/leonard/swk2/miniconda3/envs/maskRCNN/lib/python3.6/site-packages/mask_rcnn-2.1-py3.6.egg/mrcnn/model.py", line 1210, in load_image_gt
    mask, class_ids = dataset.load_mask(image_id)
  File "balloon.py", line 171, in load_mask
    mask[rr, cc, i] = 1
IndexError: index 1660 is out of bounds for axis 1 with size 1660
ERROR:root:Error processing image {'id': 'missourimedicine5611miss_0352.jpg', 'source': 'balloon', 'path': '../../datasets/illustrations/train/missourimedicine5611miss_0352.jpg', 'width': 2513, 'height': 3695, 'polygons': [{'name': 'rect', 'x': 274, 'y': 530, 'width': 1075, 'height': 743}, {'name': 'rect', 'x': 271, 'y': 2052, 'width': 1075, 'height': 739}]}
Traceback (most recent call last):
  File "/home/fas/leonard/swk2/miniconda3/envs/maskRCNN/lib/python3.6/site-packages/mask_rcnn-2.1-py3.6.egg/mrcnn/model.py", line 1695, in data_generator
    use_mini_mask=config.USE_MINI_MASK)
  File "/home/fas/leonard/swk2/miniconda3/envs/maskRCNN/lib/python3.6/site-packages/mask_rcnn-2.1-py3.6.egg/mrcnn/model.py", line 1210, in load_image_gt
    mask, class_ids = dataset.load_mask(image_id)
  File "balloon.py", line 171, in load_mask
    mask[rr, cc, i] = 1
IndexError: index 2513 is out of bounds for axis 1 with size 2513
ERROR:root:Error processing image {'id': 'b29124815_0156.jpg', 'source': 'balloon', 'path': '../../datasets/illustrations/train/b29124815_0156.jpg', 'width': 1914, 'height': 3294, 'polygons': [{'name': 'rect', 'x': 212, 'y': 717, 'width': 1301, 'height': 1790}]}
Traceback (most recent call last):
  File "/home/fas/leonard/swk2/miniconda3/envs/maskRCNN/lib/python3.6/site-packages/mask_rcnn-2.1-py3.6.egg/mrcnn/model.py", line 1695, in data_generator
    use_mini_mask=config.USE_MINI_MASK)
  File "/home/fas/leonard/swk2/miniconda3/envs/maskRCNN/lib/python3.6/site-packages/mask_rcnn-2.1-py3.6.egg/mrcnn/model.py", line 1210, in load_image_gt
    mask, class_ids = dataset.load_mask(image_id)
  File "balloon.py", line 171, in load_mask
    mask[rr, cc, i] = 1
IndexError: index 1914 is out of bounds for axis 1 with size 1914
ERROR:root:Error processing image {'id': 'americanjournal46ameruoft_0831.jpg', 'source': 'balloon', 'path': '../../datasets/illustrations/train/americanjournal46ameruoft_0831.jpg', 'width': 2137, 'height': 3279, 'polygons': [{'name': 'rect', 'x': 487, 'y': 991, 'width': 1065, 'height': 1283}]}
Traceback (most recent call last):
  File "/home/fas/leonard/swk2/miniconda3/envs/maskRCNN/lib/python3.6/site-packages/mask_rcnn-2.1-py3.6.egg/mrcnn/model.py", line 1695, in data_generator
    use_mini_mask=config.USE_MINI_MASK)
  File "/home/fas/leonard/swk2/miniconda3/envs/maskRCNN/lib/python3.6/site-packages/mask_rcnn-2.1-py3.6.egg/mrcnn/model.py", line 1210, in load_image_gt
    mask, class_ids = dataset.load_mask(image_id)
  File "balloon.py", line 171, in load_mask
    mask[rr, cc, i] = 1
IndexError: index 2137 is out of bounds for axis 1 with size 2137
ERROR:root:Error processing image {'id': 'gynecology00grav_0307.jpg', 'source': 'balloon', 'path': '../../datasets/illustrations/train/gynecology00grav_0307.jpg', 'width': 2329, 'height': 3708, 'polygons': [{'name': 'rect', 'x': 279, 'y': 882, 'width': 1649, 'height': 1638}]}
Traceback (most recent call last):
  File "/home/fas/leonard/swk2/miniconda3/envs/maskRCNN/lib/python3.6/site-packages/mask_rcnn-2.1-py3.6.egg/mrcnn/model.py", line 1695, in data_generator
    use_mini_mask=config.USE_MINI_MASK)
  File "/home/fas/leonard/swk2/miniconda3/envs/maskRCNN/lib/python3.6/site-packages/mask_rcnn-2.1-py3.6.egg/mrcnn/model.py", line 1210, in load_image_gt
    mask, class_ids = dataset.load_mask(image_id)
  File "balloon.py", line 171, in load_mask
    mask[rr, cc, i] = 1
IndexError: index 2329 is out of bounds for axis 1 with size 2329
ERROR:root:Error processing image {'id': 'missourimedicine5611miss_0352.jpg', 'source': 'balloon', 'path': '../../datasets/illustrations/train/missourimedicine5611miss_0352.jpg', 'width': 2513, 'height': 3695, 'polygons': [{'name': 'rect', 'x': 274, 'y': 530, 'width': 1075, 'height': 743}, {'name': 'rect', 'x': 271, 'y': 2052, 'width': 1075, 'height': 739}]}
Traceback (most recent call last):
  File "/home/fas/leonard/swk2/miniconda3/envs/maskRCNN/lib/python3.6/site-packages/mask_rcnn-2.1-py3.6.egg/mrcnn/model.py", line 1695, in data_generator
    use_mini_mask=config.USE_MINI_MASK)
  File "/home/fas/leonard/swk2/miniconda3/envs/maskRCNN/lib/python3.6/site-packages/mask_rcnn-2.1-py3.6.egg/mrcnn/model.py", line 1210, in load_image_gt
    mask, class_ids = dataset.load_mask(image_id)
  File "balloon.py", line 171, in load_mask
    mask[rr, cc, i] = 1
IndexError: index 2513 is out of bounds for axis 1 with size 2513
ERROR:root:Error processing image {'id': 'gynecology00grav_0127.jpg', 'source': 'balloon', 'path': '../../datasets/illustrations/train/gynecology00grav_0127.jpg', 'width': 2329, 'height': 3708, 'polygons': [{'name': 'rect', 'x': 198, 'y': 1227, 'width': 1888, 'height': 1271}]}
Traceback (most recent call last):
  File "/home/fas/leonard/swk2/miniconda3/envs/maskRCNN/lib/python3.6/site-packages/mask_rcnn-2.1-py3.6.egg/mrcnn/model.py", line 1695, in data_generator
    use_mini_mask=config.USE_MINI_MASK)
  File "/home/fas/leonard/swk2/miniconda3/envs/maskRCNN/lib/python3.6/site-packages/mask_rcnn-2.1-py3.6.egg/mrcnn/model.py", line 1210, in load_image_gt
    mask, class_ids = dataset.load_mask(image_id)
  File "balloon.py", line 171, in load_mask
    mask[rr, cc, i] = 1
IndexError: index 2329 is out of bounds for axis 1 with size 2329
ERROR:root:Error processing image {'id': 'anatomicalmemoir21good_0494.jpg', 'source': 'balloon', 'path': '../../datasets/illustrations/train/anatomicalmemoir21good_0494.jpg', 'width': 1680, 'height': 2929, 'polygons': [{'name': 'rect', 'x': 84, 'y': 203, 'width': 1430, 'height': 2472}]}
Traceback (most recent call last):
  File "/home/fas/leonard/swk2/miniconda3/envs/maskRCNN/lib/python3.6/site-packages/mask_rcnn-2.1-py3.6.egg/mrcnn/model.py", line 1695, in data_generator
    use_mini_mask=config.USE_MINI_MASK)
  File "/home/fas/leonard/swk2/miniconda3/envs/maskRCNN/lib/python3.6/site-packages/mask_rcnn-2.1-py3.6.egg/mrcnn/model.py", line 1210, in load_image_gt
    mask, class_ids = dataset.load_mask(image_id)
  File "balloon.py", line 171, in load_mask
    mask[rr, cc, i] = 1
IndexError: index 1680 is out of bounds for axis 1 with size 1680
ERROR:root:Error processing image {'id': 'b21932323_0260.jpg', 'source': 'balloon', 'path': '../../datasets/illustrations/train/b21932323_0260.jpg', 'width': 1811, 'height': 2946, 'polygons': [{'name': 'rect', 'x': 782, 'y': 1881, 'width': 373, 'height': 385}]}
Traceback (most recent call last):
  File "/home/fas/leonard/swk2/miniconda3/envs/maskRCNN/lib/python3.6/site-packages/mask_rcnn-2.1-py3.6.egg/mrcnn/model.py", line 1695, in data_generator
    use_mini_mask=config.USE_MINI_MASK)
  File "/home/fas/leonard/swk2/miniconda3/envs/maskRCNN/lib/python3.6/site-packages/mask_rcnn-2.1-py3.6.egg/mrcnn/model.py", line 1210, in load_image_gt
    mask, class_ids = dataset.load_mask(image_id)
  File "balloon.py", line 171, in load_mask
    mask[rr, cc, i] = 1
IndexError: index 1881 is out of bounds for axis 1 with size 1811
ERROR:root:Error processing image {'id': 'glimpseofindiabe1909swai_0245.jpg', 'source': 'balloon', 'path': '../../datasets/illustrations/train/glimpseofindiabe1909swai_0245.jpg', 'width': 2106, 'height': 3360, 'polygons': [{'name': 'rect', 'x': 203, 'y': 526, 'width': 1461, 'height': 2069}]}
Traceback (most recent call last):
  File "/home/fas/leonard/swk2/miniconda3/envs/maskRCNN/lib/python3.6/site-packages/mask_rcnn-2.1-py3.6.egg/mrcnn/model.py", line 1695, in data_generator
    use_mini_mask=config.USE_MINI_MASK)
  File "/home/fas/leonard/swk2/miniconda3/envs/maskRCNN/lib/python3.6/site-packages/mask_rcnn-2.1-py3.6.egg/mrcnn/model.py", line 1210, in load_image_gt
    mask, class_ids = dataset.load_mask(image_id)
  File "balloon.py", line 171, in load_mask
    mask[rr, cc, i] = 1
IndexError: index 2106 is out of bounds for axis 1 with size 2106
ERROR:root:Error processing image {'id': 'b28120553_0263.jpg', 'source': 'balloon', 'path': '../../datasets/illustrations/train/b28120553_0263.jpg', 'width': 1789, 'height': 3082, 'polygons': [{'name': 'rect', 'x': 263, 'y': 64, 'width': 1310, 'height': 1099}, {'name': 'rect', 'x': 150, 'y': 1200, 'width': 681, 'height': 913}, {'name': 'rect', 'x': 1087, 'y': 1380, 'width': 614, 'height': 632}, {'name': 'rect', 'x': 986, 'y': 2158, 'width': 720, 'height': 757}, {'name': 'rect', 'x': 128, 'y': 2223, 'width': 659, 'height': 684}]}
Traceback (most recent call last):
  File "/home/fas/leonard/swk2/miniconda3/envs/maskRCNN/lib/python3.6/site-packages/mask_rcnn-2.1-py3.6.egg/mrcnn/model.py", line 1695, in data_generator
    use_mini_mask=config.USE_MINI_MASK)
  File "/home/fas/leonard/swk2/miniconda3/envs/maskRCNN/lib/python3.6/site-packages/mask_rcnn-2.1-py3.6.egg/mrcnn/model.py", line 1210, in load_image_gt
    mask, class_ids = dataset.load_mask(image_id)
  File "balloon.py", line 171, in load_mask
    mask[rr, cc, i] = 1
IndexError: index 1789 is out of bounds for axis 1 with size 1789
ERROR:root:Error processing image {'id': 'glimpseofindiabe1909swai_0245.jpg', 'source': 'balloon', 'path': '../../datasets/illustrations/train/glimpseofindiabe1909swai_0245.jpg', 'width': 2106, 'height': 3360, 'polygons': [{'name': 'rect', 'x': 203, 'y': 526, 'width': 1461, 'height': 2069}]}
Traceback (most recent call last):
  File "/home/fas/leonard/swk2/miniconda3/envs/maskRCNN/lib/python3.6/site-packages/mask_rcnn-2.1-py3.6.egg/mrcnn/model.py", line 1695, in data_generator
    use_mini_mask=config.USE_MINI_MASK)
  File "/home/fas/leonard/swk2/miniconda3/envs/maskRCNN/lib/python3.6/site-packages/mask_rcnn-2.1-py3.6.egg/mrcnn/model.py", line 1210, in load_image_gt
    mask, class_ids = dataset.load_mask(image_id)
  File "balloon.py", line 171, in load_mask
    mask[rr, cc, i] = 1
IndexError: index 2106 is out of bounds for axis 1 with size 2106
ERROR:root:Error processing image {'id': 'b21932323_0260.jpg', 'source': 'balloon', 'path': '../../datasets/illustrations/train/b21932323_0260.jpg', 'width': 1811, 'height': 2946, 'polygons': [{'name': 'rect', 'x': 782, 'y': 1881, 'width': 373, 'height': 385}]}
Traceback (most recent call last):
  File "/home/fas/leonard/swk2/miniconda3/envs/maskRCNN/lib/python3.6/site-packages/mask_rcnn-2.1-py3.6.egg/mrcnn/model.py", line 1695, in data_generator
    use_mini_mask=config.USE_MINI_MASK)
  File "/home/fas/leonard/swk2/miniconda3/envs/maskRCNN/lib/python3.6/site-packages/mask_rcnn-2.1-py3.6.egg/mrcnn/model.py", line 1210, in load_image_gt
    mask, class_ids = dataset.load_mask(image_id)
  File "balloon.py", line 171, in load_mask
    mask[rr, cc, i] = 1
IndexError: index 1881 is out of bounds for axis 1 with size 1811
ERROR:root:Error processing image {'id': 'b21357298_0133.jpg', 'source': 'balloon', 'path': '../../datasets/illustrations/train/b21357298_0133.jpg', 'width': 1660, 'height': 2826, 'polygons': [{'name': 'rect', 'x': 115, 'y': 647, 'width': 1257, 'height': 1366}]}
Traceback (most recent call last):
  File "/home/fas/leonard/swk2/miniconda3/envs/maskRCNN/lib/python3.6/site-packages/mask_rcnn-2.1-py3.6.egg/mrcnn/model.py", line 1695, in data_generator
    use_mini_mask=config.USE_MINI_MASK)
  File "/home/fas/leonard/swk2/miniconda3/envs/maskRCNN/lib/python3.6/site-packages/mask_rcnn-2.1-py3.6.egg/mrcnn/model.py", line 1210, in load_image_gt
    mask, class_ids = dataset.load_mask(image_id)
  File "balloon.py", line 171, in load_mask
    mask[rr, cc, i] = 1
IndexError: index 1660 is out of bounds for axis 1 with size 1660
ERROR:root:Error processing image {'id': 'americantextbook00essi_0480.jpg', 'source': 'balloon', 'path': '../../datasets/illustrations/train/americantextbook00essi_0480.jpg', 'width': 2121, 'height': 3452, 'polygons': [{'name': 'rect', 'x': 512, 'y': 615, 'width': 1025, 'height': 912}, {'name': 'rect', 'x': 362, 'y': 1930, 'width': 1356, 'height': 970}]}
Traceback (most recent call last):
  File "/home/fas/leonard/swk2/miniconda3/envs/maskRCNN/lib/python3.6/site-packages/mask_rcnn-2.1-py3.6.egg/mrcnn/model.py", line 1695, in data_generator
    use_mini_mask=config.USE_MINI_MASK)
  File "/home/fas/leonard/swk2/miniconda3/envs/maskRCNN/lib/python3.6/site-packages/mask_rcnn-2.1-py3.6.egg/mrcnn/model.py", line 1210, in load_image_gt
    mask, class_ids = dataset.load_mask(image_id)
  File "balloon.py", line 171, in load_mask
    mask[rr, cc, i] = 1
IndexError: index 2121 is out of bounds for axis 1 with size 2121
ERROR:root:Error processing image {'id': 'gynecology00grav_0127.jpg', 'source': 'balloon', 'path': '../../datasets/illustrations/train/gynecology00grav_0127.jpg', 'width': 2329, 'height': 3708, 'polygons': [{'name': 'rect', 'x': 198, 'y': 1227, 'width': 1888, 'height': 1271}]}
Traceback (most recent call last):
  File "/home/fas/leonard/swk2/miniconda3/envs/maskRCNN/lib/python3.6/site-packages/mask_rcnn-2.1-py3.6.egg/mrcnn/model.py", line 1695, in data_generator
    use_mini_mask=config.USE_MINI_MASK)
  File "/home/fas/leonard/swk2/miniconda3/envs/maskRCNN/lib/python3.6/site-packages/mask_rcnn-2.1-py3.6.egg/mrcnn/model.py", line 1210, in load_image_gt
    mask, class_ids = dataset.load_mask(image_id)
  File "balloon.py", line 171, in load_mask
    mask[rr, cc, i] = 1
IndexError: index 2329 is out of bounds for axis 1 with size 2329
ERROR:root:Error processing image {'id': 'hotspringsofbath00hattuoft_0009.jpg', 'source': 'balloon', 'path': '../../datasets/illustrations/train/hotspringsofbath00hattuoft_0009.jpg', 'width': 2027, 'height': 3192, 'polygons': [{'name': 'rect', 'x': 190, 'y': 421, 'width': 1518, 'height': 2223}]}
Traceback (most recent call last):
  File "/home/fas/leonard/swk2/miniconda3/envs/maskRCNN/lib/python3.6/site-packages/mask_rcnn-2.1-py3.6.egg/mrcnn/model.py", line 1695, in data_generator
    use_mini_mask=config.USE_MINI_MASK)
  File "/home/fas/leonard/swk2/miniconda3/envs/maskRCNN/lib/python3.6/site-packages/mask_rcnn-2.1-py3.6.egg/mrcnn/model.py", line 1210, in load_image_gt
    mask, class_ids = dataset.load_mask(image_id)
  File "balloon.py", line 171, in load_mask
    mask[rr, cc, i] = 1
IndexError: index 2027 is out of bounds for axis 1 with size 2027
ERROR:root:Error processing image {'id': 'appliedanatomyor00ivyr_0028.jpg', 'source': 'balloon', 'path': '../../datasets/illustrations/train/appliedanatomyor00ivyr_0028.jpg', 'width': 1818, 'height': 2865, 'polygons': [{'name': 'rect', 'x': 227, 'y': 851, 'width': 1395, 'height': 1027}]}
Traceback (most recent call last):
  File "/home/fas/leonard/swk2/miniconda3/envs/maskRCNN/lib/python3.6/site-packages/mask_rcnn-2.1-py3.6.egg/mrcnn/model.py", line 1695, in data_generator
    use_mini_mask=config.USE_MINI_MASK)
  File "/home/fas/leonard/swk2/miniconda3/envs/maskRCNN/lib/python3.6/site-packages/mask_rcnn-2.1-py3.6.egg/mrcnn/model.py", line 1210, in load_image_gt
    mask, class_ids = dataset.load_mask(image_id)
  File "balloon.py", line 171, in load_mask
    mask[rr, cc, i] = 1
IndexError: index 1818 is out of bounds for axis 1 with size 1818
ERROR:root:Error processing image {'id': '63571000R_0947.jpg', 'source': 'balloon', 'path': '../../datasets/illustrations/train/63571000R_0947.jpg', 'width': 1980, 'height': 3528, 'polygons': [{'name': 'rect', 'x': 496, 'y': 1502, 'width': 1083, 'height': 1582}]}
Traceback (most recent call last):
  File "/home/fas/leonard/swk2/miniconda3/envs/maskRCNN/lib/python3.6/site-packages/mask_rcnn-2.1-py3.6.egg/mrcnn/model.py", line 1695, in data_generator
    use_mini_mask=config.USE_MINI_MASK)
  File "/home/fas/leonard/swk2/miniconda3/envs/maskRCNN/lib/python3.6/site-packages/mask_rcnn-2.1-py3.6.egg/mrcnn/model.py", line 1210, in load_image_gt
    mask, class_ids = dataset.load_mask(image_id)
  File "balloon.py", line 171, in load_mask
    mask[rr, cc, i] = 1
IndexError: index 1980 is out of bounds for axis 1 with size 1980
ERROR:root:Error processing image {'id': 'exceptionalchild00roma_0013.jpg', 'source': 'balloon', 'path': '../../datasets/illustrations/train/exceptionalchild00roma_0013.jpg', 'width': 2853, 'height': 2081, 'polygons': [{'name': 'rect', 'x': 173, 'y': 445, 'width': 2130, 'height': 1341}]}
Traceback (most recent call last):
  File "/home/fas/leonard/swk2/miniconda3/envs/maskRCNN/lib/python3.6/site-packages/mask_rcnn-2.1-py3.6.egg/mrcnn/model.py", line 1695, in data_generator
    use_mini_mask=config.USE_MINI_MASK)
  File "/home/fas/leonard/swk2/miniconda3/envs/maskRCNN/lib/python3.6/site-packages/mask_rcnn-2.1-py3.6.egg/mrcnn/model.py", line 1210, in load_image_gt
    mask, class_ids = dataset.load_mask(image_id)
  File "balloon.py", line 171, in load_mask
    mask[rr, cc, i] = 1
IndexError: index 2081 is out of bounds for axis 0 with size 2081
ERROR:root:Error processing image {'id': 'b21648979_0064.jpg', 'source': 'balloon', 'path': '../../datasets/illustrations/train/b21648979_0064.jpg', 'width': 2309, 'height': 4147, 'polygons': [{'name': 'rect', 'x': 440, 'y': 1097, 'width': 1438, 'height': 1491}]}
Traceback (most recent call last):
  File "/home/fas/leonard/swk2/miniconda3/envs/maskRCNN/lib/python3.6/site-packages/mask_rcnn-2.1-py3.6.egg/mrcnn/model.py", line 1695, in data_generator
    use_mini_mask=config.USE_MINI_MASK)
  File "/home/fas/leonard/swk2/miniconda3/envs/maskRCNN/lib/python3.6/site-packages/mask_rcnn-2.1-py3.6.egg/mrcnn/model.py", line 1210, in load_image_gt
    mask, class_ids = dataset.load_mask(image_id)
  File "balloon.py", line 171, in load_mask
    mask[rr, cc, i] = 1
IndexError: index 2309 is out of bounds for axis 1 with size 2309
ERROR:root:Error processing image {'id': 'hotspringsofbath00hattuoft_0009.jpg', 'source': 'balloon', 'path': '../../datasets/illustrations/train/hotspringsofbath00hattuoft_0009.jpg', 'width': 2027, 'height': 3192, 'polygons': [{'name': 'rect', 'x': 190, 'y': 421, 'width': 1518, 'height': 2223}]}
Traceback (most recent call last):
  File "/home/fas/leonard/swk2/miniconda3/envs/maskRCNN/lib/python3.6/site-packages/mask_rcnn-2.1-py3.6.egg/mrcnn/model.py", line 1695, in data_generator
    use_mini_mask=config.USE_MINI_MASK)
  File "/home/fas/leonard/swk2/miniconda3/envs/maskRCNN/lib/python3.6/site-packages/mask_rcnn-2.1-py3.6.egg/mrcnn/model.py", line 1210, in load_image_gt
    mask, class_ids = dataset.load_mask(image_id)
  File "balloon.py", line 171, in load_mask
    mask[rr, cc, i] = 1
IndexError: index 2027 is out of bounds for axis 1 with size 2027
ERROR:root:Error processing image {'id': 'b21303502_0001_0191.jpg', 'source': 'balloon', 'path': '../../datasets/illustrations/train/b21303502_0001_0191.jpg', 'width': 1790, 'height': 3122, 'polygons': [{'name': 'rect', 'x': 297, 'y': 1011, 'width': 1085, 'height': 1029}]}
Traceback (most recent call last):
  File "/home/fas/leonard/swk2/miniconda3/envs/maskRCNN/lib/python3.6/site-packages/mask_rcnn-2.1-py3.6.egg/mrcnn/model.py", line 1695, in data_generator
    use_mini_mask=config.USE_MINI_MASK)
  File "/home/fas/leonard/swk2/miniconda3/envs/maskRCNN/lib/python3.6/site-packages/mask_rcnn-2.1-py3.6.egg/mrcnn/model.py", line 1210, in load_image_gt
    mask, class_ids = dataset.load_mask(image_id)
  File "balloon.py", line 171, in load_mask
    mask[rr, cc, i] = 1
IndexError: index 1790 is out of bounds for axis 1 with size 1790
ERROR:root:Error processing image {'id': 'gynecology00grav_0713.jpg', 'source': 'balloon', 'path': '../../datasets/illustrations/train/gynecology00grav_0713.jpg', 'width': 2329, 'height': 3708, 'polygons': [{'name': 'rect', 'x': 665, 'y': 823, 'width': 996, 'height': 1763}]}
Traceback (most recent call last):
  File "/home/fas/leonard/swk2/miniconda3/envs/maskRCNN/lib/python3.6/site-packages/mask_rcnn-2.1-py3.6.egg/mrcnn/model.py", line 1695, in data_generator
    use_mini_mask=config.USE_MINI_MASK)
  File "/home/fas/leonard/swk2/miniconda3/envs/maskRCNN/lib/python3.6/site-packages/mask_rcnn-2.1-py3.6.egg/mrcnn/model.py", line 1210, in load_image_gt
    mask, class_ids = dataset.load_mask(image_id)
  File "balloon.py", line 171, in load_mask
    mask[rr, cc, i] = 1
IndexError: index 2329 is out of bounds for axis 1 with size 2329
ERROR:root:Error processing image {'id': '63571000R_0947.jpg', 'source': 'balloon', 'path': '../../datasets/illustrations/train/63571000R_0947.jpg', 'width': 1980, 'height': 3528, 'polygons': [{'name': 'rect', 'x': 496, 'y': 1502, 'width': 1083, 'height': 1582}]}
Traceback (most recent call last):
  File "/home/fas/leonard/swk2/miniconda3/envs/maskRCNN/lib/python3.6/site-packages/mask_rcnn-2.1-py3.6.egg/mrcnn/model.py", line 1695, in data_generator
    use_mini_mask=config.USE_MINI_MASK)
  File "/home/fas/leonard/swk2/miniconda3/envs/maskRCNN/lib/python3.6/site-packages/mask_rcnn-2.1-py3.6.egg/mrcnn/model.py", line 1210, in load_image_gt
    mask, class_ids = dataset.load_mask(image_id)
  File "balloon.py", line 171, in load_mask
    mask[rr, cc, i] = 1
IndexError: index 1980 is out of bounds for axis 1 with size 1980
ERROR:root:Error processing image {'id': 'dentalcosmos5186whit_0034.jpg', 'source': 'balloon', 'path': '../../datasets/illustrations/train/dentalcosmos5186whit_0034.jpg', 'width': 2490, 'height': 4058, 'polygons': [{'name': 'rect', 'x': 145, 'y': 683, 'width': 996, 'height': 767}, {'name': 'rect', 'x': 1209, 'y': 546, 'width': 1145, 'height': 988}, {'name': 'rect', 'x': 76, 'y': 2149, 'width': 1161, 'height': 1028}, {'name': 'rect', 'x': 1253, 'y': 2133, 'width': 1185, 'height': 972}]}
Traceback (most recent call last):
  File "/home/fas/leonard/swk2/miniconda3/envs/maskRCNN/lib/python3.6/site-packages/mask_rcnn-2.1-py3.6.egg/mrcnn/model.py", line 1695, in data_generator
    use_mini_mask=config.USE_MINI_MASK)
  File "/home/fas/leonard/swk2/miniconda3/envs/maskRCNN/lib/python3.6/site-packages/mask_rcnn-2.1-py3.6.egg/mrcnn/model.py", line 1210, in load_image_gt
    mask, class_ids = dataset.load_mask(image_id)
  File "balloon.py", line 171, in load_mask
    mask[rr, cc, i] = 1
IndexError: index 2490 is out of bounds for axis 1 with size 2490
ERROR:root:Error processing image {'id': 'b29123082_0081.jpg', 'source': 'balloon', 'path': '../../datasets/illustrations/train/b29123082_0081.jpg', 'width': 2024, 'height': 3346, 'polygons': [{'name': 'rect', 'x': 23, 'y': 788, 'width': 1988, 'height': 1534}]}
Traceback (most recent call last):
  File "/home/fas/leonard/swk2/miniconda3/envs/maskRCNN/lib/python3.6/site-packages/mask_rcnn-2.1-py3.6.egg/mrcnn/model.py", line 1695, in data_generator
    use_mini_mask=config.USE_MINI_MASK)
  File "/home/fas/leonard/swk2/miniconda3/envs/maskRCNN/lib/python3.6/site-packages/mask_rcnn-2.1-py3.6.egg/mrcnn/model.py", line 1210, in load_image_gt
    mask, class_ids = dataset.load_mask(image_id)
  File "balloon.py", line 171, in load_mask
    mask[rr, cc, i] = 1
IndexError: index 2024 is out of bounds for axis 1 with size 2024
ERROR:root:Error processing image {'id': 'terramariaemedic00unse_14_0026.jpg', 'source': 'balloon', 'path': '../../datasets/illustrations/train/terramariaemedic00unse_14_0026.jpg', 'width': 3472, 'height': 4657, 'polygons': [{'name': 'rect', 'x': 5, 'y': 1203, 'width': 959, 'height': 1434}, {'name': 'rect', 'x': 1024, 'y': 563, 'width': 1305, 'height': 1014}, {'name': 'rect', 'x': 2379, 'y': 138, 'width': 1079, 'height': 1425}, {'name': 'rect', 'x': 1019, 'y': 1637, 'width': 1434, 'height': 1001}, {'name': 'rect', 'x': 2518, 'y': 1632, 'width': 941, 'height': 1005}, {'name': 'rect', 'x': 0, 'y': 2716, 'width': 752, 'height': 1070}, {'name': 'rect', 'x': 802, 'y': 2707, 'width': 788, 'height': 1074}, {'name': 'rect', 'x': 1660, 'y': 2716, 'width': 798, 'height': 1079}, {'name': 'rect', 'x': 2518, 'y': 2716, 'width': 936, 'height': 1485}]}
Traceback (most recent call last):
  File "/home/fas/leonard/swk2/miniconda3/envs/maskRCNN/lib/python3.6/site-packages/mask_rcnn-2.1-py3.6.egg/mrcnn/model.py", line 1695, in data_generator
    use_mini_mask=config.USE_MINI_MASK)
  File "/home/fas/leonard/swk2/miniconda3/envs/maskRCNN/lib/python3.6/site-packages/mask_rcnn-2.1-py3.6.egg/mrcnn/model.py", line 1210, in load_image_gt
    mask, class_ids = dataset.load_mask(image_id)
  File "balloon.py", line 171, in load_mask
    mask[rr, cc, i] = 1
IndexError: index 3472 is out of bounds for axis 1 with size 3472
ERROR:root:Error processing image {'id': '67440190R_0259.jpg', 'source': 'balloon', 'path': '../../datasets/illustrations/train/67440190R_0259.jpg', 'width': 3357, 'height': 4424, 'polygons': [{'name': 'rect', 'x': 596, 'y': 618, 'width': 1898, 'height': 1451}, {'name': 'rect', 'x': 543, 'y': 2331, 'width': 1998, 'height': 1437}]}
Traceback (most recent call last):
  File "/home/fas/leonard/swk2/miniconda3/envs/maskRCNN/lib/python3.6/site-packages/mask_rcnn-2.1-py3.6.egg/mrcnn/model.py", line 1695, in data_generator
    use_mini_mask=config.USE_MINI_MASK)
  File "/home/fas/leonard/swk2/miniconda3/envs/maskRCNN/lib/python3.6/site-packages/mask_rcnn-2.1-py3.6.egg/mrcnn/model.py", line 1210, in load_image_gt
    mask, class_ids = dataset.load_mask(image_id)
  File "balloon.py", line 171, in load_mask
    mask[rr, cc, i] = 1
IndexError: index 3357 is out of bounds for axis 1 with size 3357
ERROR:root:Error processing image {'id': 'americanjournal46ameruoft_0831.jpg', 'source': 'balloon', 'path': '../../datasets/illustrations/train/americanjournal46ameruoft_0831.jpg', 'width': 2137, 'height': 3279, 'polygons': [{'name': 'rect', 'x': 487, 'y': 991, 'width': 1065, 'height': 1283}]}
Traceback (most recent call last):
  File "/home/fas/leonard/swk2/miniconda3/envs/maskRCNN/lib/python3.6/site-packages/mask_rcnn-2.1-py3.6.egg/mrcnn/model.py", line 1695, in data_generator
    use_mini_mask=config.USE_MINI_MASK)
  File "/home/fas/leonard/swk2/miniconda3/envs/maskRCNN/lib/python3.6/site-packages/mask_rcnn-2.1-py3.6.egg/mrcnn/model.py", line 1210, in load_image_gt
    mask, class_ids = dataset.load_mask(image_id)
  File "balloon.py", line 171, in load_mask
    mask[rr, cc, i] = 1
IndexError: index 2137 is out of bounds for axis 1 with size 2137
ERROR:root:Error processing image {'id': 'americantextbook00essi_0177.jpg', 'source': 'balloon', 'path': '../../datasets/illustrations/train/americantextbook00essi_0177.jpg', 'width': 2121, 'height': 3452, 'polygons': [{'name': 'rect', 'x': 1305, 'y': 1554, 'width': 587, 'height': 178}, {'name': 'rect', 'x': 1079, 'y': 2097, 'width': 768, 'height': 225}, {'name': 'rect', 'x': 212, 'y': 2637, 'width': 710, 'height': 239}, {'name': 'rect', 'x': 1055, 'y': 2633, 'width': 724, 'height': 219}]}
Traceback (most recent call last):
  File "/home/fas/leonard/swk2/miniconda3/envs/maskRCNN/lib/python3.6/site-packages/mask_rcnn-2.1-py3.6.egg/mrcnn/model.py", line 1695, in data_generator
    use_mini_mask=config.USE_MINI_MASK)
  File "/home/fas/leonard/swk2/miniconda3/envs/maskRCNN/lib/python3.6/site-packages/mask_rcnn-2.1-py3.6.egg/mrcnn/model.py", line 1210, in load_image_gt
    mask, class_ids = dataset.load_mask(image_id)
  File "balloon.py", line 171, in load_mask
    mask[rr, cc, i] = 1
IndexError: index 2121 is out of bounds for axis 1 with size 2121
ERROR:root:Error processing image {'id': 'exceptionalchild00roma_0013.jpg', 'source': 'balloon', 'path': '../../datasets/illustrations/train/exceptionalchild00roma_0013.jpg', 'width': 2853, 'height': 2081, 'polygons': [{'name': 'rect', 'x': 173, 'y': 445, 'width': 2130, 'height': 1341}]}
Traceback (most recent call last):
  File "/home/fas/leonard/swk2/miniconda3/envs/maskRCNN/lib/python3.6/site-packages/mask_rcnn-2.1-py3.6.egg/mrcnn/model.py", line 1695, in data_generator
    use_mini_mask=config.USE_MINI_MASK)
  File "/home/fas/leonard/swk2/miniconda3/envs/maskRCNN/lib/python3.6/site-packages/mask_rcnn-2.1-py3.6.egg/mrcnn/model.py", line 1210, in load_image_gt
    mask, class_ids = dataset.load_mask(image_id)
  File "balloon.py", line 171, in load_mask
    mask[rr, cc, i] = 1
IndexError: index 2081 is out of bounds for axis 0 with size 2081
ERROR:root:Error processing image {'id': 'proceedingsofann1875ameruoft_0636.jpg', 'source': 'balloon', 'path': '../../datasets/illustrations/train/proceedingsofann1875ameruoft_0636.jpg', 'width': 2003, 'height': 3439, 'polygons': [{'name': 'rect', 'x': 518, 'y': 1128, 'width': 1206, 'height': 1553}]}
Traceback (most recent call last):
  File "/home/fas/leonard/swk2/miniconda3/envs/maskRCNN/lib/python3.6/site-packages/mask_rcnn-2.1-py3.6.egg/mrcnn/model.py", line 1695, in data_generator
    use_mini_mask=config.USE_MINI_MASK)
  File "/home/fas/leonard/swk2/miniconda3/envs/maskRCNN/lib/python3.6/site-packages/mask_rcnn-2.1-py3.6.egg/mrcnn/model.py", line 1210, in load_image_gt
    mask, class_ids = dataset.load_mask(image_id)
  File "balloon.py", line 171, in load_mask
    mask[rr, cc, i] = 1
IndexError: index 2003 is out of bounds for axis 1 with size 2003
ERROR:root:Error processing image {'id': 'b28120553_0263.jpg', 'source': 'balloon', 'path': '../../datasets/illustrations/train/b28120553_0263.jpg', 'width': 1789, 'height': 3082, 'polygons': [{'name': 'rect', 'x': 263, 'y': 64, 'width': 1310, 'height': 1099}, {'name': 'rect', 'x': 150, 'y': 1200, 'width': 681, 'height': 913}, {'name': 'rect', 'x': 1087, 'y': 1380, 'width': 614, 'height': 632}, {'name': 'rect', 'x': 986, 'y': 2158, 'width': 720, 'height': 757}, {'name': 'rect', 'x': 128, 'y': 2223, 'width': 659, 'height': 684}]}
Traceback (most recent call last):
  File "/home/fas/leonard/swk2/miniconda3/envs/maskRCNN/lib/python3.6/site-packages/mask_rcnn-2.1-py3.6.egg/mrcnn/model.py", line 1695, in data_generator
    use_mini_mask=config.USE_MINI_MASK)
  File "/home/fas/leonard/swk2/miniconda3/envs/maskRCNN/lib/python3.6/site-packages/mask_rcnn-2.1-py3.6.egg/mrcnn/model.py", line 1210, in load_image_gt
    mask, class_ids = dataset.load_mask(image_id)
  File "balloon.py", line 171, in load_mask
    mask[rr, cc, i] = 1
IndexError: index 1789 is out of bounds for axis 1 with size 1789
ERROR:root:Error processing image {'id': 'differentialdiag002cabo_0138.jpg', 'source': 'balloon', 'path': '../../datasets/illustrations/train/differentialdiag002cabo_0138.jpg', 'width': 2102, 'height': 3453, 'polygons': [{'name': 'rect', 'x': 608, 'y': 885, 'width': 1114, 'height': 1470}]}
Traceback (most recent call last):
  File "/home/fas/leonard/swk2/miniconda3/envs/maskRCNN/lib/python3.6/site-packages/mask_rcnn-2.1-py3.6.egg/mrcnn/model.py", line 1695, in data_generator
    use_mini_mask=config.USE_MINI_MASK)
  File "/home/fas/leonard/swk2/miniconda3/envs/maskRCNN/lib/python3.6/site-packages/mask_rcnn-2.1-py3.6.egg/mrcnn/model.py", line 1210, in load_image_gt
    mask, class_ids = dataset.load_mask(image_id)
  File "balloon.py", line 171, in load_mask
    mask[rr, cc, i] = 1
IndexError: index 2102 is out of bounds for axis 1 with size 2102
ERROR:root:Error processing image {'id': 'americantextbook00essi_0480.jpg', 'source': 'balloon', 'path': '../../datasets/illustrations/train/americantextbook00essi_0480.jpg', 'width': 2121, 'height': 3452, 'polygons': [{'name': 'rect', 'x': 512, 'y': 615, 'width': 1025, 'height': 912}, {'name': 'rect', 'x': 362, 'y': 1930, 'width': 1356, 'height': 970}]}
Traceback (most recent call last):
  File "/home/fas/leonard/swk2/miniconda3/envs/maskRCNN/lib/python3.6/site-packages/mask_rcnn-2.1-py3.6.egg/mrcnn/model.py", line 1695, in data_generator
    use_mini_mask=config.USE_MINI_MASK)
  File "/home/fas/leonard/swk2/miniconda3/envs/maskRCNN/lib/python3.6/site-packages/mask_rcnn-2.1-py3.6.egg/mrcnn/model.py", line 1210, in load_image_gt
    mask, class_ids = dataset.load_mask(image_id)
  File "balloon.py", line 171, in load_mask
    mask[rr, cc, i] = 1
IndexError: index 2121 is out of bounds for axis 1 with size 2121
ERROR:root:Error processing image {'id': 'b29123082_0081.jpg', 'source': 'balloon', 'path': '../../datasets/illustrations/train/b29123082_0081.jpg', 'width': 2024, 'height': 3346, 'polygons': [{'name': 'rect', 'x': 23, 'y': 788, 'width': 1988, 'height': 1534}]}
Traceback (most recent call last):
  File "/home/fas/leonard/swk2/miniconda3/envs/maskRCNN/lib/python3.6/site-packages/mask_rcnn-2.1-py3.6.egg/mrcnn/model.py", line 1695, in data_generator
    use_mini_mask=config.USE_MINI_MASK)
  File "/home/fas/leonard/swk2/miniconda3/envs/maskRCNN/lib/python3.6/site-packages/mask_rcnn-2.1-py3.6.egg/mrcnn/model.py", line 1210, in load_image_gt
    mask, class_ids = dataset.load_mask(image_id)
  File "balloon.py", line 171, in load_mask
    mask[rr, cc, i] = 1
IndexError: index 2024 is out of bounds for axis 1 with size 2024
ERROR:root:Error processing image {'id': 'b2193311x_0654.jpg', 'source': 'balloon', 'path': '../../datasets/illustrations/train/b2193311x_0654.jpg', 'width': 1759, 'height': 3008, 'polygons': [{'name': 'rect', 'x': 193, 'y': 95, 'width': 1369, 'height': 2708}]}
Traceback (most recent call last):
  File "/home/fas/leonard/swk2/miniconda3/envs/maskRCNN/lib/python3.6/site-packages/mask_rcnn-2.1-py3.6.egg/mrcnn/model.py", line 1695, in data_generator
    use_mini_mask=config.USE_MINI_MASK)
  File "/home/fas/leonard/swk2/miniconda3/envs/maskRCNN/lib/python3.6/site-packages/mask_rcnn-2.1-py3.6.egg/mrcnn/model.py", line 1210, in load_image_gt
    mask, class_ids = dataset.load_mask(image_id)
  File "balloon.py", line 171, in load_mask
    mask[rr, cc, i] = 1
IndexError: index 1759 is out of bounds for axis 1 with size 1759
ERROR:root:Error processing image {'id': 's3edinburghmedical04edinuoft_0477.jpg', 'source': 'balloon', 'path': '../../datasets/illustrations/train/s3edinburghmedical04edinuoft_0477.jpg', 'width': 2126, 'height': 3206, 'polygons': [{'name': 'rect', 'x': 267, 'y': 320, 'width': 1355, 'height': 1165}, {'name': 'rect', 'x': 311, 'y': 1717, 'width': 1260, 'height': 1092}]}
Traceback (most recent call last):
  File "/home/fas/leonard/swk2/miniconda3/envs/maskRCNN/lib/python3.6/site-packages/mask_rcnn-2.1-py3.6.egg/mrcnn/model.py", line 1695, in data_generator
    use_mini_mask=config.USE_MINI_MASK)
  File "/home/fas/leonard/swk2/miniconda3/envs/maskRCNN/lib/python3.6/site-packages/mask_rcnn-2.1-py3.6.egg/mrcnn/model.py", line 1210, in load_image_gt
    mask, class_ids = dataset.load_mask(image_id)
  File "balloon.py", line 171, in load_mask
    mask[rr, cc, i] = 1
IndexError: index 2126 is out of bounds for axis 1 with size 2126
ERROR:root:Error processing image {'id': 'textbookofdental00burc_0367.jpg', 'source': 'balloon', 'path': '../../datasets/illustrations/train/textbookofdental00burc_0367.jpg', 'width': 1990, 'height': 3381, 'polygons': [{'name': 'rect', 'x': 211, 'y': 905, 'width': 1568, 'height': 1276}]}
Traceback (most recent call last):
  File "/home/fas/leonard/swk2/miniconda3/envs/maskRCNN/lib/python3.6/site-packages/mask_rcnn-2.1-py3.6.egg/mrcnn/model.py", line 1695, in data_generator
    use_mini_mask=config.USE_MINI_MASK)
  File "/home/fas/leonard/swk2/miniconda3/envs/maskRCNN/lib/python3.6/site-packages/mask_rcnn-2.1-py3.6.egg/mrcnn/model.py", line 1210, in load_image_gt
    mask, class_ids = dataset.load_mask(image_id)
  File "balloon.py", line 171, in load_mask
    mask[rr, cc, i] = 1
IndexError: index 1990 is out of bounds for axis 1 with size 1990
ERROR:root:Error processing image {'id': 'gynecology00grav_0307.jpg', 'source': 'balloon', 'path': '../../datasets/illustrations/train/gynecology00grav_0307.jpg', 'width': 2329, 'height': 3708, 'polygons': [{'name': 'rect', 'x': 279, 'y': 882, 'width': 1649, 'height': 1638}]}
Traceback (most recent call last):
  File "/home/fas/leonard/swk2/miniconda3/envs/maskRCNN/lib/python3.6/site-packages/mask_rcnn-2.1-py3.6.egg/mrcnn/model.py", line 1695, in data_generator
    use_mini_mask=config.USE_MINI_MASK)
  File "/home/fas/leonard/swk2/miniconda3/envs/maskRCNN/lib/python3.6/site-packages/mask_rcnn-2.1-py3.6.egg/mrcnn/model.py", line 1210, in load_image_gt
    mask, class_ids = dataset.load_mask(image_id)
  File "balloon.py", line 171, in load_mask
    mask[rr, cc, i] = 1
IndexError: index 2329 is out of bounds for axis 1 with size 2329
ERROR:root:Error processing image {'id': 'traitdesfistules00jobe_0373.jpg', 'source': 'balloon', 'path': '../../datasets/illustrations/train/traitdesfistules00jobe_0373.jpg', 'width': 2208, 'height': 3894, 'polygons': [{'name': 'rect', 'x': 69, 'y': 890, 'width': 1958, 'height': 2254}]}
Traceback (most recent call last):
  File "/home/fas/leonard/swk2/miniconda3/envs/maskRCNN/lib/python3.6/site-packages/mask_rcnn-2.1-py3.6.egg/mrcnn/model.py", line 1695, in data_generator
    use_mini_mask=config.USE_MINI_MASK)
  File "/home/fas/leonard/swk2/miniconda3/envs/maskRCNN/lib/python3.6/site-packages/mask_rcnn-2.1-py3.6.egg/mrcnn/model.py", line 1210, in load_image_gt
    mask, class_ids = dataset.load_mask(image_id)
  File "balloon.py", line 171, in load_mask
    mask[rr, cc, i] = 1
IndexError: index 2208 is out of bounds for axis 1 with size 2208
ERROR:root:Error processing image {'id': 'b28120553_0263.jpg', 'source': 'balloon', 'path': '../../datasets/illustrations/train/b28120553_0263.jpg', 'width': 1789, 'height': 3082, 'polygons': [{'name': 'rect', 'x': 263, 'y': 64, 'width': 1310, 'height': 1099}, {'name': 'rect', 'x': 150, 'y': 1200, 'width': 681, 'height': 913}, {'name': 'rect', 'x': 1087, 'y': 1380, 'width': 614, 'height': 632}, {'name': 'rect', 'x': 986, 'y': 2158, 'width': 720, 'height': 757}, {'name': 'rect', 'x': 128, 'y': 2223, 'width': 659, 'height': 684}]}
Traceback (most recent call last):
  File "/home/fas/leonard/swk2/miniconda3/envs/maskRCNN/lib/python3.6/site-packages/mask_rcnn-2.1-py3.6.egg/mrcnn/model.py", line 1695, in data_generator
    use_mini_mask=config.USE_MINI_MASK)
  File "/home/fas/leonard/swk2/miniconda3/envs/maskRCNN/lib/python3.6/site-packages/mask_rcnn-2.1-py3.6.egg/mrcnn/model.py", line 1210, in load_image_gt
    mask, class_ids = dataset.load_mask(image_id)
  File "balloon.py", line 171, in load_mask
    mask[rr, cc, i] = 1
IndexError: index 1789 is out of bounds for axis 1 with size 1789
ERROR:root:Error processing image {'id': 'differentialdiag002cabo_0138.jpg', 'source': 'balloon', 'path': '../../datasets/illustrations/train/differentialdiag002cabo_0138.jpg', 'width': 2102, 'height': 3453, 'polygons': [{'name': 'rect', 'x': 608, 'y': 885, 'width': 1114, 'height': 1470}]}
Traceback (most recent call last):
  File "/home/fas/leonard/swk2/miniconda3/envs/maskRCNN/lib/python3.6/site-packages/mask_rcnn-2.1-py3.6.egg/mrcnn/model.py", line 1695, in data_generator
    use_mini_mask=config.USE_MINI_MASK)
  File "/home/fas/leonard/swk2/miniconda3/envs/maskRCNN/lib/python3.6/site-packages/mask_rcnn-2.1-py3.6.egg/mrcnn/model.py", line 1210, in load_image_gt
    mask, class_ids = dataset.load_mask(image_id)
  File "balloon.py", line 171, in load_mask
    mask[rr, cc, i] = 1
IndexError: index 2102 is out of bounds for axis 1 with size 2102
Traceback (most recent call last):
  File "/home/fas/leonard/swk2/miniconda3/envs/maskRCNN/lib/python3.6/site-packages/keras/utils/data_utils.py", line 677, in _data_generator_task
    generator_output = next(self._generator)
  File "/home/fas/leonard/swk2/miniconda3/envs/maskRCNN/lib/python3.6/site-packages/mask_rcnn-2.1-py3.6.egg/mrcnn/model.py", line 1695, in data_generator
    use_mini_mask=config.USE_MINI_MASK)
  File "/home/fas/leonard/swk2/miniconda3/envs/maskRCNN/lib/python3.6/site-packages/mask_rcnn-2.1-py3.6.egg/mrcnn/model.py", line 1210, in load_image_gt
    mask, class_ids = dataset.load_mask(image_id)
  File "balloon.py", line 171, in load_mask
    mask[rr, cc, i] = 1
IndexError: index 2102 is out of bounds for axis 1 with size 2102
ERROR:root:Error processing image {'id': 'b29124815_0156.jpg', 'source': 'balloon', 'path': '../../datasets/illustrations/train/b29124815_0156.jpg', 'width': 1914, 'height': 3294, 'polygons': [{'name': 'rect', 'x': 212, 'y': 717, 'width': 1301, 'height': 1790}]}
Traceback (most recent call last):
  File "/home/fas/leonard/swk2/miniconda3/envs/maskRCNN/lib/python3.6/site-packages/mask_rcnn-2.1-py3.6.egg/mrcnn/model.py", line 1695, in data_generator
    use_mini_mask=config.USE_MINI_MASK)
  File "/home/fas/leonard/swk2/miniconda3/envs/maskRCNN/lib/python3.6/site-packages/mask_rcnn-2.1-py3.6.egg/mrcnn/model.py", line 1210, in load_image_gt
    mask, class_ids = dataset.load_mask(image_id)
  File "balloon.py", line 171, in load_mask
    mask[rr, cc, i] = 1
IndexError: index 1914 is out of bounds for axis 1 with size 1914
ERROR:root:Error processing image {'id': 'b21932323_0188.jpg', 'source': 'balloon', 'path': '../../datasets/illustrations/train/b21932323_0188.jpg', 'width': 1811, 'height': 2946, 'polygons': [{'name': 'rect', 'x': 271, 'y': 612, 'width': 1315, 'height': 1362}]}
Traceback (most recent call last):
  File "/home/fas/leonard/swk2/miniconda3/envs/maskRCNN/lib/python3.6/site-packages/mask_rcnn-2.1-py3.6.egg/mrcnn/model.py", line 1695, in data_generator
    use_mini_mask=config.USE_MINI_MASK)
  File "/home/fas/leonard/swk2/miniconda3/envs/maskRCNN/lib/python3.6/site-packages/mask_rcnn-2.1-py3.6.egg/mrcnn/model.py", line 1210, in load_image_gt
    mask, class_ids = dataset.load_mask(image_id)
  File "balloon.py", line 171, in load_mask
    mask[rr, cc, i] = 1
IndexError: index 1811 is out of bounds for axis 1 with size 1811
ERROR:root:Error processing image {'id': 'b2812098x_0002_0093.jpg', 'source': 'balloon', 'path': '../../datasets/illustrations/train/b2812098x_0002_0093.jpg', 'width': 1809, 'height': 3069, 'polygons': [{'name': 'rect', 'x': 821, 'y': 833, 'width': 784, 'height': 1627}]}
Traceback (most recent call last):
  File "/home/fas/leonard/swk2/miniconda3/envs/maskRCNN/lib/python3.6/site-packages/mask_rcnn-2.1-py3.6.egg/mrcnn/model.py", line 1695, in data_generator
    use_mini_mask=config.USE_MINI_MASK)
  File "/home/fas/leonard/swk2/miniconda3/envs/maskRCNN/lib/python3.6/site-packages/mask_rcnn-2.1-py3.6.egg/mrcnn/model.py", line 1210, in load_image_gt
    mask, class_ids = dataset.load_mask(image_id)
  File "balloon.py", line 171, in load_mask
    mask[rr, cc, i] = 1
IndexError: index 1809 is out of bounds for axis 1 with size 1809
ERROR:root:Error processing image {'id': 'b21648979_0064.jpg', 'source': 'balloon', 'path': '../../datasets/illustrations/train/b21648979_0064.jpg', 'width': 2309, 'height': 4147, 'polygons': [{'name': 'rect', 'x': 440, 'y': 1097, 'width': 1438, 'height': 1491}]}
Traceback (most recent call last):
  File "/home/fas/leonard/swk2/miniconda3/envs/maskRCNN/lib/python3.6/site-packages/mask_rcnn-2.1-py3.6.egg/mrcnn/model.py", line 1695, in data_generator
    use_mini_mask=config.USE_MINI_MASK)
  File "/home/fas/leonard/swk2/miniconda3/envs/maskRCNN/lib/python3.6/site-packages/mask_rcnn-2.1-py3.6.egg/mrcnn/model.py", line 1210, in load_image_gt
    mask, class_ids = dataset.load_mask(image_id)
  File "balloon.py", line 171, in load_mask
    mask[rr, cc, i] = 1
IndexError: index 2309 is out of bounds for axis 1 with size 2309
ERROR:root:Error processing image {'id': 'textbookofbotany00strauoft_0604.jpg', 'source': 'balloon', 'path': '../../datasets/illustrations/train/textbookofbotany00strauoft_0604.jpg', 'width': 1918, 'height': 3216, 'polygons': [{'name': 'rect', 'x': 261, 'y': 2208, 'width': 398, 'height': 421}, {'name': 'rect', 'x': 857, 'y': 510, 'width': 873, 'height': 2179}]}
Traceback (most recent call last):
  File "/home/fas/leonard/swk2/miniconda3/envs/maskRCNN/lib/python3.6/site-packages/mask_rcnn-2.1-py3.6.egg/mrcnn/model.py", line 1695, in data_generator
    use_mini_mask=config.USE_MINI_MASK)
  File "/home/fas/leonard/swk2/miniconda3/envs/maskRCNN/lib/python3.6/site-packages/mask_rcnn-2.1-py3.6.egg/mrcnn/model.py", line 1210, in load_image_gt
    mask, class_ids = dataset.load_mask(image_id)
  File "balloon.py", line 171, in load_mask
    mask[rr, cc, i] = 1
IndexError: index 2208 is out of bounds for axis 1 with size 1918
ERROR:root:Error processing image {'id': 'b21932323_0260.jpg', 'source': 'balloon', 'path': '../../datasets/illustrations/train/b21932323_0260.jpg', 'width': 1811, 'height': 2946, 'polygons': [{'name': 'rect', 'x': 782, 'y': 1881, 'width': 373, 'height': 385}]}
Traceback (most recent call last):
  File "/home/fas/leonard/swk2/miniconda3/envs/maskRCNN/lib/python3.6/site-packages/mask_rcnn-2.1-py3.6.egg/mrcnn/model.py", line 1695, in data_generator
    use_mini_mask=config.USE_MINI_MASK)
  File "/home/fas/leonard/swk2/miniconda3/envs/maskRCNN/lib/python3.6/site-packages/mask_rcnn-2.1-py3.6.egg/mrcnn/model.py", line 1210, in load_image_gt
    mask, class_ids = dataset.load_mask(image_id)
  File "balloon.py", line 171, in load_mask
    mask[rr, cc, i] = 1
IndexError: index 1881 is out of bounds for axis 1 with size 1811
ERROR:root:Error processing image {'id': 'b28120553_0263.jpg', 'source': 'balloon', 'path': '../../datasets/illustrations/train/b28120553_0263.jpg', 'width': 1789, 'height': 3082, 'polygons': [{'name': 'rect', 'x': 263, 'y': 64, 'width': 1310, 'height': 1099}, {'name': 'rect', 'x': 150, 'y': 1200, 'width': 681, 'height': 913}, {'name': 'rect', 'x': 1087, 'y': 1380, 'width': 614, 'height': 632}, {'name': 'rect', 'x': 986, 'y': 2158, 'width': 720, 'height': 757}, {'name': 'rect', 'x': 128, 'y': 2223, 'width': 659, 'height': 684}]}
Traceback (most recent call last):
  File "/home/fas/leonard/swk2/miniconda3/envs/maskRCNN/lib/python3.6/site-packages/mask_rcnn-2.1-py3.6.egg/mrcnn/model.py", line 1695, in data_generator
    use_mini_mask=config.USE_MINI_MASK)
  File "/home/fas/leonard/swk2/miniconda3/envs/maskRCNN/lib/python3.6/site-packages/mask_rcnn-2.1-py3.6.egg/mrcnn/model.py", line 1210, in load_image_gt
    mask, class_ids = dataset.load_mask(image_id)
  File "balloon.py", line 171, in load_mask
    mask[rr, cc, i] = 1
IndexError: index 1789 is out of bounds for axis 1 with size 1789
ERROR:root:Error processing image {'id': 'principlespracti00bedf_0066.jpg', 'source': 'balloon', 'path': '../../datasets/illustrations/train/principlespracti00bedf_0066.jpg', 'width': 2493, 'height': 4262, 'polygons': [{'name': 'rect', 'x': 569, 'y': 2607, 'width': 1375, 'height': 1050}]}
Traceback (most recent call last):
  File "/home/fas/leonard/swk2/miniconda3/envs/maskRCNN/lib/python3.6/site-packages/mask_rcnn-2.1-py3.6.egg/mrcnn/model.py", line 1695, in data_generator
    use_mini_mask=config.USE_MINI_MASK)
  File "/home/fas/leonard/swk2/miniconda3/envs/maskRCNN/lib/python3.6/site-packages/mask_rcnn-2.1-py3.6.egg/mrcnn/model.py", line 1210, in load_image_gt
    mask, class_ids = dataset.load_mask(image_id)
  File "balloon.py", line 171, in load_mask
    mask[rr, cc, i] = 1
IndexError: index 2607 is out of bounds for axis 1 with size 2493
ERROR:root:Error processing image {'id': 'gynecology00grav_0787.jpg', 'source': 'balloon', 'path': '../../datasets/illustrations/train/gynecology00grav_0787.jpg', 'width': 2329, 'height': 3708, 'polygons': [{'name': 'rect', 'x': 165, 'y': 918, 'width': 1958, 'height': 1528}]}
Traceback (most recent call last):
  File "/home/fas/leonard/swk2/miniconda3/envs/maskRCNN/lib/python3.6/site-packages/mask_rcnn-2.1-py3.6.egg/mrcnn/model.py", line 1695, in data_generator
    use_mini_mask=config.USE_MINI_MASK)
  File "/home/fas/leonard/swk2/miniconda3/envs/maskRCNN/lib/python3.6/site-packages/mask_rcnn-2.1-py3.6.egg/mrcnn/model.py", line 1210, in load_image_gt
    mask, class_ids = dataset.load_mask(image_id)
  File "balloon.py", line 171, in load_mask
    mask[rr, cc, i] = 1
IndexError: index 2329 is out of bounds for axis 1 with size 2329
Traceback (most recent call last):
  File "/home/fas/leonard/swk2/miniconda3/envs/maskRCNN/lib/python3.6/site-packages/keras/utils/data_utils.py", line 677, in _data_generator_task
    generator_output = next(self._generator)
  File "/home/fas/leonard/swk2/miniconda3/envs/maskRCNN/lib/python3.6/site-packages/mask_rcnn-2.1-py3.6.egg/mrcnn/model.py", line 1695, in data_generator
    use_mini_mask=config.USE_MINI_MASK)
  File "/home/fas/leonard/swk2/miniconda3/envs/maskRCNN/lib/python3.6/site-packages/mask_rcnn-2.1-py3.6.egg/mrcnn/model.py", line 1210, in load_image_gt
    mask, class_ids = dataset.load_mask(image_id)
  File "balloon.py", line 171, in load_mask
    mask[rr, cc, i] = 1
IndexError: index 2329 is out of bounds for axis 1 with size 2329
ERROR:root:Error processing image {'id': 'textbookofbotany00strauoft_0681.jpg', 'source': 'balloon', 'path': '../../datasets/illustrations/train/textbookofbotany00strauoft_0681.jpg', 'width': 1918, 'height': 3216, 'polygons': [{'name': 'rect', 'x': 201, 'y': 366, 'width': 1354, 'height': 2425}]}
Traceback (most recent call last):
  File "/home/fas/leonard/swk2/miniconda3/envs/maskRCNN/lib/python3.6/site-packages/mask_rcnn-2.1-py3.6.egg/mrcnn/model.py", line 1695, in data_generator
    use_mini_mask=config.USE_MINI_MASK)
  File "/home/fas/leonard/swk2/miniconda3/envs/maskRCNN/lib/python3.6/site-packages/mask_rcnn-2.1-py3.6.egg/mrcnn/model.py", line 1210, in load_image_gt
    mask, class_ids = dataset.load_mask(image_id)
  File "balloon.py", line 171, in load_mask
    mask[rr, cc, i] = 1
IndexError: index 1918 is out of bounds for axis 1 with size 1918
ERROR:root:Error processing image {'id': 'terramariaemedic00unse_14_0128.jpg', 'source': 'balloon', 'path': '../../datasets/illustrations/train/terramariaemedic00unse_14_0128.jpg', 'width': 3546, 'height': 4678, 'polygons': [{'name': 'rect', 'x': 819, 'y': 875, 'width': 1018, 'height': 1301}, {'name': 'rect', 'x': 1898, 'y': 5, 'width': 1592, 'height': 2162}, {'name': 'rect', 'x': 523, 'y': 3449, 'width': 1528, 'height': 870}, {'name': 'rect', 'x': 2111, 'y': 3032, 'width': 1370, 'height': 995}, {'name': 'rect', 'x': 176, 'y': 2236, 'width': 1870, 'height': 1153}]}
Traceback (most recent call last):
  File "/home/fas/leonard/swk2/miniconda3/envs/maskRCNN/lib/python3.6/site-packages/mask_rcnn-2.1-py3.6.egg/mrcnn/model.py", line 1695, in data_generator
    use_mini_mask=config.USE_MINI_MASK)
  File "/home/fas/leonard/swk2/miniconda3/envs/maskRCNN/lib/python3.6/site-packages/mask_rcnn-2.1-py3.6.egg/mrcnn/model.py", line 1210, in load_image_gt
    mask, class_ids = dataset.load_mask(image_id)
  File "balloon.py", line 171, in load_mask
    mask[rr, cc, i] = 1
IndexError: index 3546 is out of bounds for axis 1 with size 3546
ERROR:root:Error processing image {'id': 'terramariaemedic00unse_14_0128.jpg', 'source': 'balloon', 'path': '../../datasets/illustrations/train/terramariaemedic00unse_14_0128.jpg', 'width': 3546, 'height': 4678, 'polygons': [{'name': 'rect', 'x': 819, 'y': 875, 'width': 1018, 'height': 1301}, {'name': 'rect', 'x': 1898, 'y': 5, 'width': 1592, 'height': 2162}, {'name': 'rect', 'x': 523, 'y': 3449, 'width': 1528, 'height': 870}, {'name': 'rect', 'x': 2111, 'y': 3032, 'width': 1370, 'height': 995}, {'name': 'rect', 'x': 176, 'y': 2236, 'width': 1870, 'height': 1153}]}
Traceback (most recent call last):
  File "/home/fas/leonard/swk2/miniconda3/envs/maskRCNN/lib/python3.6/site-packages/mask_rcnn-2.1-py3.6.egg/mrcnn/model.py", line 1695, in data_generator
    use_mini_mask=config.USE_MINI_MASK)
  File "/home/fas/leonard/swk2/miniconda3/envs/maskRCNN/lib/python3.6/site-packages/mask_rcnn-2.1-py3.6.egg/mrcnn/model.py", line 1210, in load_image_gt
    mask, class_ids = dataset.load_mask(image_id)
  File "balloon.py", line 171, in load_mask
    mask[rr, cc, i] = 1
IndexError: index 3546 is out of bounds for axis 1 with size 3546
ERROR:root:Error processing image {'id': '67440190R_0259.jpg', 'source': 'balloon', 'path': '../../datasets/illustrations/train/67440190R_0259.jpg', 'width': 3357, 'height': 4424, 'polygons': [{'name': 'rect', 'x': 596, 'y': 618, 'width': 1898, 'height': 1451}, {'name': 'rect', 'x': 543, 'y': 2331, 'width': 1998, 'height': 1437}]}
Traceback (most recent call last):
  File "/home/fas/leonard/swk2/miniconda3/envs/maskRCNN/lib/python3.6/site-packages/mask_rcnn-2.1-py3.6.egg/mrcnn/model.py", line 1695, in data_generator
    use_mini_mask=config.USE_MINI_MASK)
  File "/home/fas/leonard/swk2/miniconda3/envs/maskRCNN/lib/python3.6/site-packages/mask_rcnn-2.1-py3.6.egg/mrcnn/model.py", line 1210, in load_image_gt
    mask, class_ids = dataset.load_mask(image_id)
  File "balloon.py", line 171, in load_mask
    mask[rr, cc, i] = 1
IndexError: index 3357 is out of bounds for axis 1 with size 3357
ERROR:root:Error processing image {'id': 'differentialdiag002cabo_0117.jpg', 'source': 'balloon', 'path': '../../datasets/illustrations/train/differentialdiag002cabo_0117.jpg', 'width': 2102, 'height': 3453, 'polygons': [{'name': 'rect', 'x': 362, 'y': 885, 'width': 1142, 'height': 1477}]}
Traceback (most recent call last):
  File "/home/fas/leonard/swk2/miniconda3/envs/maskRCNN/lib/python3.6/site-packages/mask_rcnn-2.1-py3.6.egg/mrcnn/model.py", line 1695, in data_generator
    use_mini_mask=config.USE_MINI_MASK)
  File "/home/fas/leonard/swk2/miniconda3/envs/maskRCNN/lib/python3.6/site-packages/mask_rcnn-2.1-py3.6.egg/mrcnn/model.py", line 1210, in load_image_gt
    mask, class_ids = dataset.load_mask(image_id)
  File "balloon.py", line 171, in load_mask
    mask[rr, cc, i] = 1
IndexError: index 2102 is out of bounds for axis 1 with size 2102
ERROR:root:Error processing image {'id': 'transactionsstud4161coll_0123.jpg', 'source': 'balloon', 'path': '../../datasets/illustrations/train/transactionsstud4161coll_0123.jpg', 'width': 2204, 'height': 3345, 'polygons': [{'name': 'rect', 'x': 46, 'y': 219, 'width': 2002, 'height': 1558}, {'name': 'rect', 'x': 388, 'y': 1853, 'width': 1299, 'height': 1021}]}
Traceback (most recent call last):
  File "/home/fas/leonard/swk2/miniconda3/envs/maskRCNN/lib/python3.6/site-packages/mask_rcnn-2.1-py3.6.egg/mrcnn/model.py", line 1695, in data_generator
    use_mini_mask=config.USE_MINI_MASK)
  File "/home/fas/leonard/swk2/miniconda3/envs/maskRCNN/lib/python3.6/site-packages/mask_rcnn-2.1-py3.6.egg/mrcnn/model.py", line 1210, in load_image_gt
    mask, class_ids = dataset.load_mask(image_id)
  File "balloon.py", line 171, in load_mask
    mask[rr, cc, i] = 1
IndexError: index 2204 is out of bounds for axis 1 with size 2204
ERROR:root:Error processing image {'id': 'textbookofbotany00strauoft_0604.jpg', 'source': 'balloon', 'path': '../../datasets/illustrations/train/textbookofbotany00strauoft_0604.jpg', 'width': 1918, 'height': 3216, 'polygons': [{'name': 'rect', 'x': 261, 'y': 2208, 'width': 398, 'height': 421}, {'name': 'rect', 'x': 857, 'y': 510, 'width': 873, 'height': 2179}]}
Traceback (most recent call last):
  File "/home/fas/leonard/swk2/miniconda3/envs/maskRCNN/lib/python3.6/site-packages/mask_rcnn-2.1-py3.6.egg/mrcnn/model.py", line 1695, in data_generator
    use_mini_mask=config.USE_MINI_MASK)
  File "/home/fas/leonard/swk2/miniconda3/envs/maskRCNN/lib/python3.6/site-packages/mask_rcnn-2.1-py3.6.egg/mrcnn/model.py", line 1210, in load_image_gt
    mask, class_ids = dataset.load_mask(image_id)
  File "balloon.py", line 171, in load_mask
    mask[rr, cc, i] = 1
IndexError: index 2208 is out of bounds for axis 1 with size 1918
ERROR:root:Error processing image {'id': 'b2150751x_0001_0585.jpg', 'source': 'balloon', 'path': '../../datasets/illustrations/train/b2150751x_0001_0585.jpg', 'width': 2025, 'height': 3331, 'polygons': [{'name': 'rect', 'x': 937, 'y': 1200, 'width': 729, 'height': 930}]}
Traceback (most recent call last):
  File "/home/fas/leonard/swk2/miniconda3/envs/maskRCNN/lib/python3.6/site-packages/mask_rcnn-2.1-py3.6.egg/mrcnn/model.py", line 1695, in data_generator
    use_mini_mask=config.USE_MINI_MASK)
  File "/home/fas/leonard/swk2/miniconda3/envs/maskRCNN/lib/python3.6/site-packages/mask_rcnn-2.1-py3.6.egg/mrcnn/model.py", line 1210, in load_image_gt
    mask, class_ids = dataset.load_mask(image_id)
  File "balloon.py", line 171, in load_mask
    mask[rr, cc, i] = 1
IndexError: index 2025 is out of bounds for axis 1 with size 2025
ERROR:root:Error processing image {'id': 'newjerseymedicin9611medi_0202.jpg', 'source': 'balloon', 'path': '../../datasets/illustrations/train/newjerseymedicin9611medi_0202.jpg', 'width': 2623, 'height': 3742, 'polygons': [{'name': 'rect', 'x': 170, 'y': 571, 'width': 2397, 'height': 2808}]}
Traceback (most recent call last):
  File "/home/fas/leonard/swk2/miniconda3/envs/maskRCNN/lib/python3.6/site-packages/mask_rcnn-2.1-py3.6.egg/mrcnn/model.py", line 1695, in data_generator
    use_mini_mask=config.USE_MINI_MASK)
  File "/home/fas/leonard/swk2/miniconda3/envs/maskRCNN/lib/python3.6/site-packages/mask_rcnn-2.1-py3.6.egg/mrcnn/model.py", line 1210, in load_image_gt
    mask, class_ids = dataset.load_mask(image_id)
  File "balloon.py", line 171, in load_mask
    mask[rr, cc, i] = 1
IndexError: index 2623 is out of bounds for axis 1 with size 2623
ERROR:root:Error processing image {'id': 'newyorkpresbyter00newy_2_0024.jpg', 'source': 'balloon', 'path': '../../datasets/illustrations/train/newyorkpresbyter00newy_2_0024.jpg', 'width': 2870, 'height': 3820, 'polygons': [{'name': 'rect', 'x': 95, 'y': 942, 'width': 2707, 'height': 2613}]}
Traceback (most recent call last):
  File "/home/fas/leonard/swk2/miniconda3/envs/maskRCNN/lib/python3.6/site-packages/mask_rcnn-2.1-py3.6.egg/mrcnn/model.py", line 1695, in data_generator
    use_mini_mask=config.USE_MINI_MASK)
  File "/home/fas/leonard/swk2/miniconda3/envs/maskRCNN/lib/python3.6/site-packages/mask_rcnn-2.1-py3.6.egg/mrcnn/model.py", line 1210, in load_image_gt
    mask, class_ids = dataset.load_mask(image_id)
  File "balloon.py", line 171, in load_mask
    mask[rr, cc, i] = 1
IndexError: index 2870 is out of bounds for axis 1 with size 2870
ERROR:root:Error processing image {'id': 'hotspringsofbath00hattuoft_0009.jpg', 'source': 'balloon', 'path': '../../datasets/illustrations/train/hotspringsofbath00hattuoft_0009.jpg', 'width': 2027, 'height': 3192, 'polygons': [{'name': 'rect', 'x': 190, 'y': 421, 'width': 1518, 'height': 2223}]}
Traceback (most recent call last):
  File "/home/fas/leonard/swk2/miniconda3/envs/maskRCNN/lib/python3.6/site-packages/mask_rcnn-2.1-py3.6.egg/mrcnn/model.py", line 1695, in data_generator
    use_mini_mask=config.USE_MINI_MASK)
  File "/home/fas/leonard/swk2/miniconda3/envs/maskRCNN/lib/python3.6/site-packages/mask_rcnn-2.1-py3.6.egg/mrcnn/model.py", line 1210, in load_image_gt
    mask, class_ids = dataset.load_mask(image_id)
  File "balloon.py", line 171, in load_mask
    mask[rr, cc, i] = 1
IndexError: index 2027 is out of bounds for axis 1 with size 2027
Traceback (most recent call last):
  File "/home/fas/leonard/swk2/miniconda3/envs/maskRCNN/lib/python3.6/site-packages/keras/utils/data_utils.py", line 677, in _data_generator_task
    generator_output = next(self._generator)
  File "/home/fas/leonard/swk2/miniconda3/envs/maskRCNN/lib/python3.6/site-packages/mask_rcnn-2.1-py3.6.egg/mrcnn/model.py", line 1695, in data_generator
    use_mini_mask=config.USE_MINI_MASK)
  File "/home/fas/leonard/swk2/miniconda3/envs/maskRCNN/lib/python3.6/site-packages/mask_rcnn-2.1-py3.6.egg/mrcnn/model.py", line 1210, in load_image_gt
    mask, class_ids = dataset.load_mask(image_id)
  File "balloon.py", line 171, in load_mask
    mask[rr, cc, i] = 1
IndexError: index 2027 is out of bounds for axis 1 with size 2027
ERROR:root:Error processing image {'id': 'transactamersurg26ameruoft_0566.jpg', 'source': 'balloon', 'path': '../../datasets/illustrations/train/transactamersurg26ameruoft_0566.jpg', 'width': 2099, 'height': 3490, 'polygons': [{'name': 'rect', 'x': 228, 'y': 498, 'width': 1795, 'height': 2417}]}
Traceback (most recent call last):
  File "/home/fas/leonard/swk2/miniconda3/envs/maskRCNN/lib/python3.6/site-packages/mask_rcnn-2.1-py3.6.egg/mrcnn/model.py", line 1695, in data_generator
    use_mini_mask=config.USE_MINI_MASK)
  File "/home/fas/leonard/swk2/miniconda3/envs/maskRCNN/lib/python3.6/site-packages/mask_rcnn-2.1-py3.6.egg/mrcnn/model.py", line 1210, in load_image_gt
    mask, class_ids = dataset.load_mask(image_id)
  File "balloon.py", line 171, in load_mask
    mask[rr, cc, i] = 1
IndexError: index 2099 is out of bounds for axis 1 with size 2099
ERROR:root:Error processing image {'id': 'americantextbook00essi_0177.jpg', 'source': 'balloon', 'path': '../../datasets/illustrations/train/americantextbook00essi_0177.jpg', 'width': 2121, 'height': 3452, 'polygons': [{'name': 'rect', 'x': 1305, 'y': 1554, 'width': 587, 'height': 178}, {'name': 'rect', 'x': 1079, 'y': 2097, 'width': 768, 'height': 225}, {'name': 'rect', 'x': 212, 'y': 2637, 'width': 710, 'height': 239}, {'name': 'rect', 'x': 1055, 'y': 2633, 'width': 724, 'height': 219}]}
Traceback (most recent call last):
  File "/home/fas/leonard/swk2/miniconda3/envs/maskRCNN/lib/python3.6/site-packages/mask_rcnn-2.1-py3.6.egg/mrcnn/model.py", line 1695, in data_generator
    use_mini_mask=config.USE_MINI_MASK)
  File "/home/fas/leonard/swk2/miniconda3/envs/maskRCNN/lib/python3.6/site-packages/mask_rcnn-2.1-py3.6.egg/mrcnn/model.py", line 1210, in load_image_gt
    mask, class_ids = dataset.load_mask(image_id)
  File "balloon.py", line 171, in load_mask
    mask[rr, cc, i] = 1
IndexError: index 2121 is out of bounds for axis 1 with size 2121
ERROR:root:Error processing image {'id': 'differentialdiag002cabo_0138.jpg', 'source': 'balloon', 'path': '../../datasets/illustrations/train/differentialdiag002cabo_0138.jpg', 'width': 2102, 'height': 3453, 'polygons': [{'name': 'rect', 'x': 608, 'y': 885, 'width': 1114, 'height': 1470}]}
Traceback (most recent call last):
  File "/home/fas/leonard/swk2/miniconda3/envs/maskRCNN/lib/python3.6/site-packages/mask_rcnn-2.1-py3.6.egg/mrcnn/model.py", line 1695, in data_generator
    use_mini_mask=config.USE_MINI_MASK)
  File "/home/fas/leonard/swk2/miniconda3/envs/maskRCNN/lib/python3.6/site-packages/mask_rcnn-2.1-py3.6.egg/mrcnn/model.py", line 1210, in load_image_gt
    mask, class_ids = dataset.load_mask(image_id)
  File "balloon.py", line 171, in load_mask
    mask[rr, cc, i] = 1
IndexError: index 2102 is out of bounds for axis 1 with size 2102
ERROR:root:Error processing image {'id': 'proceedingsofann1875ameruoft_0636.jpg', 'source': 'balloon', 'path': '../../datasets/illustrations/train/proceedingsofann1875ameruoft_0636.jpg', 'width': 2003, 'height': 3439, 'polygons': [{'name': 'rect', 'x': 518, 'y': 1128, 'width': 1206, 'height': 1553}]}
Traceback (most recent call last):
  File "/home/fas/leonard/swk2/miniconda3/envs/maskRCNN/lib/python3.6/site-packages/mask_rcnn-2.1-py3.6.egg/mrcnn/model.py", line 1695, in data_generator
    use_mini_mask=config.USE_MINI_MASK)
  File "/home/fas/leonard/swk2/miniconda3/envs/maskRCNN/lib/python3.6/site-packages/mask_rcnn-2.1-py3.6.egg/mrcnn/model.py", line 1210, in load_image_gt
    mask, class_ids = dataset.load_mask(image_id)
  File "balloon.py", line 171, in load_mask
    mask[rr, cc, i] = 1
IndexError: index 2003 is out of bounds for axis 1 with size 2003
ERROR:root:Error processing image {'id': 'anatomicalmemoir21good_0494.jpg', 'source': 'balloon', 'path': '../../datasets/illustrations/train/anatomicalmemoir21good_0494.jpg', 'width': 1680, 'height': 2929, 'polygons': [{'name': 'rect', 'x': 84, 'y': 203, 'width': 1430, 'height': 2472}]}
Traceback (most recent call last):
  File "/home/fas/leonard/swk2/miniconda3/envs/maskRCNN/lib/python3.6/site-packages/mask_rcnn-2.1-py3.6.egg/mrcnn/model.py", line 1695, in data_generator
    use_mini_mask=config.USE_MINI_MASK)
  File "/home/fas/leonard/swk2/miniconda3/envs/maskRCNN/lib/python3.6/site-packages/mask_rcnn-2.1-py3.6.egg/mrcnn/model.py", line 1210, in load_image_gt
    mask, class_ids = dataset.load_mask(image_id)
  File "balloon.py", line 171, in load_mask
    mask[rr, cc, i] = 1
IndexError: index 1680 is out of bounds for axis 1 with size 1680
ERROR:root:Error processing image {'id': 'gynecology00grav_0713.jpg', 'source': 'balloon', 'path': '../../datasets/illustrations/train/gynecology00grav_0713.jpg', 'width': 2329, 'height': 3708, 'polygons': [{'name': 'rect', 'x': 665, 'y': 823, 'width': 996, 'height': 1763}]}
Traceback (most recent call last):
  File "/home/fas/leonard/swk2/miniconda3/envs/maskRCNN/lib/python3.6/site-packages/mask_rcnn-2.1-py3.6.egg/mrcnn/model.py", line 1695, in data_generator
    use_mini_mask=config.USE_MINI_MASK)
  File "/home/fas/leonard/swk2/miniconda3/envs/maskRCNN/lib/python3.6/site-packages/mask_rcnn-2.1-py3.6.egg/mrcnn/model.py", line 1210, in load_image_gt
    mask, class_ids = dataset.load_mask(image_id)
  File "balloon.py", line 171, in load_mask
    mask[rr, cc, i] = 1
IndexError: index 2329 is out of bounds for axis 1 with size 2329
ERROR:root:Error processing image {'id': 'lehrbuchderspeci001strm_0639.jpg', 'source': 'balloon', 'path': '../../datasets/illustrations/train/lehrbuchderspeci001strm_0639.jpg', 'width': 2065, 'height': 3269, 'polygons': [{'name': 'rect', 'x': 1314, 'y': 469, 'width': 320, 'height': 414}, {'name': 'rect', 'x': 1172, 'y': 1042, 'width': 641, 'height': 1660}]}
Traceback (most recent call last):
  File "/home/fas/leonard/swk2/miniconda3/envs/maskRCNN/lib/python3.6/site-packages/mask_rcnn-2.1-py3.6.egg/mrcnn/model.py", line 1695, in data_generator
    use_mini_mask=config.USE_MINI_MASK)
  File "/home/fas/leonard/swk2/miniconda3/envs/maskRCNN/lib/python3.6/site-packages/mask_rcnn-2.1-py3.6.egg/mrcnn/model.py", line 1210, in load_image_gt
    mask, class_ids = dataset.load_mask(image_id)
  File "balloon.py", line 171, in load_mask
    mask[rr, cc, i] = 1
IndexError: index 2065 is out of bounds for axis 1 with size 2065
ERROR:root:Error processing image {'id': 'b21648979_0064.jpg', 'source': 'balloon', 'path': '../../datasets/illustrations/train/b21648979_0064.jpg', 'width': 2309, 'height': 4147, 'polygons': [{'name': 'rect', 'x': 440, 'y': 1097, 'width': 1438, 'height': 1491}]}
Traceback (most recent call last):
  File "/home/fas/leonard/swk2/miniconda3/envs/maskRCNN/lib/python3.6/site-packages/mask_rcnn-2.1-py3.6.egg/mrcnn/model.py", line 1695, in data_generator
    use_mini_mask=config.USE_MINI_MASK)
  File "/home/fas/leonard/swk2/miniconda3/envs/maskRCNN/lib/python3.6/site-packages/mask_rcnn-2.1-py3.6.egg/mrcnn/model.py", line 1210, in load_image_gt
    mask, class_ids = dataset.load_mask(image_id)
  File "balloon.py", line 171, in load_mask
    mask[rr, cc, i] = 1
IndexError: index 2309 is out of bounds for axis 1 with size 2309
ERROR:root:Error processing image {'id': 'b2812098x_0002_0093.jpg', 'source': 'balloon', 'path': '../../datasets/illustrations/train/b2812098x_0002_0093.jpg', 'width': 1809, 'height': 3069, 'polygons': [{'name': 'rect', 'x': 821, 'y': 833, 'width': 784, 'height': 1627}]}
Traceback (most recent call last):
  File "/home/fas/leonard/swk2/miniconda3/envs/maskRCNN/lib/python3.6/site-packages/mask_rcnn-2.1-py3.6.egg/mrcnn/model.py", line 1695, in data_generator
    use_mini_mask=config.USE_MINI_MASK)
  File "/home/fas/leonard/swk2/miniconda3/envs/maskRCNN/lib/python3.6/site-packages/mask_rcnn-2.1-py3.6.egg/mrcnn/model.py", line 1210, in load_image_gt
    mask, class_ids = dataset.load_mask(image_id)
  File "balloon.py", line 171, in load_mask
    mask[rr, cc, i] = 1
IndexError: index 1809 is out of bounds for axis 1 with size 1809
Traceback (most recent call last):
  File "/home/fas/leonard/swk2/miniconda3/envs/maskRCNN/lib/python3.6/site-packages/keras/utils/data_utils.py", line 677, in _data_generator_task
    generator_output = next(self._generator)
  File "/home/fas/leonard/swk2/miniconda3/envs/maskRCNN/lib/python3.6/site-packages/mask_rcnn-2.1-py3.6.egg/mrcnn/model.py", line 1695, in data_generator
    use_mini_mask=config.USE_MINI_MASK)
  File "/home/fas/leonard/swk2/miniconda3/envs/maskRCNN/lib/python3.6/site-packages/mask_rcnn-2.1-py3.6.egg/mrcnn/model.py", line 1210, in load_image_gt
    mask, class_ids = dataset.load_mask(image_id)
  File "balloon.py", line 171, in load_mask
    mask[rr, cc, i] = 1
IndexError: index 1809 is out of bounds for axis 1 with size 1809
ERROR:root:Error processing image {'id': 'missourimedicine5611miss_0352.jpg', 'source': 'balloon', 'path': '../../datasets/illustrations/train/missourimedicine5611miss_0352.jpg', 'width': 2513, 'height': 3695, 'polygons': [{'name': 'rect', 'x': 274, 'y': 530, 'width': 1075, 'height': 743}, {'name': 'rect', 'x': 271, 'y': 2052, 'width': 1075, 'height': 739}]}
Traceback (most recent call last):
  File "/home/fas/leonard/swk2/miniconda3/envs/maskRCNN/lib/python3.6/site-packages/mask_rcnn-2.1-py3.6.egg/mrcnn/model.py", line 1695, in data_generator
    use_mini_mask=config.USE_MINI_MASK)
  File "/home/fas/leonard/swk2/miniconda3/envs/maskRCNN/lib/python3.6/site-packages/mask_rcnn-2.1-py3.6.egg/mrcnn/model.py", line 1210, in load_image_gt
    mask, class_ids = dataset.load_mask(image_id)
  File "balloon.py", line 171, in load_mask
    mask[rr, cc, i] = 1
IndexError: index 2513 is out of bounds for axis 1 with size 2513
Traceback (most recent call last):
  File "/home/fas/leonard/swk2/miniconda3/envs/maskRCNN/lib/python3.6/site-packages/keras/utils/data_utils.py", line 677, in _data_generator_task
    generator_output = next(self._generator)
  File "/home/fas/leonard/swk2/miniconda3/envs/maskRCNN/lib/python3.6/site-packages/mask_rcnn-2.1-py3.6.egg/mrcnn/model.py", line 1695, in data_generator
    use_mini_mask=config.USE_MINI_MASK)
  File "/home/fas/leonard/swk2/miniconda3/envs/maskRCNN/lib/python3.6/site-packages/mask_rcnn-2.1-py3.6.egg/mrcnn/model.py", line 1210, in load_image_gt
    mask, class_ids = dataset.load_mask(image_id)
  File "balloon.py", line 171, in load_mask
    mask[rr, cc, i] = 1
IndexError: index 2513 is out of bounds for axis 1 with size 2513
ERROR:root:Error processing image {'id': 'missourimedicine5611miss_0352.jpg', 'source': 'balloon', 'path': '../../datasets/illustrations/train/missourimedicine5611miss_0352.jpg', 'width': 2513, 'height': 3695, 'polygons': [{'name': 'rect', 'x': 274, 'y': 530, 'width': 1075, 'height': 743}, {'name': 'rect', 'x': 271, 'y': 2052, 'width': 1075, 'height': 739}]}
Traceback (most recent call last):
  File "/home/fas/leonard/swk2/miniconda3/envs/maskRCNN/lib/python3.6/site-packages/mask_rcnn-2.1-py3.6.egg/mrcnn/model.py", line 1695, in data_generator
    use_mini_mask=config.USE_MINI_MASK)
  File "/home/fas/leonard/swk2/miniconda3/envs/maskRCNN/lib/python3.6/site-packages/mask_rcnn-2.1-py3.6.egg/mrcnn/model.py", line 1210, in load_image_gt
    mask, class_ids = dataset.load_mask(image_id)
  File "balloon.py", line 171, in load_mask
    mask[rr, cc, i] = 1
IndexError: index 2513 is out of bounds for axis 1 with size 2513
Traceback (most recent call last):
  File "/home/fas/leonard/swk2/miniconda3/envs/maskRCNN/lib/python3.6/site-packages/keras/utils/data_utils.py", line 677, in _data_generator_task
    generator_output = next(self._generator)
  File "/home/fas/leonard/swk2/miniconda3/envs/maskRCNN/lib/python3.6/site-packages/mask_rcnn-2.1-py3.6.egg/mrcnn/model.py", line 1695, in data_generator
    use_mini_mask=config.USE_MINI_MASK)
  File "/home/fas/leonard/swk2/miniconda3/envs/maskRCNN/lib/python3.6/site-packages/mask_rcnn-2.1-py3.6.egg/mrcnn/model.py", line 1210, in load_image_gt
    mask, class_ids = dataset.load_mask(image_id)
  File "balloon.py", line 171, in load_mask
    mask[rr, cc, i] = 1
IndexError: index 2513 is out of bounds for axis 1 with size 2513
ERROR:root:Error processing image {'id': 'b21648979_0064.jpg', 'source': 'balloon', 'path': '../../datasets/illustrations/train/b21648979_0064.jpg', 'width': 2309, 'height': 4147, 'polygons': [{'name': 'rect', 'x': 440, 'y': 1097, 'width': 1438, 'height': 1491}]}
Traceback (most recent call last):
  File "/home/fas/leonard/swk2/miniconda3/envs/maskRCNN/lib/python3.6/site-packages/mask_rcnn-2.1-py3.6.egg/mrcnn/model.py", line 1695, in data_generator
    use_mini_mask=config.USE_MINI_MASK)
  File "/home/fas/leonard/swk2/miniconda3/envs/maskRCNN/lib/python3.6/site-packages/mask_rcnn-2.1-py3.6.egg/mrcnn/model.py", line 1210, in load_image_gt
    mask, class_ids = dataset.load_mask(image_id)
  File "balloon.py", line 171, in load_mask
    mask[rr, cc, i] = 1
IndexError: index 2309 is out of bounds for axis 1 with size 2309
Traceback (most recent call last):
  File "/home/fas/leonard/swk2/miniconda3/envs/maskRCNN/lib/python3.6/site-packages/keras/utils/data_utils.py", line 677, in _data_generator_task
    generator_output = next(self._generator)
  File "/home/fas/leonard/swk2/miniconda3/envs/maskRCNN/lib/python3.6/site-packages/mask_rcnn-2.1-py3.6.egg/mrcnn/model.py", line 1695, in data_generator
    use_mini_mask=config.USE_MINI_MASK)
  File "/home/fas/leonard/swk2/miniconda3/envs/maskRCNN/lib/python3.6/site-packages/mask_rcnn-2.1-py3.6.egg/mrcnn/model.py", line 1210, in load_image_gt
    mask, class_ids = dataset.load_mask(image_id)
  File "balloon.py", line 171, in load_mask
    mask[rr, cc, i] = 1
IndexError: index 2309 is out of bounds for axis 1 with size 2309
ERROR:root:Error processing image {'id': 'dentalcosmos5186whit_0034.jpg', 'source': 'balloon', 'path': '../../datasets/illustrations/train/dentalcosmos5186whit_0034.jpg', 'width': 2490, 'height': 4058, 'polygons': [{'name': 'rect', 'x': 145, 'y': 683, 'width': 996, 'height': 767}, {'name': 'rect', 'x': 1209, 'y': 546, 'width': 1145, 'height': 988}, {'name': 'rect', 'x': 76, 'y': 2149, 'width': 1161, 'height': 1028}, {'name': 'rect', 'x': 1253, 'y': 2133, 'width': 1185, 'height': 972}]}
Traceback (most recent call last):
  File "/home/fas/leonard/swk2/miniconda3/envs/maskRCNN/lib/python3.6/site-packages/mask_rcnn-2.1-py3.6.egg/mrcnn/model.py", line 1695, in data_generator
    use_mini_mask=config.USE_MINI_MASK)
  File "/home/fas/leonard/swk2/miniconda3/envs/maskRCNN/lib/python3.6/site-packages/mask_rcnn-2.1-py3.6.egg/mrcnn/model.py", line 1210, in load_image_gt
    mask, class_ids = dataset.load_mask(image_id)
  File "balloon.py", line 171, in load_mask
    mask[rr, cc, i] = 1
IndexError: index 2490 is out of bounds for axis 1 with size 2490
ERROR:root:Error processing image {'id': 'terramariaemedic00unse_14_0140.jpg', 'source': 'balloon', 'path': '../../datasets/illustrations/train/terramariaemedic00unse_14_0140.jpg', 'width': 3527, 'height': 4678, 'polygons': [{'name': 'rect', 'x': 894, 'y': 158, 'width': 1024, 'height': 1808}, {'name': 'rect', 'x': 0, 'y': 2030, 'width': 1488, 'height': 1455}, {'name': 'rect', 'x': 1543, 'y': 2322, 'width': 1075, 'height': 1163}, {'name': 'rect', 'x': 2688, 'y': 2322, 'width': 830, 'height': 1159}, {'name': 'rect', 'x': 1974, 'y': 1242, 'width': 1539, 'height': 1010}, {'name': 'rect', 'x': 1891, 'y': 3532, 'width': 1622, 'height': 802}]}
Traceback (most recent call last):
  File "/home/fas/leonard/swk2/miniconda3/envs/maskRCNN/lib/python3.6/site-packages/mask_rcnn-2.1-py3.6.egg/mrcnn/model.py", line 1695, in data_generator
    use_mini_mask=config.USE_MINI_MASK)
  File "/home/fas/leonard/swk2/miniconda3/envs/maskRCNN/lib/python3.6/site-packages/mask_rcnn-2.1-py3.6.egg/mrcnn/model.py", line 1210, in load_image_gt
    mask, class_ids = dataset.load_mask(image_id)
  File "balloon.py", line 171, in load_mask
    mask[rr, cc, i] = 1
IndexError: index 3532 is out of bounds for axis 1 with size 3527
ERROR:root:Error processing image {'id': 'terramariaemedic00unse_14_0026.jpg', 'source': 'balloon', 'path': '../../datasets/illustrations/train/terramariaemedic00unse_14_0026.jpg', 'width': 3472, 'height': 4657, 'polygons': [{'name': 'rect', 'x': 5, 'y': 1203, 'width': 959, 'height': 1434}, {'name': 'rect', 'x': 1024, 'y': 563, 'width': 1305, 'height': 1014}, {'name': 'rect', 'x': 2379, 'y': 138, 'width': 1079, 'height': 1425}, {'name': 'rect', 'x': 1019, 'y': 1637, 'width': 1434, 'height': 1001}, {'name': 'rect', 'x': 2518, 'y': 1632, 'width': 941, 'height': 1005}, {'name': 'rect', 'x': 0, 'y': 2716, 'width': 752, 'height': 1070}, {'name': 'rect', 'x': 802, 'y': 2707, 'width': 788, 'height': 1074}, {'name': 'rect', 'x': 1660, 'y': 2716, 'width': 798, 'height': 1079}, {'name': 'rect', 'x': 2518, 'y': 2716, 'width': 936, 'height': 1485}]}
Traceback (most recent call last):
  File "/home/fas/leonard/swk2/miniconda3/envs/maskRCNN/lib/python3.6/site-packages/mask_rcnn-2.1-py3.6.egg/mrcnn/model.py", line 1695, in data_generator
    use_mini_mask=config.USE_MINI_MASK)
  File "/home/fas/leonard/swk2/miniconda3/envs/maskRCNN/lib/python3.6/site-packages/mask_rcnn-2.1-py3.6.egg/mrcnn/model.py", line 1210, in load_image_gt
    mask, class_ids = dataset.load_mask(image_id)
  File "balloon.py", line 171, in load_mask
    mask[rr, cc, i] = 1
IndexError: index 3472 is out of bounds for axis 1 with size 3472
ERROR:root:Error processing image {'id': 'newjerseymedicin9611medi_0202.jpg', 'source': 'balloon', 'path': '../../datasets/illustrations/train/newjerseymedicin9611medi_0202.jpg', 'width': 2623, 'height': 3742, 'polygons': [{'name': 'rect', 'x': 170, 'y': 571, 'width': 2397, 'height': 2808}]}
Traceback (most recent call last):
  File "/home/fas/leonard/swk2/miniconda3/envs/maskRCNN/lib/python3.6/site-packages/mask_rcnn-2.1-py3.6.egg/mrcnn/model.py", line 1695, in data_generator
    use_mini_mask=config.USE_MINI_MASK)
  File "/home/fas/leonard/swk2/miniconda3/envs/maskRCNN/lib/python3.6/site-packages/mask_rcnn-2.1-py3.6.egg/mrcnn/model.py", line 1210, in load_image_gt
    mask, class_ids = dataset.load_mask(image_id)
  File "balloon.py", line 171, in load_mask
    mask[rr, cc, i] = 1
IndexError: index 2623 is out of bounds for axis 1 with size 2623
ERROR:root:Error processing image {'id': 'b21915635_0002_0116.jpg', 'source': 'balloon', 'path': '../../datasets/illustrations/train/b21915635_0002_0116.jpg', 'width': 1886, 'height': 3313, 'polygons': [{'name': 'rect', 'x': 430, 'y': 1473, 'width': 1178, 'height': 686}]}
Traceback (most recent call last):
  File "/home/fas/leonard/swk2/miniconda3/envs/maskRCNN/lib/python3.6/site-packages/mask_rcnn-2.1-py3.6.egg/mrcnn/model.py", line 1695, in data_generator
    use_mini_mask=config.USE_MINI_MASK)
  File "/home/fas/leonard/swk2/miniconda3/envs/maskRCNN/lib/python3.6/site-packages/mask_rcnn-2.1-py3.6.egg/mrcnn/model.py", line 1210, in load_image_gt
    mask, class_ids = dataset.load_mask(image_id)
  File "balloon.py", line 171, in load_mask
    mask[rr, cc, i] = 1
IndexError: index 1886 is out of bounds for axis 1 with size 1886
ERROR:root:Error processing image {'id': 'terramariaemedic00unse_14_0140.jpg', 'source': 'balloon', 'path': '../../datasets/illustrations/train/terramariaemedic00unse_14_0140.jpg', 'width': 3527, 'height': 4678, 'polygons': [{'name': 'rect', 'x': 894, 'y': 158, 'width': 1024, 'height': 1808}, {'name': 'rect', 'x': 0, 'y': 2030, 'width': 1488, 'height': 1455}, {'name': 'rect', 'x': 1543, 'y': 2322, 'width': 1075, 'height': 1163}, {'name': 'rect', 'x': 2688, 'y': 2322, 'width': 830, 'height': 1159}, {'name': 'rect', 'x': 1974, 'y': 1242, 'width': 1539, 'height': 1010}, {'name': 'rect', 'x': 1891, 'y': 3532, 'width': 1622, 'height': 802}]}
Traceback (most recent call last):
  File "/home/fas/leonard/swk2/miniconda3/envs/maskRCNN/lib/python3.6/site-packages/mask_rcnn-2.1-py3.6.egg/mrcnn/model.py", line 1695, in data_generator
    use_mini_mask=config.USE_MINI_MASK)
  File "/home/fas/leonard/swk2/miniconda3/envs/maskRCNN/lib/python3.6/site-packages/mask_rcnn-2.1-py3.6.egg/mrcnn/model.py", line 1210, in load_image_gt
    mask, class_ids = dataset.load_mask(image_id)
  File "balloon.py", line 171, in load_mask
    mask[rr, cc, i] = 1
IndexError: index 3532 is out of bounds for axis 1 with size 3527
ERROR:root:Error processing image {'id': 'exceptionalchild00roma_0013.jpg', 'source': 'balloon', 'path': '../../datasets/illustrations/train/exceptionalchild00roma_0013.jpg', 'width': 2853, 'height': 2081, 'polygons': [{'name': 'rect', 'x': 173, 'y': 445, 'width': 2130, 'height': 1341}]}
Traceback (most recent call last):
  File "/home/fas/leonard/swk2/miniconda3/envs/maskRCNN/lib/python3.6/site-packages/mask_rcnn-2.1-py3.6.egg/mrcnn/model.py", line 1695, in data_generator
    use_mini_mask=config.USE_MINI_MASK)
  File "/home/fas/leonard/swk2/miniconda3/envs/maskRCNN/lib/python3.6/site-packages/mask_rcnn-2.1-py3.6.egg/mrcnn/model.py", line 1210, in load_image_gt
    mask, class_ids = dataset.load_mask(image_id)
  File "balloon.py", line 171, in load_mask
    mask[rr, cc, i] = 1
IndexError: index 2081 is out of bounds for axis 0 with size 2081
ERROR:root:Error processing image {'id': 'b2812098x_0002_0601.jpg', 'source': 'balloon', 'path': '../../datasets/illustrations/train/b2812098x_0002_0601.jpg', 'width': 1809, 'height': 3069, 'polygons': [{'name': 'rect', 'x': 185, 'y': 997, 'width': 1389, 'height': 833}]}
Traceback (most recent call last):
  File "/home/fas/leonard/swk2/miniconda3/envs/maskRCNN/lib/python3.6/site-packages/mask_rcnn-2.1-py3.6.egg/mrcnn/model.py", line 1695, in data_generator
    use_mini_mask=config.USE_MINI_MASK)
  File "/home/fas/leonard/swk2/miniconda3/envs/maskRCNN/lib/python3.6/site-packages/mask_rcnn-2.1-py3.6.egg/mrcnn/model.py", line 1210, in load_image_gt
    mask, class_ids = dataset.load_mask(image_id)
  File "balloon.py", line 171, in load_mask
    mask[rr, cc, i] = 1
IndexError: index 1809 is out of bounds for axis 1 with size 1809
ERROR:root:Error processing image {'id': 'differentialdiag002cabo_0293.jpg', 'source': 'balloon', 'path': '../../datasets/illustrations/train/differentialdiag002cabo_0293.jpg', 'width': 2102, 'height': 3453, 'polygons': [{'name': 'rect', 'x': 431, 'y': 1121, 'width': 1152, 'height': 1230}]}
Traceback (most recent call last):
  File "/home/fas/leonard/swk2/miniconda3/envs/maskRCNN/lib/python3.6/site-packages/mask_rcnn-2.1-py3.6.egg/mrcnn/model.py", line 1695, in data_generator
    use_mini_mask=config.USE_MINI_MASK)
  File "/home/fas/leonard/swk2/miniconda3/envs/maskRCNN/lib/python3.6/site-packages/mask_rcnn-2.1-py3.6.egg/mrcnn/model.py", line 1210, in load_image_gt
    mask, class_ids = dataset.load_mask(image_id)
  File "balloon.py", line 171, in load_mask
    mask[rr, cc, i] = 1
IndexError: index 2102 is out of bounds for axis 1 with size 2102
Traceback (most recent call last):
  File "/home/fas/leonard/swk2/miniconda3/envs/maskRCNN/lib/python3.6/site-packages/keras/utils/data_utils.py", line 677, in _data_generator_task
    generator_output = next(self._generator)
  File "/home/fas/leonard/swk2/miniconda3/envs/maskRCNN/lib/python3.6/site-packages/mask_rcnn-2.1-py3.6.egg/mrcnn/model.py", line 1695, in data_generator
    use_mini_mask=config.USE_MINI_MASK)
  File "/home/fas/leonard/swk2/miniconda3/envs/maskRCNN/lib/python3.6/site-packages/mask_rcnn-2.1-py3.6.egg/mrcnn/model.py", line 1210, in load_image_gt
    mask, class_ids = dataset.load_mask(image_id)
  File "balloon.py", line 171, in load_mask
    mask[rr, cc, i] = 1
IndexError: index 2102 is out of bounds for axis 1 with size 2102
ERROR:root:Error processing image {'id': 'lehrbuchderspeci001strm_0639.jpg', 'source': 'balloon', 'path': '../../datasets/illustrations/train/lehrbuchderspeci001strm_0639.jpg', 'width': 2065, 'height': 3269, 'polygons': [{'name': 'rect', 'x': 1314, 'y': 469, 'width': 320, 'height': 414}, {'name': 'rect', 'x': 1172, 'y': 1042, 'width': 641, 'height': 1660}]}
Traceback (most recent call last):
  File "/home/fas/leonard/swk2/miniconda3/envs/maskRCNN/lib/python3.6/site-packages/mask_rcnn-2.1-py3.6.egg/mrcnn/model.py", line 1695, in data_generator
    use_mini_mask=config.USE_MINI_MASK)
  File "/home/fas/leonard/swk2/miniconda3/envs/maskRCNN/lib/python3.6/site-packages/mask_rcnn-2.1-py3.6.egg/mrcnn/model.py", line 1210, in load_image_gt
    mask, class_ids = dataset.load_mask(image_id)
  File "balloon.py", line 171, in load_mask
    mask[rr, cc, i] = 1
IndexError: index 2065 is out of bounds for axis 1 with size 2065
Traceback (most recent call last):
  File "/home/fas/leonard/swk2/miniconda3/envs/maskRCNN/lib/python3.6/site-packages/keras/utils/data_utils.py", line 677, in _data_generator_task
    generator_output = next(self._generator)
  File "/home/fas/leonard/swk2/miniconda3/envs/maskRCNN/lib/python3.6/site-packages/mask_rcnn-2.1-py3.6.egg/mrcnn/model.py", line 1695, in data_generator
    use_mini_mask=config.USE_MINI_MASK)
  File "/home/fas/leonard/swk2/miniconda3/envs/maskRCNN/lib/python3.6/site-packages/mask_rcnn-2.1-py3.6.egg/mrcnn/model.py", line 1210, in load_image_gt
    mask, class_ids = dataset.load_mask(image_id)
  File "balloon.py", line 171, in load_mask
    mask[rr, cc, i] = 1
IndexError: index 2065 is out of bounds for axis 1 with size 2065
ERROR:root:Error processing image {'id': 'americanjournal46ameruoft_0831.jpg', 'source': 'balloon', 'path': '../../datasets/illustrations/train/americanjournal46ameruoft_0831.jpg', 'width': 2137, 'height': 3279, 'polygons': [{'name': 'rect', 'x': 487, 'y': 991, 'width': 1065, 'height': 1283}]}
Traceback (most recent call last):
  File "/home/fas/leonard/swk2/miniconda3/envs/maskRCNN/lib/python3.6/site-packages/mask_rcnn-2.1-py3.6.egg/mrcnn/model.py", line 1695, in data_generator
    use_mini_mask=config.USE_MINI_MASK)
  File "/home/fas/leonard/swk2/miniconda3/envs/maskRCNN/lib/python3.6/site-packages/mask_rcnn-2.1-py3.6.egg/mrcnn/model.py", line 1210, in load_image_gt
    mask, class_ids = dataset.load_mask(image_id)
  File "balloon.py", line 171, in load_mask
    mask[rr, cc, i] = 1
IndexError: index 2137 is out of bounds for axis 1 with size 2137
ERROR:root:Error processing image {'id': 'americantextbook00essi_0594.jpg', 'source': 'balloon', 'path': '../../datasets/illustrations/train/americantextbook00essi_0594.jpg', 'width': 2121, 'height': 3452, 'polygons': [{'name': 'rect', 'x': 157, 'y': 1619, 'width': 663, 'height': 324}, {'name': 'rect', 'x': 301, 'y': 2630, 'width': 779, 'height': 434}, {'name': 'rect', 'x': 1346, 'y': 2637, 'width': 492, 'height': 413}]}
Traceback (most recent call last):
  File "/home/fas/leonard/swk2/miniconda3/envs/maskRCNN/lib/python3.6/site-packages/mask_rcnn-2.1-py3.6.egg/mrcnn/model.py", line 1695, in data_generator
    use_mini_mask=config.USE_MINI_MASK)
  File "/home/fas/leonard/swk2/miniconda3/envs/maskRCNN/lib/python3.6/site-packages/mask_rcnn-2.1-py3.6.egg/mrcnn/model.py", line 1210, in load_image_gt
    mask, class_ids = dataset.load_mask(image_id)
  File "balloon.py", line 171, in load_mask
    mask[rr, cc, i] = 1
IndexError: index 2630 is out of bounds for axis 1 with size 2121
ERROR:root:Error processing image {'id': 'differentialdiag002cabo_0293.jpg', 'source': 'balloon', 'path': '../../datasets/illustrations/train/differentialdiag002cabo_0293.jpg', 'width': 2102, 'height': 3453, 'polygons': [{'name': 'rect', 'x': 431, 'y': 1121, 'width': 1152, 'height': 1230}]}
Traceback (most recent call last):
  File "/home/fas/leonard/swk2/miniconda3/envs/maskRCNN/lib/python3.6/site-packages/mask_rcnn-2.1-py3.6.egg/mrcnn/model.py", line 1695, in data_generator
    use_mini_mask=config.USE_MINI_MASK)
  File "/home/fas/leonard/swk2/miniconda3/envs/maskRCNN/lib/python3.6/site-packages/mask_rcnn-2.1-py3.6.egg/mrcnn/model.py", line 1210, in load_image_gt
    mask, class_ids = dataset.load_mask(image_id)
  File "balloon.py", line 171, in load_mask
    mask[rr, cc, i] = 1
IndexError: index 2102 is out of bounds for axis 1 with size 2102
Traceback (most recent call last):
  File "/home/fas/leonard/swk2/miniconda3/envs/maskRCNN/lib/python3.6/site-packages/keras/utils/data_utils.py", line 677, in _data_generator_task
    generator_output = next(self._generator)
  File "/home/fas/leonard/swk2/miniconda3/envs/maskRCNN/lib/python3.6/site-packages/mask_rcnn-2.1-py3.6.egg/mrcnn/model.py", line 1695, in data_generator
    use_mini_mask=config.USE_MINI_MASK)
  File "/home/fas/leonard/swk2/miniconda3/envs/maskRCNN/lib/python3.6/site-packages/mask_rcnn-2.1-py3.6.egg/mrcnn/model.py", line 1210, in load_image_gt
    mask, class_ids = dataset.load_mask(image_id)
  File "balloon.py", line 171, in load_mask
    mask[rr, cc, i] = 1
IndexError: index 2102 is out of bounds for axis 1 with size 2102
ERROR:root:Error processing image {'id': 'terramariaemedic00unse_14_0140.jpg', 'source': 'balloon', 'path': '../../datasets/illustrations/train/terramariaemedic00unse_14_0140.jpg', 'width': 3527, 'height': 4678, 'polygons': [{'name': 'rect', 'x': 894, 'y': 158, 'width': 1024, 'height': 1808}, {'name': 'rect', 'x': 0, 'y': 2030, 'width': 1488, 'height': 1455}, {'name': 'rect', 'x': 1543, 'y': 2322, 'width': 1075, 'height': 1163}, {'name': 'rect', 'x': 2688, 'y': 2322, 'width': 830, 'height': 1159}, {'name': 'rect', 'x': 1974, 'y': 1242, 'width': 1539, 'height': 1010}, {'name': 'rect', 'x': 1891, 'y': 3532, 'width': 1622, 'height': 802}]}
Traceback (most recent call last):
  File "/home/fas/leonard/swk2/miniconda3/envs/maskRCNN/lib/python3.6/site-packages/mask_rcnn-2.1-py3.6.egg/mrcnn/model.py", line 1695, in data_generator
    use_mini_mask=config.USE_MINI_MASK)
  File "/home/fas/leonard/swk2/miniconda3/envs/maskRCNN/lib/python3.6/site-packages/mask_rcnn-2.1-py3.6.egg/mrcnn/model.py", line 1210, in load_image_gt
    mask, class_ids = dataset.load_mask(image_id)
  File "balloon.py", line 171, in load_mask
    mask[rr, cc, i] = 1
IndexError: index 3532 is out of bounds for axis 1 with size 3527
ERROR:root:Error processing image {'id': 'differentialdiag002cabo_0138.jpg', 'source': 'balloon', 'path': '../../datasets/illustrations/train/differentialdiag002cabo_0138.jpg', 'width': 2102, 'height': 3453, 'polygons': [{'name': 'rect', 'x': 608, 'y': 885, 'width': 1114, 'height': 1470}]}
Traceback (most recent call last):
  File "/home/fas/leonard/swk2/miniconda3/envs/maskRCNN/lib/python3.6/site-packages/mask_rcnn-2.1-py3.6.egg/mrcnn/model.py", line 1695, in data_generator
    use_mini_mask=config.USE_MINI_MASK)
  File "/home/fas/leonard/swk2/miniconda3/envs/maskRCNN/lib/python3.6/site-packages/mask_rcnn-2.1-py3.6.egg/mrcnn/model.py", line 1210, in load_image_gt
    mask, class_ids = dataset.load_mask(image_id)
  File "balloon.py", line 171, in load_mask
    mask[rr, cc, i] = 1
IndexError: index 2102 is out of bounds for axis 1 with size 2102
Traceback (most recent call last):
  File "/home/fas/leonard/swk2/miniconda3/envs/maskRCNN/lib/python3.6/site-packages/keras/utils/data_utils.py", line 677, in _data_generator_task
    generator_output = next(self._generator)
  File "/home/fas/leonard/swk2/miniconda3/envs/maskRCNN/lib/python3.6/site-packages/mask_rcnn-2.1-py3.6.egg/mrcnn/model.py", line 1695, in data_generator
    use_mini_mask=config.USE_MINI_MASK)
  File "/home/fas/leonard/swk2/miniconda3/envs/maskRCNN/lib/python3.6/site-packages/mask_rcnn-2.1-py3.6.egg/mrcnn/model.py", line 1210, in load_image_gt
    mask, class_ids = dataset.load_mask(image_id)
  File "balloon.py", line 171, in load_mask
    mask[rr, cc, i] = 1
IndexError: index 2102 is out of bounds for axis 1 with size 2102
Epoch 1/30

  1/100 [..............................] - ETA: 58:52 - loss: 7.6061 - rpn_class_loss: 0.1280 - rpn_bbox_loss: 5.2452 - mrcnn_class_loss: 0.0884 - mrcnn_bbox_loss: 1.3879 - mrcnn_mask_loss: 0.7566Traceback (most recent call last):
  File "balloon.py", line 371, in <module>
    train(model)
  File "balloon.py", line 206, in train
    layers='heads')
  File "/home/fas/leonard/swk2/miniconda3/envs/maskRCNN/lib/python3.6/site-packages/mask_rcnn-2.1-py3.6.egg/mrcnn/model.py", line 2328, in train
  File "/home/fas/leonard/swk2/miniconda3/envs/maskRCNN/lib/python3.6/site-packages/keras/legacy/interfaces.py", line 91, in wrapper
    return func(*args, **kwargs)
  File "/home/fas/leonard/swk2/miniconda3/envs/maskRCNN/lib/python3.6/site-packages/keras/engine/training.py", line 2194, in fit_generator
    generator_output = next(output_generator)
  File "/home/fas/leonard/swk2/miniconda3/envs/maskRCNN/lib/python3.6/site-packages/keras/utils/data_utils.py", line 793, in get
    six.reraise(value.__class__, value, value.__traceback__)
  File "/home/fas/leonard/swk2/miniconda3/envs/maskRCNN/lib/python3.6/site-packages/six.py", line 693, in reraise
    raise value
IndexError: index 2102 is out of bounds for axis 1 with size 2102
