The following modules were not unloaded:
  (Use "module --force purge" to unload all):

  1) StdEnv
Restoring modules from user's cuda, for system: "grace-rhel7"
2018-05-08 00:32:04.830752: I tensorflow/core/platform/cpu_feature_guard.cc:140] Your CPU supports instructions that this TensorFlow binary was not compiled to use: AVX2 FMA
/home/fas/leonard/swk2/miniconda3/envs/maskRCNN/lib/python3.6/site-packages/h5py/__init__.py:36: FutureWarning: Conversion of the second argument of issubdtype from `float` to `np.floating` is deprecated. In future, it will be treated as `np.float64 == np.dtype(float).type`.
  from ._conv import register_converters as _register_converters
Using TensorFlow backend.
WARNING:tensorflow:From /home/fas/leonard/swk2/miniconda3/envs/maskRCNN/lib/python3.6/site-packages/tensorflow/contrib/learn/python/learn/datasets/base.py:198: retry (from tensorflow.contrib.learn.python.learn.datasets.base) is deprecated and will be removed in a future version.
Instructions for updating:
Use the retry module or similar alternatives.
Weights:  coco
Dataset:  ../../datasets/illustrations
Logs:  /gpfs/loomis/project/fas/leonard/swk2/Mask_RCNN/logs

Configurations:
BACKBONE                       resnet101
BACKBONE_STRIDES               [4, 8, 16, 32, 64]
BATCH_SIZE                     2
BBOX_STD_DEV                   [0.1 0.1 0.2 0.2]
DETECTION_MAX_INSTANCES        100
DETECTION_MIN_CONFIDENCE       0.9
DETECTION_NMS_THRESHOLD        0.3
GPU_COUNT                      1
GRADIENT_CLIP_NORM             5.0
IMAGES_PER_GPU                 2
IMAGE_MAX_DIM                  1024
IMAGE_META_SIZE                14
IMAGE_MIN_DIM                  800
IMAGE_MIN_SCALE                0
IMAGE_RESIZE_MODE              square
IMAGE_SHAPE                    [1024 1024    3]
LEARNING_MOMENTUM              0.9
LEARNING_RATE                  0.001
LOSS_WEIGHTS                   {'rpn_class_loss': 1.0, 'rpn_bbox_loss': 1.0, 'mrcnn_class_loss': 1.0, 'mrcnn_bbox_loss': 1.0, 'mrcnn_mask_loss': 1.0}
MASK_POOL_SIZE                 14
MASK_SHAPE                     [28, 28]
MAX_GT_INSTANCES               100
MEAN_PIXEL                     [123.7 116.8 103.9]
MINI_MASK_SHAPE                (56, 56)
NAME                           balloon
NUM_CLASSES                    2
POOL_SIZE                      7
POST_NMS_ROIS_INFERENCE        1000
POST_NMS_ROIS_TRAINING         2000
ROI_POSITIVE_RATIO             0.33
RPN_ANCHOR_RATIOS              [0.5, 1, 2]
RPN_ANCHOR_SCALES              (32, 64, 128, 256, 512)
RPN_ANCHOR_STRIDE              1
RPN_BBOX_STD_DEV               [0.1 0.1 0.2 0.2]
RPN_NMS_THRESHOLD              0.7
RPN_TRAIN_ANCHORS_PER_IMAGE    256
STEPS_PER_EPOCH                100
TRAIN_BN                       False
TRAIN_ROIS_PER_IMAGE           200
USE_MINI_MASK                  True
USE_RPN_ROIS                   True
VALIDATION_STEPS               50
WEIGHT_DECAY                   0.0001


Loading weights  /gpfs/loomis/project/fas/leonard/swk2/Mask_RCNN/mask_rcnn_coco.h5
Training network heads

Starting at epoch 0. LR=0.001

Checkpoint Path: /gpfs/loomis/project/fas/leonard/swk2/Mask_RCNN/logs/balloon20180508T0032/mask_rcnn_balloon_{epoch:04d}.h5
Selecting layers to train
fpn_c5p5               (Conv2D)
fpn_c4p4               (Conv2D)
fpn_c3p3               (Conv2D)
fpn_c2p2               (Conv2D)
fpn_p5                 (Conv2D)
fpn_p2                 (Conv2D)
fpn_p3                 (Conv2D)
fpn_p4                 (Conv2D)
In model:  rpn_model
    rpn_conv_shared        (Conv2D)
    rpn_class_raw          (Conv2D)
    rpn_bbox_pred          (Conv2D)
mrcnn_mask_conv1       (TimeDistributed)
mrcnn_mask_bn1         (TimeDistributed)
mrcnn_mask_conv2       (TimeDistributed)
mrcnn_mask_bn2         (TimeDistributed)
mrcnn_class_conv1      (TimeDistributed)
mrcnn_class_bn1        (TimeDistributed)
mrcnn_mask_conv3       (TimeDistributed)
mrcnn_mask_bn3         (TimeDistributed)
mrcnn_class_conv2      (TimeDistributed)
mrcnn_class_bn2        (TimeDistributed)
mrcnn_mask_conv4       (TimeDistributed)
mrcnn_mask_bn4         (TimeDistributed)
mrcnn_bbox_fc          (TimeDistributed)
mrcnn_mask_deconv      (TimeDistributed)
mrcnn_class_logits     (TimeDistributed)
mrcnn_mask             (TimeDistributed)
/home/fas/leonard/swk2/miniconda3/envs/maskRCNN/lib/python3.6/site-packages/tensorflow/python/ops/gradients_impl.py:100: UserWarning: Converting sparse IndexedSlices to a dense Tensor of unknown shape. This may consume a large amount of memory.
  "Converting sparse IndexedSlices to a dense Tensor of unknown shape. "
/home/fas/leonard/swk2/miniconda3/envs/maskRCNN/lib/python3.6/site-packages/keras/engine/training.py:2087: UserWarning: Using a generator with `use_multiprocessing=True` and multiple workers may duplicate your data. Please consider using the`keras.utils.Sequence class.
  UserWarning('Using a generator with `use_multiprocessing=True`'
ERROR:root:Error processing image {'id': 'textbookofdental00burc_0367.jpg', 'source': 'balloon', 'path': '../../datasets/illustrations/train/textbookofdental00burc_0367.jpg', 'width': 1990, 'height': 3381, 'polygons': [{'name': 'rect', 'x': 211, 'y': 905, 'width': 1568, 'height': 1276}]}
Traceback (most recent call last):
  File "/home/fas/leonard/swk2/miniconda3/envs/maskRCNN/lib/python3.6/site-packages/mask_rcnn-2.1-py3.6.egg/mrcnn/model.py", line 1695, in data_generator
    use_mini_mask=config.USE_MINI_MASK)
  File "/home/fas/leonard/swk2/miniconda3/envs/maskRCNN/lib/python3.6/site-packages/mask_rcnn-2.1-py3.6.egg/mrcnn/model.py", line 1210, in load_image_gt
    mask, class_ids = dataset.load_mask(image_id)
  File "balloon.py", line 171, in load_mask
    mask[rr, cc, i] = 1
IndexError: index 1990 is out of bounds for axis 1 with size 1990
ERROR:root:Error processing image {'id': 'americanjournal46ameruoft_0831.jpg', 'source': 'balloon', 'path': '../../datasets/illustrations/train/americanjournal46ameruoft_0831.jpg', 'width': 2137, 'height': 3279, 'polygons': [{'name': 'rect', 'x': 487, 'y': 991, 'width': 1065, 'height': 1283}]}
Traceback (most recent call last):
  File "/home/fas/leonard/swk2/miniconda3/envs/maskRCNN/lib/python3.6/site-packages/mask_rcnn-2.1-py3.6.egg/mrcnn/model.py", line 1695, in data_generator
    use_mini_mask=config.USE_MINI_MASK)
  File "/home/fas/leonard/swk2/miniconda3/envs/maskRCNN/lib/python3.6/site-packages/mask_rcnn-2.1-py3.6.egg/mrcnn/model.py", line 1210, in load_image_gt
    mask, class_ids = dataset.load_mask(image_id)
  File "balloon.py", line 171, in load_mask
    mask[rr, cc, i] = 1
IndexError: index 2137 is out of bounds for axis 1 with size 2137
ERROR:root:Error processing image {'id': 'textbookofdental00burc_0367.jpg', 'source': 'balloon', 'path': '../../datasets/illustrations/train/textbookofdental00burc_0367.jpg', 'width': 1990, 'height': 3381, 'polygons': [{'name': 'rect', 'x': 211, 'y': 905, 'width': 1568, 'height': 1276}]}
Traceback (most recent call last):
  File "/home/fas/leonard/swk2/miniconda3/envs/maskRCNN/lib/python3.6/site-packages/mask_rcnn-2.1-py3.6.egg/mrcnn/model.py", line 1695, in data_generator
    use_mini_mask=config.USE_MINI_MASK)
  File "/home/fas/leonard/swk2/miniconda3/envs/maskRCNN/lib/python3.6/site-packages/mask_rcnn-2.1-py3.6.egg/mrcnn/model.py", line 1210, in load_image_gt
    mask, class_ids = dataset.load_mask(image_id)
  File "balloon.py", line 171, in load_mask
    mask[rr, cc, i] = 1
IndexError: index 1990 is out of bounds for axis 1 with size 1990
ERROR:root:Error processing image {'id': 'proceedings16newy_0178.jpg', 'source': 'balloon', 'path': '../../datasets/illustrations/train/proceedings16newy_0178.jpg', 'width': 2133, 'height': 3495, 'polygons': [{'name': 'rect', 'x': 398, 'y': 1125, 'width': 1434, 'height': 1389}]}
Traceback (most recent call last):
  File "/home/fas/leonard/swk2/miniconda3/envs/maskRCNN/lib/python3.6/site-packages/mask_rcnn-2.1-py3.6.egg/mrcnn/model.py", line 1695, in data_generator
    use_mini_mask=config.USE_MINI_MASK)
  File "/home/fas/leonard/swk2/miniconda3/envs/maskRCNN/lib/python3.6/site-packages/mask_rcnn-2.1-py3.6.egg/mrcnn/model.py", line 1210, in load_image_gt
    mask, class_ids = dataset.load_mask(image_id)
  File "balloon.py", line 171, in load_mask
    mask[rr, cc, i] = 1
IndexError: index 2133 is out of bounds for axis 1 with size 2133
ERROR:root:Error processing image {'id': 'appliedanatomyor00ivyr_0028.jpg', 'source': 'balloon', 'path': '../../datasets/illustrations/train/appliedanatomyor00ivyr_0028.jpg', 'width': 1818, 'height': 2865, 'polygons': [{'name': 'rect', 'x': 227, 'y': 851, 'width': 1395, 'height': 1027}]}
Traceback (most recent call last):
  File "/home/fas/leonard/swk2/miniconda3/envs/maskRCNN/lib/python3.6/site-packages/mask_rcnn-2.1-py3.6.egg/mrcnn/model.py", line 1695, in data_generator
    use_mini_mask=config.USE_MINI_MASK)
  File "/home/fas/leonard/swk2/miniconda3/envs/maskRCNN/lib/python3.6/site-packages/mask_rcnn-2.1-py3.6.egg/mrcnn/model.py", line 1210, in load_image_gt
    mask, class_ids = dataset.load_mask(image_id)
  File "balloon.py", line 171, in load_mask
    mask[rr, cc, i] = 1
IndexError: index 1818 is out of bounds for axis 1 with size 1818
ERROR:root:Error processing image {'id': 'americanjournal46ameruoft_0831.jpg', 'source': 'balloon', 'path': '../../datasets/illustrations/train/americanjournal46ameruoft_0831.jpg', 'width': 2137, 'height': 3279, 'polygons': [{'name': 'rect', 'x': 487, 'y': 991, 'width': 1065, 'height': 1283}]}
Traceback (most recent call last):
  File "/home/fas/leonard/swk2/miniconda3/envs/maskRCNN/lib/python3.6/site-packages/mask_rcnn-2.1-py3.6.egg/mrcnn/model.py", line 1695, in data_generator
    use_mini_mask=config.USE_MINI_MASK)
  File "/home/fas/leonard/swk2/miniconda3/envs/maskRCNN/lib/python3.6/site-packages/mask_rcnn-2.1-py3.6.egg/mrcnn/model.py", line 1210, in load_image_gt
    mask, class_ids = dataset.load_mask(image_id)
  File "balloon.py", line 171, in load_mask
    mask[rr, cc, i] = 1
IndexError: index 2137 is out of bounds for axis 1 with size 2137
ERROR:root:Error processing image {'id': 'differentialdiag002cabo_0293.jpg', 'source': 'balloon', 'path': '../../datasets/illustrations/train/differentialdiag002cabo_0293.jpg', 'width': 2102, 'height': 3453, 'polygons': [{'name': 'rect', 'x': 431, 'y': 1121, 'width': 1152, 'height': 1230}]}
Traceback (most recent call last):
  File "/home/fas/leonard/swk2/miniconda3/envs/maskRCNN/lib/python3.6/site-packages/mask_rcnn-2.1-py3.6.egg/mrcnn/model.py", line 1695, in data_generator
    use_mini_mask=config.USE_MINI_MASK)
  File "/home/fas/leonard/swk2/miniconda3/envs/maskRCNN/lib/python3.6/site-packages/mask_rcnn-2.1-py3.6.egg/mrcnn/model.py", line 1210, in load_image_gt
    mask, class_ids = dataset.load_mask(image_id)
  File "balloon.py", line 171, in load_mask
    mask[rr, cc, i] = 1
IndexError: index 2102 is out of bounds for axis 1 with size 2102
ERROR:root:Error processing image {'id': 'textbookofbotany00strauoft_0604.jpg', 'source': 'balloon', 'path': '../../datasets/illustrations/train/textbookofbotany00strauoft_0604.jpg', 'width': 1918, 'height': 3216, 'polygons': [{'name': 'rect', 'x': 261, 'y': 2208, 'width': 398, 'height': 421}, {'name': 'rect', 'x': 857, 'y': 510, 'width': 873, 'height': 2179}]}
Traceback (most recent call last):
  File "/home/fas/leonard/swk2/miniconda3/envs/maskRCNN/lib/python3.6/site-packages/mask_rcnn-2.1-py3.6.egg/mrcnn/model.py", line 1695, in data_generator
    use_mini_mask=config.USE_MINI_MASK)
  File "/home/fas/leonard/swk2/miniconda3/envs/maskRCNN/lib/python3.6/site-packages/mask_rcnn-2.1-py3.6.egg/mrcnn/model.py", line 1210, in load_image_gt
    mask, class_ids = dataset.load_mask(image_id)
  File "balloon.py", line 171, in load_mask
    mask[rr, cc, i] = 1
IndexError: index 2208 is out of bounds for axis 1 with size 1918
ERROR:root:Error processing image {'id': 'b29124815_0156.jpg', 'source': 'balloon', 'path': '../../datasets/illustrations/train/b29124815_0156.jpg', 'width': 1914, 'height': 3294, 'polygons': [{'name': 'rect', 'x': 212, 'y': 717, 'width': 1301, 'height': 1790}]}
Traceback (most recent call last):
  File "/home/fas/leonard/swk2/miniconda3/envs/maskRCNN/lib/python3.6/site-packages/mask_rcnn-2.1-py3.6.egg/mrcnn/model.py", line 1695, in data_generator
    use_mini_mask=config.USE_MINI_MASK)
  File "/home/fas/leonard/swk2/miniconda3/envs/maskRCNN/lib/python3.6/site-packages/mask_rcnn-2.1-py3.6.egg/mrcnn/model.py", line 1210, in load_image_gt
    mask, class_ids = dataset.load_mask(image_id)
  File "balloon.py", line 171, in load_mask
    mask[rr, cc, i] = 1
IndexError: index 1914 is out of bounds for axis 1 with size 1914
ERROR:root:Error processing image {'id': '63571000R_0947.jpg', 'source': 'balloon', 'path': '../../datasets/illustrations/train/63571000R_0947.jpg', 'width': 1980, 'height': 3528, 'polygons': [{'name': 'rect', 'x': 496, 'y': 1502, 'width': 1083, 'height': 1582}]}
Traceback (most recent call last):
  File "/home/fas/leonard/swk2/miniconda3/envs/maskRCNN/lib/python3.6/site-packages/mask_rcnn-2.1-py3.6.egg/mrcnn/model.py", line 1695, in data_generator
    use_mini_mask=config.USE_MINI_MASK)
  File "/home/fas/leonard/swk2/miniconda3/envs/maskRCNN/lib/python3.6/site-packages/mask_rcnn-2.1-py3.6.egg/mrcnn/model.py", line 1210, in load_image_gt
    mask, class_ids = dataset.load_mask(image_id)
  File "balloon.py", line 171, in load_mask
    mask[rr, cc, i] = 1
IndexError: index 1980 is out of bounds for axis 1 with size 1980
ERROR:root:Error processing image {'id': 'gynecology00grav_0127.jpg', 'source': 'balloon', 'path': '../../datasets/illustrations/train/gynecology00grav_0127.jpg', 'width': 2329, 'height': 3708, 'polygons': [{'name': 'rect', 'x': 198, 'y': 1227, 'width': 1888, 'height': 1271}]}
Traceback (most recent call last):
  File "/home/fas/leonard/swk2/miniconda3/envs/maskRCNN/lib/python3.6/site-packages/mask_rcnn-2.1-py3.6.egg/mrcnn/model.py", line 1695, in data_generator
    use_mini_mask=config.USE_MINI_MASK)
  File "/home/fas/leonard/swk2/miniconda3/envs/maskRCNN/lib/python3.6/site-packages/mask_rcnn-2.1-py3.6.egg/mrcnn/model.py", line 1210, in load_image_gt
    mask, class_ids = dataset.load_mask(image_id)
  File "balloon.py", line 171, in load_mask
    mask[rr, cc, i] = 1
IndexError: index 2329 is out of bounds for axis 1 with size 2329
ERROR:root:Error processing image {'id': 's3edinburghmedical04edinuoft_0477.jpg', 'source': 'balloon', 'path': '../../datasets/illustrations/train/s3edinburghmedical04edinuoft_0477.jpg', 'width': 2126, 'height': 3206, 'polygons': [{'name': 'rect', 'x': 267, 'y': 320, 'width': 1355, 'height': 1165}, {'name': 'rect', 'x': 311, 'y': 1717, 'width': 1260, 'height': 1092}]}
Traceback (most recent call last):
  File "/home/fas/leonard/swk2/miniconda3/envs/maskRCNN/lib/python3.6/site-packages/mask_rcnn-2.1-py3.6.egg/mrcnn/model.py", line 1695, in data_generator
    use_mini_mask=config.USE_MINI_MASK)
  File "/home/fas/leonard/swk2/miniconda3/envs/maskRCNN/lib/python3.6/site-packages/mask_rcnn-2.1-py3.6.egg/mrcnn/model.py", line 1210, in load_image_gt
    mask, class_ids = dataset.load_mask(image_id)
  File "balloon.py", line 171, in load_mask
    mask[rr, cc, i] = 1
IndexError: index 2126 is out of bounds for axis 1 with size 2126
ERROR:root:Error processing image {'id': 'b28120553_0263.jpg', 'source': 'balloon', 'path': '../../datasets/illustrations/train/b28120553_0263.jpg', 'width': 1789, 'height': 3082, 'polygons': [{'name': 'rect', 'x': 263, 'y': 64, 'width': 1310, 'height': 1099}, {'name': 'rect', 'x': 150, 'y': 1200, 'width': 681, 'height': 913}, {'name': 'rect', 'x': 1087, 'y': 1380, 'width': 614, 'height': 632}, {'name': 'rect', 'x': 986, 'y': 2158, 'width': 720, 'height': 757}, {'name': 'rect', 'x': 128, 'y': 2223, 'width': 659, 'height': 684}]}
Traceback (most recent call last):
  File "/home/fas/leonard/swk2/miniconda3/envs/maskRCNN/lib/python3.6/site-packages/mask_rcnn-2.1-py3.6.egg/mrcnn/model.py", line 1695, in data_generator
    use_mini_mask=config.USE_MINI_MASK)
  File "/home/fas/leonard/swk2/miniconda3/envs/maskRCNN/lib/python3.6/site-packages/mask_rcnn-2.1-py3.6.egg/mrcnn/model.py", line 1210, in load_image_gt
    mask, class_ids = dataset.load_mask(image_id)
  File "balloon.py", line 171, in load_mask
    mask[rr, cc, i] = 1
IndexError: index 1789 is out of bounds for axis 1 with size 1789
ERROR:root:Error processing image {'id': 'manualofoperativ00stim_0138.jpg', 'source': 'balloon', 'path': '../../datasets/illustrations/train/manualofoperativ00stim_0138.jpg', 'width': 2107, 'height': 3489, 'polygons': [{'name': 'rect', 'x': 594, 'y': 715, 'width': 919, 'height': 2072}]}
Traceback (most recent call last):
  File "/home/fas/leonard/swk2/miniconda3/envs/maskRCNN/lib/python3.6/site-packages/mask_rcnn-2.1-py3.6.egg/mrcnn/model.py", line 1695, in data_generator
    use_mini_mask=config.USE_MINI_MASK)
  File "/home/fas/leonard/swk2/miniconda3/envs/maskRCNN/lib/python3.6/site-packages/mask_rcnn-2.1-py3.6.egg/mrcnn/model.py", line 1210, in load_image_gt
    mask, class_ids = dataset.load_mask(image_id)
  File "balloon.py", line 171, in load_mask
    mask[rr, cc, i] = 1
IndexError: index 2107 is out of bounds for axis 1 with size 2107
ERROR:root:Error processing image {'id': 'dentalcosmos5186whit_0034.jpg', 'source': 'balloon', 'path': '../../datasets/illustrations/train/dentalcosmos5186whit_0034.jpg', 'width': 2490, 'height': 4058, 'polygons': [{'name': 'rect', 'x': 145, 'y': 683, 'width': 996, 'height': 767}, {'name': 'rect', 'x': 1209, 'y': 546, 'width': 1145, 'height': 988}, {'name': 'rect', 'x': 76, 'y': 2149, 'width': 1161, 'height': 1028}, {'name': 'rect', 'x': 1253, 'y': 2133, 'width': 1185, 'height': 972}]}
Traceback (most recent call last):
  File "/home/fas/leonard/swk2/miniconda3/envs/maskRCNN/lib/python3.6/site-packages/mask_rcnn-2.1-py3.6.egg/mrcnn/model.py", line 1695, in data_generator
    use_mini_mask=config.USE_MINI_MASK)
  File "/home/fas/leonard/swk2/miniconda3/envs/maskRCNN/lib/python3.6/site-packages/mask_rcnn-2.1-py3.6.egg/mrcnn/model.py", line 1210, in load_image_gt
    mask, class_ids = dataset.load_mask(image_id)
  File "balloon.py", line 171, in load_mask
    mask[rr, cc, i] = 1
IndexError: index 2490 is out of bounds for axis 1 with size 2490
ERROR:root:Error processing image {'id': 'exceptionalchild00roma_0013.jpg', 'source': 'balloon', 'path': '../../datasets/illustrations/train/exceptionalchild00roma_0013.jpg', 'width': 2853, 'height': 2081, 'polygons': [{'name': 'rect', 'x': 173, 'y': 445, 'width': 2130, 'height': 1341}]}
Traceback (most recent call last):
  File "/home/fas/leonard/swk2/miniconda3/envs/maskRCNN/lib/python3.6/site-packages/mask_rcnn-2.1-py3.6.egg/mrcnn/model.py", line 1695, in data_generator
    use_mini_mask=config.USE_MINI_MASK)
  File "/home/fas/leonard/swk2/miniconda3/envs/maskRCNN/lib/python3.6/site-packages/mask_rcnn-2.1-py3.6.egg/mrcnn/model.py", line 1210, in load_image_gt
    mask, class_ids = dataset.load_mask(image_id)
  File "balloon.py", line 171, in load_mask
    mask[rr, cc, i] = 1
IndexError: index 2081 is out of bounds for axis 0 with size 2081
ERROR:root:Error processing image {'id': 'hotspringsofbath00hattuoft_0009.jpg', 'source': 'balloon', 'path': '../../datasets/illustrations/train/hotspringsofbath00hattuoft_0009.jpg', 'width': 2027, 'height': 3192, 'polygons': [{'name': 'rect', 'x': 190, 'y': 421, 'width': 1518, 'height': 2223}]}
Traceback (most recent call last):
  File "/home/fas/leonard/swk2/miniconda3/envs/maskRCNN/lib/python3.6/site-packages/mask_rcnn-2.1-py3.6.egg/mrcnn/model.py", line 1695, in data_generator
    use_mini_mask=config.USE_MINI_MASK)
  File "/home/fas/leonard/swk2/miniconda3/envs/maskRCNN/lib/python3.6/site-packages/mask_rcnn-2.1-py3.6.egg/mrcnn/model.py", line 1210, in load_image_gt
    mask, class_ids = dataset.load_mask(image_id)
  File "balloon.py", line 171, in load_mask
    mask[rr, cc, i] = 1
IndexError: index 2027 is out of bounds for axis 1 with size 2027
ERROR:root:Error processing image {'id': 'hughespracticeof1911hugh_0460.jpg', 'source': 'balloon', 'path': '../../datasets/illustrations/train/hughespracticeof1911hugh_0460.jpg', 'width': 2177, 'height': 3424, 'polygons': [{'name': 'rect', 'x': 241, 'y': 285, 'width': 916, 'height': 1099}, {'name': 'rect', 'x': 1285, 'y': 471, 'width': 743, 'height': 722}, {'name': 'rect', 'x': 264, 'y': 1801, 'width': 756, 'height': 763}, {'name': 'rect', 'x': 1265, 'y': 1750, 'width': 783, 'height': 807}]}
Traceback (most recent call last):
  File "/home/fas/leonard/swk2/miniconda3/envs/maskRCNN/lib/python3.6/site-packages/mask_rcnn-2.1-py3.6.egg/mrcnn/model.py", line 1695, in data_generator
    use_mini_mask=config.USE_MINI_MASK)
  File "/home/fas/leonard/swk2/miniconda3/envs/maskRCNN/lib/python3.6/site-packages/mask_rcnn-2.1-py3.6.egg/mrcnn/model.py", line 1210, in load_image_gt
    mask, class_ids = dataset.load_mask(image_id)
  File "balloon.py", line 171, in load_mask
    mask[rr, cc, i] = 1
IndexError: index 2177 is out of bounds for axis 1 with size 2177
ERROR:root:Error processing image {'id': 'textbookofbotany00strauoft_0416.jpg', 'source': 'balloon', 'path': '../../datasets/illustrations/train/textbookofbotany00strauoft_0416.jpg', 'width': 1918, 'height': 3216, 'polygons': [{'name': 'rect', 'x': 143, 'y': 519, 'width': 895, 'height': 386}, {'name': 'rect', 'x': 857, 'y': 1201, 'width': 879, 'height': 1265}]}
Traceback (most recent call last):
  File "/home/fas/leonard/swk2/miniconda3/envs/maskRCNN/lib/python3.6/site-packages/mask_rcnn-2.1-py3.6.egg/mrcnn/model.py", line 1695, in data_generator
    use_mini_mask=config.USE_MINI_MASK)
  File "/home/fas/leonard/swk2/miniconda3/envs/maskRCNN/lib/python3.6/site-packages/mask_rcnn-2.1-py3.6.egg/mrcnn/model.py", line 1210, in load_image_gt
    mask, class_ids = dataset.load_mask(image_id)
  File "balloon.py", line 171, in load_mask
    mask[rr, cc, i] = 1
IndexError: index 1918 is out of bounds for axis 1 with size 1918
ERROR:root:Error processing image {'id': 'b29124815_0156.jpg', 'source': 'balloon', 'path': '../../datasets/illustrations/train/b29124815_0156.jpg', 'width': 1914, 'height': 3294, 'polygons': [{'name': 'rect', 'x': 212, 'y': 717, 'width': 1301, 'height': 1790}]}
Traceback (most recent call last):
  File "/home/fas/leonard/swk2/miniconda3/envs/maskRCNN/lib/python3.6/site-packages/mask_rcnn-2.1-py3.6.egg/mrcnn/model.py", line 1695, in data_generator
    use_mini_mask=config.USE_MINI_MASK)
  File "/home/fas/leonard/swk2/miniconda3/envs/maskRCNN/lib/python3.6/site-packages/mask_rcnn-2.1-py3.6.egg/mrcnn/model.py", line 1210, in load_image_gt
    mask, class_ids = dataset.load_mask(image_id)
  File "balloon.py", line 171, in load_mask
    mask[rr, cc, i] = 1
IndexError: index 1914 is out of bounds for axis 1 with size 1914
ERROR:root:Error processing image {'id': 'b21932323_0188.jpg', 'source': 'balloon', 'path': '../../datasets/illustrations/train/b21932323_0188.jpg', 'width': 1811, 'height': 2946, 'polygons': [{'name': 'rect', 'x': 271, 'y': 612, 'width': 1315, 'height': 1362}]}
Traceback (most recent call last):
  File "/home/fas/leonard/swk2/miniconda3/envs/maskRCNN/lib/python3.6/site-packages/mask_rcnn-2.1-py3.6.egg/mrcnn/model.py", line 1695, in data_generator
    use_mini_mask=config.USE_MINI_MASK)
  File "/home/fas/leonard/swk2/miniconda3/envs/maskRCNN/lib/python3.6/site-packages/mask_rcnn-2.1-py3.6.egg/mrcnn/model.py", line 1210, in load_image_gt
    mask, class_ids = dataset.load_mask(image_id)
  File "balloon.py", line 171, in load_mask
    mask[rr, cc, i] = 1
IndexError: index 1811 is out of bounds for axis 1 with size 1811
ERROR:root:Error processing image {'id': 'hotspringsofbath00hattuoft_0009.jpg', 'source': 'balloon', 'path': '../../datasets/illustrations/train/hotspringsofbath00hattuoft_0009.jpg', 'width': 2027, 'height': 3192, 'polygons': [{'name': 'rect', 'x': 190, 'y': 421, 'width': 1518, 'height': 2223}]}
Traceback (most recent call last):
  File "/home/fas/leonard/swk2/miniconda3/envs/maskRCNN/lib/python3.6/site-packages/mask_rcnn-2.1-py3.6.egg/mrcnn/model.py", line 1695, in data_generator
    use_mini_mask=config.USE_MINI_MASK)
  File "/home/fas/leonard/swk2/miniconda3/envs/maskRCNN/lib/python3.6/site-packages/mask_rcnn-2.1-py3.6.egg/mrcnn/model.py", line 1210, in load_image_gt
    mask, class_ids = dataset.load_mask(image_id)
  File "balloon.py", line 171, in load_mask
    mask[rr, cc, i] = 1
IndexError: index 2027 is out of bounds for axis 1 with size 2027
ERROR:root:Error processing image {'id': 'b28120553_0263.jpg', 'source': 'balloon', 'path': '../../datasets/illustrations/train/b28120553_0263.jpg', 'width': 1789, 'height': 3082, 'polygons': [{'name': 'rect', 'x': 263, 'y': 64, 'width': 1310, 'height': 1099}, {'name': 'rect', 'x': 150, 'y': 1200, 'width': 681, 'height': 913}, {'name': 'rect', 'x': 1087, 'y': 1380, 'width': 614, 'height': 632}, {'name': 'rect', 'x': 986, 'y': 2158, 'width': 720, 'height': 757}, {'name': 'rect', 'x': 128, 'y': 2223, 'width': 659, 'height': 684}]}
Traceback (most recent call last):
  File "/home/fas/leonard/swk2/miniconda3/envs/maskRCNN/lib/python3.6/site-packages/mask_rcnn-2.1-py3.6.egg/mrcnn/model.py", line 1695, in data_generator
    use_mini_mask=config.USE_MINI_MASK)
  File "/home/fas/leonard/swk2/miniconda3/envs/maskRCNN/lib/python3.6/site-packages/mask_rcnn-2.1-py3.6.egg/mrcnn/model.py", line 1210, in load_image_gt
    mask, class_ids = dataset.load_mask(image_id)
  File "balloon.py", line 171, in load_mask
    mask[rr, cc, i] = 1
IndexError: index 1789 is out of bounds for axis 1 with size 1789
ERROR:root:Error processing image {'id': 's3edinburghmedical04edinuoft_0477.jpg', 'source': 'balloon', 'path': '../../datasets/illustrations/train/s3edinburghmedical04edinuoft_0477.jpg', 'width': 2126, 'height': 3206, 'polygons': [{'name': 'rect', 'x': 267, 'y': 320, 'width': 1355, 'height': 1165}, {'name': 'rect', 'x': 311, 'y': 1717, 'width': 1260, 'height': 1092}]}
Traceback (most recent call last):
  File "/home/fas/leonard/swk2/miniconda3/envs/maskRCNN/lib/python3.6/site-packages/mask_rcnn-2.1-py3.6.egg/mrcnn/model.py", line 1695, in data_generator
    use_mini_mask=config.USE_MINI_MASK)
  File "/home/fas/leonard/swk2/miniconda3/envs/maskRCNN/lib/python3.6/site-packages/mask_rcnn-2.1-py3.6.egg/mrcnn/model.py", line 1210, in load_image_gt
    mask, class_ids = dataset.load_mask(image_id)
  File "balloon.py", line 171, in load_mask
    mask[rr, cc, i] = 1
IndexError: index 2126 is out of bounds for axis 1 with size 2126
ERROR:root:Error processing image {'id': 'b2193311x_0654.jpg', 'source': 'balloon', 'path': '../../datasets/illustrations/train/b2193311x_0654.jpg', 'width': 1759, 'height': 3008, 'polygons': [{'name': 'rect', 'x': 193, 'y': 95, 'width': 1369, 'height': 2708}]}
Traceback (most recent call last):
  File "/home/fas/leonard/swk2/miniconda3/envs/maskRCNN/lib/python3.6/site-packages/mask_rcnn-2.1-py3.6.egg/mrcnn/model.py", line 1695, in data_generator
    use_mini_mask=config.USE_MINI_MASK)
  File "/home/fas/leonard/swk2/miniconda3/envs/maskRCNN/lib/python3.6/site-packages/mask_rcnn-2.1-py3.6.egg/mrcnn/model.py", line 1210, in load_image_gt
    mask, class_ids = dataset.load_mask(image_id)
  File "balloon.py", line 171, in load_mask
    mask[rr, cc, i] = 1
IndexError: index 1759 is out of bounds for axis 1 with size 1759
ERROR:root:Error processing image {'id': 'b21303502_0001_0191.jpg', 'source': 'balloon', 'path': '../../datasets/illustrations/train/b21303502_0001_0191.jpg', 'width': 1790, 'height': 3122, 'polygons': [{'name': 'rect', 'x': 297, 'y': 1011, 'width': 1085, 'height': 1029}]}
Traceback (most recent call last):
  File "/home/fas/leonard/swk2/miniconda3/envs/maskRCNN/lib/python3.6/site-packages/mask_rcnn-2.1-py3.6.egg/mrcnn/model.py", line 1695, in data_generator
    use_mini_mask=config.USE_MINI_MASK)
  File "/home/fas/leonard/swk2/miniconda3/envs/maskRCNN/lib/python3.6/site-packages/mask_rcnn-2.1-py3.6.egg/mrcnn/model.py", line 1210, in load_image_gt
    mask, class_ids = dataset.load_mask(image_id)
  File "balloon.py", line 171, in load_mask
    mask[rr, cc, i] = 1
IndexError: index 1790 is out of bounds for axis 1 with size 1790
ERROR:root:Error processing image {'id': 's3edinburghmedical04edinuoft_0477.jpg', 'source': 'balloon', 'path': '../../datasets/illustrations/train/s3edinburghmedical04edinuoft_0477.jpg', 'width': 2126, 'height': 3206, 'polygons': [{'name': 'rect', 'x': 267, 'y': 320, 'width': 1355, 'height': 1165}, {'name': 'rect', 'x': 311, 'y': 1717, 'width': 1260, 'height': 1092}]}
Traceback (most recent call last):
  File "/home/fas/leonard/swk2/miniconda3/envs/maskRCNN/lib/python3.6/site-packages/mask_rcnn-2.1-py3.6.egg/mrcnn/model.py", line 1695, in data_generator
    use_mini_mask=config.USE_MINI_MASK)
  File "/home/fas/leonard/swk2/miniconda3/envs/maskRCNN/lib/python3.6/site-packages/mask_rcnn-2.1-py3.6.egg/mrcnn/model.py", line 1210, in load_image_gt
    mask, class_ids = dataset.load_mask(image_id)
  File "balloon.py", line 171, in load_mask
    mask[rr, cc, i] = 1
IndexError: index 2126 is out of bounds for axis 1 with size 2126
ERROR:root:Error processing image {'id': 'differentialdiag002cabo_0463.jpg', 'source': 'balloon', 'path': '../../datasets/illustrations/train/differentialdiag002cabo_0463.jpg', 'width': 2041, 'height': 3441, 'polygons': [{'name': 'rect', 'x': 368, 'y': 593, 'width': 1203, 'height': 2286}]}
Traceback (most recent call last):
  File "/home/fas/leonard/swk2/miniconda3/envs/maskRCNN/lib/python3.6/site-packages/mask_rcnn-2.1-py3.6.egg/mrcnn/model.py", line 1695, in data_generator
    use_mini_mask=config.USE_MINI_MASK)
  File "/home/fas/leonard/swk2/miniconda3/envs/maskRCNN/lib/python3.6/site-packages/mask_rcnn-2.1-py3.6.egg/mrcnn/model.py", line 1210, in load_image_gt
    mask, class_ids = dataset.load_mask(image_id)
  File "balloon.py", line 171, in load_mask
    mask[rr, cc, i] = 1
IndexError: index 2041 is out of bounds for axis 1 with size 2041
ERROR:root:Error processing image {'id': 'textbookofbotany00strauoft_0604.jpg', 'source': 'balloon', 'path': '../../datasets/illustrations/train/textbookofbotany00strauoft_0604.jpg', 'width': 1918, 'height': 3216, 'polygons': [{'name': 'rect', 'x': 261, 'y': 2208, 'width': 398, 'height': 421}, {'name': 'rect', 'x': 857, 'y': 510, 'width': 873, 'height': 2179}]}
Traceback (most recent call last):
  File "/home/fas/leonard/swk2/miniconda3/envs/maskRCNN/lib/python3.6/site-packages/mask_rcnn-2.1-py3.6.egg/mrcnn/model.py", line 1695, in data_generator
    use_mini_mask=config.USE_MINI_MASK)
  File "/home/fas/leonard/swk2/miniconda3/envs/maskRCNN/lib/python3.6/site-packages/mask_rcnn-2.1-py3.6.egg/mrcnn/model.py", line 1210, in load_image_gt
    mask, class_ids = dataset.load_mask(image_id)
  File "balloon.py", line 171, in load_mask
    mask[rr, cc, i] = 1
IndexError: index 2208 is out of bounds for axis 1 with size 1918
ERROR:root:Error processing image {'id': '67440190R_0259.jpg', 'source': 'balloon', 'path': '../../datasets/illustrations/train/67440190R_0259.jpg', 'width': 3357, 'height': 4424, 'polygons': [{'name': 'rect', 'x': 596, 'y': 618, 'width': 1898, 'height': 1451}, {'name': 'rect', 'x': 543, 'y': 2331, 'width': 1998, 'height': 1437}]}
Traceback (most recent call last):
  File "/home/fas/leonard/swk2/miniconda3/envs/maskRCNN/lib/python3.6/site-packages/mask_rcnn-2.1-py3.6.egg/mrcnn/model.py", line 1695, in data_generator
    use_mini_mask=config.USE_MINI_MASK)
  File "/home/fas/leonard/swk2/miniconda3/envs/maskRCNN/lib/python3.6/site-packages/mask_rcnn-2.1-py3.6.egg/mrcnn/model.py", line 1210, in load_image_gt
    mask, class_ids = dataset.load_mask(image_id)
  File "balloon.py", line 171, in load_mask
    mask[rr, cc, i] = 1
IndexError: index 3357 is out of bounds for axis 1 with size 3357
ERROR:root:Error processing image {'id': 'b22365977_0007.jpg', 'source': 'balloon', 'path': '../../datasets/illustrations/train/b22365977_0007.jpg', 'width': 2642, 'height': 4292, 'polygons': [{'name': 'rect', 'x': 348, 'y': 556, 'width': 2064, 'height': 1657}, {'name': 'rect', 'x': 527, 'y': 2629, 'width': 1606, 'height': 1121}]}
Traceback (most recent call last):
  File "/home/fas/leonard/swk2/miniconda3/envs/maskRCNN/lib/python3.6/site-packages/mask_rcnn-2.1-py3.6.egg/mrcnn/model.py", line 1695, in data_generator
    use_mini_mask=config.USE_MINI_MASK)
  File "/home/fas/leonard/swk2/miniconda3/envs/maskRCNN/lib/python3.6/site-packages/mask_rcnn-2.1-py3.6.egg/mrcnn/model.py", line 1210, in load_image_gt
    mask, class_ids = dataset.load_mask(image_id)
  File "balloon.py", line 171, in load_mask
    mask[rr, cc, i] = 1
IndexError: index 2642 is out of bounds for axis 1 with size 2642
ERROR:root:Error processing image {'id': 's3edinburghmedical04edinuoft_0477.jpg', 'source': 'balloon', 'path': '../../datasets/illustrations/train/s3edinburghmedical04edinuoft_0477.jpg', 'width': 2126, 'height': 3206, 'polygons': [{'name': 'rect', 'x': 267, 'y': 320, 'width': 1355, 'height': 1165}, {'name': 'rect', 'x': 311, 'y': 1717, 'width': 1260, 'height': 1092}]}
Traceback (most recent call last):
  File "/home/fas/leonard/swk2/miniconda3/envs/maskRCNN/lib/python3.6/site-packages/mask_rcnn-2.1-py3.6.egg/mrcnn/model.py", line 1695, in data_generator
    use_mini_mask=config.USE_MINI_MASK)
  File "/home/fas/leonard/swk2/miniconda3/envs/maskRCNN/lib/python3.6/site-packages/mask_rcnn-2.1-py3.6.egg/mrcnn/model.py", line 1210, in load_image_gt
    mask, class_ids = dataset.load_mask(image_id)
  File "balloon.py", line 171, in load_mask
    mask[rr, cc, i] = 1
IndexError: index 2126 is out of bounds for axis 1 with size 2126
ERROR:root:Error processing image {'id': 'textbookofbotany00strauoft_0416.jpg', 'source': 'balloon', 'path': '../../datasets/illustrations/train/textbookofbotany00strauoft_0416.jpg', 'width': 1918, 'height': 3216, 'polygons': [{'name': 'rect', 'x': 143, 'y': 519, 'width': 895, 'height': 386}, {'name': 'rect', 'x': 857, 'y': 1201, 'width': 879, 'height': 1265}]}
Traceback (most recent call last):
  File "/home/fas/leonard/swk2/miniconda3/envs/maskRCNN/lib/python3.6/site-packages/mask_rcnn-2.1-py3.6.egg/mrcnn/model.py", line 1695, in data_generator
    use_mini_mask=config.USE_MINI_MASK)
  File "/home/fas/leonard/swk2/miniconda3/envs/maskRCNN/lib/python3.6/site-packages/mask_rcnn-2.1-py3.6.egg/mrcnn/model.py", line 1210, in load_image_gt
    mask, class_ids = dataset.load_mask(image_id)
  File "balloon.py", line 171, in load_mask
    mask[rr, cc, i] = 1
IndexError: index 1918 is out of bounds for axis 1 with size 1918
ERROR:root:Error processing image {'id': 'gynecology00grav_0453.jpg', 'source': 'balloon', 'path': '../../datasets/illustrations/train/gynecology00grav_0453.jpg', 'width': 2329, 'height': 3708, 'polygons': [{'name': 'rect', 'x': 169, 'y': 533, 'width': 933, 'height': 834}, {'name': 'rect', 'x': 1161, 'y': 547, 'width': 933, 'height': 816}, {'name': 'rect', 'x': 617, 'y': 1987, 'width': 1021, 'height': 896}]}
Traceback (most recent call last):
  File "/home/fas/leonard/swk2/miniconda3/envs/maskRCNN/lib/python3.6/site-packages/mask_rcnn-2.1-py3.6.egg/mrcnn/model.py", line 1695, in data_generator
    use_mini_mask=config.USE_MINI_MASK)
  File "/home/fas/leonard/swk2/miniconda3/envs/maskRCNN/lib/python3.6/site-packages/mask_rcnn-2.1-py3.6.egg/mrcnn/model.py", line 1210, in load_image_gt
    mask, class_ids = dataset.load_mask(image_id)
  File "balloon.py", line 171, in load_mask
    mask[rr, cc, i] = 1
IndexError: index 2329 is out of bounds for axis 1 with size 2329
ERROR:root:Error processing image {'id': 'differentialdiag002cabo_0623.jpg', 'source': 'balloon', 'path': '../../datasets/illustrations/train/differentialdiag002cabo_0623.jpg', 'width': 2041, 'height': 3441, 'polygons': [{'name': 'rect', 'x': 460, 'y': 1046, 'width': 1145, 'height': 1250}]}
Traceback (most recent call last):
  File "/home/fas/leonard/swk2/miniconda3/envs/maskRCNN/lib/python3.6/site-packages/mask_rcnn-2.1-py3.6.egg/mrcnn/model.py", line 1695, in data_generator
    use_mini_mask=config.USE_MINI_MASK)
  File "/home/fas/leonard/swk2/miniconda3/envs/maskRCNN/lib/python3.6/site-packages/mask_rcnn-2.1-py3.6.egg/mrcnn/model.py", line 1210, in load_image_gt
    mask, class_ids = dataset.load_mask(image_id)
  File "balloon.py", line 171, in load_mask
    mask[rr, cc, i] = 1
IndexError: index 2041 is out of bounds for axis 1 with size 2041
ERROR:root:Error processing image {'id': 'transactamersurg26ameruoft_0566.jpg', 'source': 'balloon', 'path': '../../datasets/illustrations/train/transactamersurg26ameruoft_0566.jpg', 'width': 2099, 'height': 3490, 'polygons': [{'name': 'rect', 'x': 228, 'y': 498, 'width': 1795, 'height': 2417}]}
Traceback (most recent call last):
  File "/home/fas/leonard/swk2/miniconda3/envs/maskRCNN/lib/python3.6/site-packages/mask_rcnn-2.1-py3.6.egg/mrcnn/model.py", line 1695, in data_generator
    use_mini_mask=config.USE_MINI_MASK)
  File "/home/fas/leonard/swk2/miniconda3/envs/maskRCNN/lib/python3.6/site-packages/mask_rcnn-2.1-py3.6.egg/mrcnn/model.py", line 1210, in load_image_gt
    mask, class_ids = dataset.load_mask(image_id)
  File "balloon.py", line 171, in load_mask
    mask[rr, cc, i] = 1
IndexError: index 2099 is out of bounds for axis 1 with size 2099
ERROR:root:Error processing image {'id': 'anaestheticsthei1914buxt_0281.jpg', 'source': 'balloon', 'path': '../../datasets/illustrations/train/anaestheticsthei1914buxt_0281.jpg', 'width': 1959, 'height': 3136, 'polygons': [{'name': 'rect', 'x': 618, 'y': 705, 'width': 540, 'height': 817}, {'name': 'rect', 'x': 1332, 'y': 1990, 'width': 369, 'height': 649}]}
Traceback (most recent call last):
  File "/home/fas/leonard/swk2/miniconda3/envs/maskRCNN/lib/python3.6/site-packages/mask_rcnn-2.1-py3.6.egg/mrcnn/model.py", line 1695, in data_generator
    use_mini_mask=config.USE_MINI_MASK)
  File "/home/fas/leonard/swk2/miniconda3/envs/maskRCNN/lib/python3.6/site-packages/mask_rcnn-2.1-py3.6.egg/mrcnn/model.py", line 1210, in load_image_gt
    mask, class_ids = dataset.load_mask(image_id)
  File "balloon.py", line 171, in load_mask
    mask[rr, cc, i] = 1
IndexError: index 1990 is out of bounds for axis 1 with size 1959
ERROR:root:Error processing image {'id': 'exceptionalchild00roma_0013.jpg', 'source': 'balloon', 'path': '../../datasets/illustrations/train/exceptionalchild00roma_0013.jpg', 'width': 2853, 'height': 2081, 'polygons': [{'name': 'rect', 'x': 173, 'y': 445, 'width': 2130, 'height': 1341}]}
Traceback (most recent call last):
  File "/home/fas/leonard/swk2/miniconda3/envs/maskRCNN/lib/python3.6/site-packages/mask_rcnn-2.1-py3.6.egg/mrcnn/model.py", line 1695, in data_generator
    use_mini_mask=config.USE_MINI_MASK)
  File "/home/fas/leonard/swk2/miniconda3/envs/maskRCNN/lib/python3.6/site-packages/mask_rcnn-2.1-py3.6.egg/mrcnn/model.py", line 1210, in load_image_gt
    mask, class_ids = dataset.load_mask(image_id)
  File "balloon.py", line 171, in load_mask
    mask[rr, cc, i] = 1
IndexError: index 2081 is out of bounds for axis 0 with size 2081
ERROR:root:Error processing image {'id': 'manualofoperativ00stim_0138.jpg', 'source': 'balloon', 'path': '../../datasets/illustrations/train/manualofoperativ00stim_0138.jpg', 'width': 2107, 'height': 3489, 'polygons': [{'name': 'rect', 'x': 594, 'y': 715, 'width': 919, 'height': 2072}]}
Traceback (most recent call last):
  File "/home/fas/leonard/swk2/miniconda3/envs/maskRCNN/lib/python3.6/site-packages/mask_rcnn-2.1-py3.6.egg/mrcnn/model.py", line 1695, in data_generator
    use_mini_mask=config.USE_MINI_MASK)
  File "/home/fas/leonard/swk2/miniconda3/envs/maskRCNN/lib/python3.6/site-packages/mask_rcnn-2.1-py3.6.egg/mrcnn/model.py", line 1210, in load_image_gt
    mask, class_ids = dataset.load_mask(image_id)
  File "balloon.py", line 171, in load_mask
    mask[rr, cc, i] = 1
IndexError: index 2107 is out of bounds for axis 1 with size 2107
ERROR:root:Error processing image {'id': 'newyorkpresbyter00newy_2_0024.jpg', 'source': 'balloon', 'path': '../../datasets/illustrations/train/newyorkpresbyter00newy_2_0024.jpg', 'width': 2870, 'height': 3820, 'polygons': [{'name': 'rect', 'x': 95, 'y': 942, 'width': 2707, 'height': 2613}]}
Traceback (most recent call last):
  File "/home/fas/leonard/swk2/miniconda3/envs/maskRCNN/lib/python3.6/site-packages/mask_rcnn-2.1-py3.6.egg/mrcnn/model.py", line 1695, in data_generator
    use_mini_mask=config.USE_MINI_MASK)
  File "/home/fas/leonard/swk2/miniconda3/envs/maskRCNN/lib/python3.6/site-packages/mask_rcnn-2.1-py3.6.egg/mrcnn/model.py", line 1210, in load_image_gt
    mask, class_ids = dataset.load_mask(image_id)
  File "balloon.py", line 171, in load_mask
    mask[rr, cc, i] = 1
IndexError: index 2870 is out of bounds for axis 1 with size 2870
ERROR:root:Error processing image {'id': 'gynecology00grav_0713.jpg', 'source': 'balloon', 'path': '../../datasets/illustrations/train/gynecology00grav_0713.jpg', 'width': 2329, 'height': 3708, 'polygons': [{'name': 'rect', 'x': 665, 'y': 823, 'width': 996, 'height': 1763}]}
Traceback (most recent call last):
  File "/home/fas/leonard/swk2/miniconda3/envs/maskRCNN/lib/python3.6/site-packages/mask_rcnn-2.1-py3.6.egg/mrcnn/model.py", line 1695, in data_generator
    use_mini_mask=config.USE_MINI_MASK)
  File "/home/fas/leonard/swk2/miniconda3/envs/maskRCNN/lib/python3.6/site-packages/mask_rcnn-2.1-py3.6.egg/mrcnn/model.py", line 1210, in load_image_gt
    mask, class_ids = dataset.load_mask(image_id)
  File "balloon.py", line 171, in load_mask
    mask[rr, cc, i] = 1
IndexError: index 2329 is out of bounds for axis 1 with size 2329
ERROR:root:Error processing image {'id': 'differentialdiag002cabo_0623.jpg', 'source': 'balloon', 'path': '../../datasets/illustrations/train/differentialdiag002cabo_0623.jpg', 'width': 2041, 'height': 3441, 'polygons': [{'name': 'rect', 'x': 460, 'y': 1046, 'width': 1145, 'height': 1250}]}
Traceback (most recent call last):
  File "/home/fas/leonard/swk2/miniconda3/envs/maskRCNN/lib/python3.6/site-packages/mask_rcnn-2.1-py3.6.egg/mrcnn/model.py", line 1695, in data_generator
    use_mini_mask=config.USE_MINI_MASK)
  File "/home/fas/leonard/swk2/miniconda3/envs/maskRCNN/lib/python3.6/site-packages/mask_rcnn-2.1-py3.6.egg/mrcnn/model.py", line 1210, in load_image_gt
    mask, class_ids = dataset.load_mask(image_id)
  File "balloon.py", line 171, in load_mask
    mask[rr, cc, i] = 1
IndexError: index 2041 is out of bounds for axis 1 with size 2041
ERROR:root:Error processing image {'id': 'b29123082_0081.jpg', 'source': 'balloon', 'path': '../../datasets/illustrations/train/b29123082_0081.jpg', 'width': 2024, 'height': 3346, 'polygons': [{'name': 'rect', 'x': 23, 'y': 788, 'width': 1988, 'height': 1534}]}
Traceback (most recent call last):
  File "/home/fas/leonard/swk2/miniconda3/envs/maskRCNN/lib/python3.6/site-packages/mask_rcnn-2.1-py3.6.egg/mrcnn/model.py", line 1695, in data_generator
    use_mini_mask=config.USE_MINI_MASK)
  File "/home/fas/leonard/swk2/miniconda3/envs/maskRCNN/lib/python3.6/site-packages/mask_rcnn-2.1-py3.6.egg/mrcnn/model.py", line 1210, in load_image_gt
    mask, class_ids = dataset.load_mask(image_id)
  File "balloon.py", line 171, in load_mask
    mask[rr, cc, i] = 1
IndexError: index 2024 is out of bounds for axis 1 with size 2024
ERROR:root:Error processing image {'id': 'b21932323_0260.jpg', 'source': 'balloon', 'path': '../../datasets/illustrations/train/b21932323_0260.jpg', 'width': 1811, 'height': 2946, 'polygons': [{'name': 'rect', 'x': 782, 'y': 1881, 'width': 373, 'height': 385}]}
Traceback (most recent call last):
  File "/home/fas/leonard/swk2/miniconda3/envs/maskRCNN/lib/python3.6/site-packages/mask_rcnn-2.1-py3.6.egg/mrcnn/model.py", line 1695, in data_generator
    use_mini_mask=config.USE_MINI_MASK)
  File "/home/fas/leonard/swk2/miniconda3/envs/maskRCNN/lib/python3.6/site-packages/mask_rcnn-2.1-py3.6.egg/mrcnn/model.py", line 1210, in load_image_gt
    mask, class_ids = dataset.load_mask(image_id)
  File "balloon.py", line 171, in load_mask
    mask[rr, cc, i] = 1
IndexError: index 1881 is out of bounds for axis 1 with size 1811
ERROR:root:Error processing image {'id': 'hughespracticeof1911hugh_0460.jpg', 'source': 'balloon', 'path': '../../datasets/illustrations/train/hughespracticeof1911hugh_0460.jpg', 'width': 2177, 'height': 3424, 'polygons': [{'name': 'rect', 'x': 241, 'y': 285, 'width': 916, 'height': 1099}, {'name': 'rect', 'x': 1285, 'y': 471, 'width': 743, 'height': 722}, {'name': 'rect', 'x': 264, 'y': 1801, 'width': 756, 'height': 763}, {'name': 'rect', 'x': 1265, 'y': 1750, 'width': 783, 'height': 807}]}
Traceback (most recent call last):
  File "/home/fas/leonard/swk2/miniconda3/envs/maskRCNN/lib/python3.6/site-packages/mask_rcnn-2.1-py3.6.egg/mrcnn/model.py", line 1695, in data_generator
    use_mini_mask=config.USE_MINI_MASK)
  File "/home/fas/leonard/swk2/miniconda3/envs/maskRCNN/lib/python3.6/site-packages/mask_rcnn-2.1-py3.6.egg/mrcnn/model.py", line 1210, in load_image_gt
    mask, class_ids = dataset.load_mask(image_id)
  File "balloon.py", line 171, in load_mask
    mask[rr, cc, i] = 1
IndexError: index 2177 is out of bounds for axis 1 with size 2177
ERROR:root:Error processing image {'id': 'textbookofbotany00strauoft_0604.jpg', 'source': 'balloon', 'path': '../../datasets/illustrations/train/textbookofbotany00strauoft_0604.jpg', 'width': 1918, 'height': 3216, 'polygons': [{'name': 'rect', 'x': 261, 'y': 2208, 'width': 398, 'height': 421}, {'name': 'rect', 'x': 857, 'y': 510, 'width': 873, 'height': 2179}]}
Traceback (most recent call last):
  File "/home/fas/leonard/swk2/miniconda3/envs/maskRCNN/lib/python3.6/site-packages/mask_rcnn-2.1-py3.6.egg/mrcnn/model.py", line 1695, in data_generator
    use_mini_mask=config.USE_MINI_MASK)
  File "/home/fas/leonard/swk2/miniconda3/envs/maskRCNN/lib/python3.6/site-packages/mask_rcnn-2.1-py3.6.egg/mrcnn/model.py", line 1210, in load_image_gt
    mask, class_ids = dataset.load_mask(image_id)
  File "balloon.py", line 171, in load_mask
    mask[rr, cc, i] = 1
IndexError: index 2208 is out of bounds for axis 1 with size 1918
ERROR:root:Error processing image {'id': 'b28120553_0263.jpg', 'source': 'balloon', 'path': '../../datasets/illustrations/train/b28120553_0263.jpg', 'width': 1789, 'height': 3082, 'polygons': [{'name': 'rect', 'x': 263, 'y': 64, 'width': 1310, 'height': 1099}, {'name': 'rect', 'x': 150, 'y': 1200, 'width': 681, 'height': 913}, {'name': 'rect', 'x': 1087, 'y': 1380, 'width': 614, 'height': 632}, {'name': 'rect', 'x': 986, 'y': 2158, 'width': 720, 'height': 757}, {'name': 'rect', 'x': 128, 'y': 2223, 'width': 659, 'height': 684}]}
Traceback (most recent call last):
  File "/home/fas/leonard/swk2/miniconda3/envs/maskRCNN/lib/python3.6/site-packages/mask_rcnn-2.1-py3.6.egg/mrcnn/model.py", line 1695, in data_generator
    use_mini_mask=config.USE_MINI_MASK)
  File "/home/fas/leonard/swk2/miniconda3/envs/maskRCNN/lib/python3.6/site-packages/mask_rcnn-2.1-py3.6.egg/mrcnn/model.py", line 1210, in load_image_gt
    mask, class_ids = dataset.load_mask(image_id)
  File "balloon.py", line 171, in load_mask
    mask[rr, cc, i] = 1
IndexError: index 1789 is out of bounds for axis 1 with size 1789
ERROR:root:Error processing image {'id': 'gynecology00grav_0127.jpg', 'source': 'balloon', 'path': '../../datasets/illustrations/train/gynecology00grav_0127.jpg', 'width': 2329, 'height': 3708, 'polygons': [{'name': 'rect', 'x': 198, 'y': 1227, 'width': 1888, 'height': 1271}]}
Traceback (most recent call last):
  File "/home/fas/leonard/swk2/miniconda3/envs/maskRCNN/lib/python3.6/site-packages/mask_rcnn-2.1-py3.6.egg/mrcnn/model.py", line 1695, in data_generator
    use_mini_mask=config.USE_MINI_MASK)
  File "/home/fas/leonard/swk2/miniconda3/envs/maskRCNN/lib/python3.6/site-packages/mask_rcnn-2.1-py3.6.egg/mrcnn/model.py", line 1210, in load_image_gt
    mask, class_ids = dataset.load_mask(image_id)
  File "balloon.py", line 171, in load_mask
    mask[rr, cc, i] = 1
IndexError: index 2329 is out of bounds for axis 1 with size 2329
ERROR:root:Error processing image {'id': 'differentialdiag002cabo_0463.jpg', 'source': 'balloon', 'path': '../../datasets/illustrations/train/differentialdiag002cabo_0463.jpg', 'width': 2041, 'height': 3441, 'polygons': [{'name': 'rect', 'x': 368, 'y': 593, 'width': 1203, 'height': 2286}]}
Traceback (most recent call last):
  File "/home/fas/leonard/swk2/miniconda3/envs/maskRCNN/lib/python3.6/site-packages/mask_rcnn-2.1-py3.6.egg/mrcnn/model.py", line 1695, in data_generator
    use_mini_mask=config.USE_MINI_MASK)
  File "/home/fas/leonard/swk2/miniconda3/envs/maskRCNN/lib/python3.6/site-packages/mask_rcnn-2.1-py3.6.egg/mrcnn/model.py", line 1210, in load_image_gt
    mask, class_ids = dataset.load_mask(image_id)
  File "balloon.py", line 171, in load_mask
    mask[rr, cc, i] = 1
IndexError: index 2041 is out of bounds for axis 1 with size 2041
ERROR:root:Error processing image {'id': 'differentialdiag002cabo_0623.jpg', 'source': 'balloon', 'path': '../../datasets/illustrations/train/differentialdiag002cabo_0623.jpg', 'width': 2041, 'height': 3441, 'polygons': [{'name': 'rect', 'x': 460, 'y': 1046, 'width': 1145, 'height': 1250}]}
Traceback (most recent call last):
  File "/home/fas/leonard/swk2/miniconda3/envs/maskRCNN/lib/python3.6/site-packages/mask_rcnn-2.1-py3.6.egg/mrcnn/model.py", line 1695, in data_generator
    use_mini_mask=config.USE_MINI_MASK)
  File "/home/fas/leonard/swk2/miniconda3/envs/maskRCNN/lib/python3.6/site-packages/mask_rcnn-2.1-py3.6.egg/mrcnn/model.py", line 1210, in load_image_gt
    mask, class_ids = dataset.load_mask(image_id)
  File "balloon.py", line 171, in load_mask
    mask[rr, cc, i] = 1
IndexError: index 2041 is out of bounds for axis 1 with size 2041
ERROR:root:Error processing image {'id': 'traitdesfistules00jobe_0373.jpg', 'source': 'balloon', 'path': '../../datasets/illustrations/train/traitdesfistules00jobe_0373.jpg', 'width': 2208, 'height': 3894, 'polygons': [{'name': 'rect', 'x': 69, 'y': 890, 'width': 1958, 'height': 2254}]}
Traceback (most recent call last):
  File "/home/fas/leonard/swk2/miniconda3/envs/maskRCNN/lib/python3.6/site-packages/mask_rcnn-2.1-py3.6.egg/mrcnn/model.py", line 1695, in data_generator
    use_mini_mask=config.USE_MINI_MASK)
  File "/home/fas/leonard/swk2/miniconda3/envs/maskRCNN/lib/python3.6/site-packages/mask_rcnn-2.1-py3.6.egg/mrcnn/model.py", line 1210, in load_image_gt
    mask, class_ids = dataset.load_mask(image_id)
  File "balloon.py", line 171, in load_mask
    mask[rr, cc, i] = 1
IndexError: index 2208 is out of bounds for axis 1 with size 2208
ERROR:root:Error processing image {'id': 'transactamersurg26ameruoft_0566.jpg', 'source': 'balloon', 'path': '../../datasets/illustrations/train/transactamersurg26ameruoft_0566.jpg', 'width': 2099, 'height': 3490, 'polygons': [{'name': 'rect', 'x': 228, 'y': 498, 'width': 1795, 'height': 2417}]}
Traceback (most recent call last):
  File "/home/fas/leonard/swk2/miniconda3/envs/maskRCNN/lib/python3.6/site-packages/mask_rcnn-2.1-py3.6.egg/mrcnn/model.py", line 1695, in data_generator
    use_mini_mask=config.USE_MINI_MASK)
  File "/home/fas/leonard/swk2/miniconda3/envs/maskRCNN/lib/python3.6/site-packages/mask_rcnn-2.1-py3.6.egg/mrcnn/model.py", line 1210, in load_image_gt
    mask, class_ids = dataset.load_mask(image_id)
  File "balloon.py", line 171, in load_mask
    mask[rr, cc, i] = 1
IndexError: index 2099 is out of bounds for axis 1 with size 2099
ERROR:root:Error processing image {'id': 'missourimedicine5611miss_0352.jpg', 'source': 'balloon', 'path': '../../datasets/illustrations/train/missourimedicine5611miss_0352.jpg', 'width': 2513, 'height': 3695, 'polygons': [{'name': 'rect', 'x': 274, 'y': 530, 'width': 1075, 'height': 743}, {'name': 'rect', 'x': 271, 'y': 2052, 'width': 1075, 'height': 739}]}
Traceback (most recent call last):
  File "/home/fas/leonard/swk2/miniconda3/envs/maskRCNN/lib/python3.6/site-packages/mask_rcnn-2.1-py3.6.egg/mrcnn/model.py", line 1695, in data_generator
    use_mini_mask=config.USE_MINI_MASK)
  File "/home/fas/leonard/swk2/miniconda3/envs/maskRCNN/lib/python3.6/site-packages/mask_rcnn-2.1-py3.6.egg/mrcnn/model.py", line 1210, in load_image_gt
    mask, class_ids = dataset.load_mask(image_id)
  File "balloon.py", line 171, in load_mask
    mask[rr, cc, i] = 1
IndexError: index 2513 is out of bounds for axis 1 with size 2513
ERROR:root:Error processing image {'id': 'manualofoperativ00stim_0138.jpg', 'source': 'balloon', 'path': '../../datasets/illustrations/train/manualofoperativ00stim_0138.jpg', 'width': 2107, 'height': 3489, 'polygons': [{'name': 'rect', 'x': 594, 'y': 715, 'width': 919, 'height': 2072}]}
Traceback (most recent call last):
  File "/home/fas/leonard/swk2/miniconda3/envs/maskRCNN/lib/python3.6/site-packages/mask_rcnn-2.1-py3.6.egg/mrcnn/model.py", line 1695, in data_generator
    use_mini_mask=config.USE_MINI_MASK)
  File "/home/fas/leonard/swk2/miniconda3/envs/maskRCNN/lib/python3.6/site-packages/mask_rcnn-2.1-py3.6.egg/mrcnn/model.py", line 1210, in load_image_gt
    mask, class_ids = dataset.load_mask(image_id)
  File "balloon.py", line 171, in load_mask
    mask[rr, cc, i] = 1
IndexError: index 2107 is out of bounds for axis 1 with size 2107
ERROR:root:Error processing image {'id': 'lehrbuchderspeci001strm_0639.jpg', 'source': 'balloon', 'path': '../../datasets/illustrations/train/lehrbuchderspeci001strm_0639.jpg', 'width': 2065, 'height': 3269, 'polygons': [{'name': 'rect', 'x': 1314, 'y': 469, 'width': 320, 'height': 414}, {'name': 'rect', 'x': 1172, 'y': 1042, 'width': 641, 'height': 1660}]}
Traceback (most recent call last):
  File "/home/fas/leonard/swk2/miniconda3/envs/maskRCNN/lib/python3.6/site-packages/mask_rcnn-2.1-py3.6.egg/mrcnn/model.py", line 1695, in data_generator
    use_mini_mask=config.USE_MINI_MASK)
  File "/home/fas/leonard/swk2/miniconda3/envs/maskRCNN/lib/python3.6/site-packages/mask_rcnn-2.1-py3.6.egg/mrcnn/model.py", line 1210, in load_image_gt
    mask, class_ids = dataset.load_mask(image_id)
  File "balloon.py", line 171, in load_mask
    mask[rr, cc, i] = 1
IndexError: index 2065 is out of bounds for axis 1 with size 2065
ERROR:root:Error processing image {'id': 'b21932323_0151.jpg', 'source': 'balloon', 'path': '../../datasets/illustrations/train/b21932323_0151.jpg', 'width': 1811, 'height': 2946, 'polygons': [{'name': 'rect', 'x': 408, 'y': 726, 'width': 872, 'height': 1341}]}
Traceback (most recent call last):
  File "/home/fas/leonard/swk2/miniconda3/envs/maskRCNN/lib/python3.6/site-packages/mask_rcnn-2.1-py3.6.egg/mrcnn/model.py", line 1695, in data_generator
    use_mini_mask=config.USE_MINI_MASK)
  File "/home/fas/leonard/swk2/miniconda3/envs/maskRCNN/lib/python3.6/site-packages/mask_rcnn-2.1-py3.6.egg/mrcnn/model.py", line 1210, in load_image_gt
    mask, class_ids = dataset.load_mask(image_id)
  File "balloon.py", line 171, in load_mask
    mask[rr, cc, i] = 1
IndexError: index 1811 is out of bounds for axis 1 with size 1811
ERROR:root:Error processing image {'id': 'gynecology00grav_0453.jpg', 'source': 'balloon', 'path': '../../datasets/illustrations/train/gynecology00grav_0453.jpg', 'width': 2329, 'height': 3708, 'polygons': [{'name': 'rect', 'x': 169, 'y': 533, 'width': 933, 'height': 834}, {'name': 'rect', 'x': 1161, 'y': 547, 'width': 933, 'height': 816}, {'name': 'rect', 'x': 617, 'y': 1987, 'width': 1021, 'height': 896}]}
Traceback (most recent call last):
  File "/home/fas/leonard/swk2/miniconda3/envs/maskRCNN/lib/python3.6/site-packages/mask_rcnn-2.1-py3.6.egg/mrcnn/model.py", line 1695, in data_generator
    use_mini_mask=config.USE_MINI_MASK)
  File "/home/fas/leonard/swk2/miniconda3/envs/maskRCNN/lib/python3.6/site-packages/mask_rcnn-2.1-py3.6.egg/mrcnn/model.py", line 1210, in load_image_gt
    mask, class_ids = dataset.load_mask(image_id)
  File "balloon.py", line 171, in load_mask
    mask[rr, cc, i] = 1
IndexError: index 2329 is out of bounds for axis 1 with size 2329
ERROR:root:Error processing image {'id': 'differentialdiag002cabo_0463.jpg', 'source': 'balloon', 'path': '../../datasets/illustrations/train/differentialdiag002cabo_0463.jpg', 'width': 2041, 'height': 3441, 'polygons': [{'name': 'rect', 'x': 368, 'y': 593, 'width': 1203, 'height': 2286}]}
Traceback (most recent call last):
  File "/home/fas/leonard/swk2/miniconda3/envs/maskRCNN/lib/python3.6/site-packages/mask_rcnn-2.1-py3.6.egg/mrcnn/model.py", line 1695, in data_generator
    use_mini_mask=config.USE_MINI_MASK)
  File "/home/fas/leonard/swk2/miniconda3/envs/maskRCNN/lib/python3.6/site-packages/mask_rcnn-2.1-py3.6.egg/mrcnn/model.py", line 1210, in load_image_gt
    mask, class_ids = dataset.load_mask(image_id)
  File "balloon.py", line 171, in load_mask
    mask[rr, cc, i] = 1
IndexError: index 2041 is out of bounds for axis 1 with size 2041
ERROR:root:Error processing image {'id': 'b2150751x_0001_0585.jpg', 'source': 'balloon', 'path': '../../datasets/illustrations/train/b2150751x_0001_0585.jpg', 'width': 2025, 'height': 3331, 'polygons': [{'name': 'rect', 'x': 937, 'y': 1200, 'width': 729, 'height': 930}]}
Traceback (most recent call last):
  File "/home/fas/leonard/swk2/miniconda3/envs/maskRCNN/lib/python3.6/site-packages/mask_rcnn-2.1-py3.6.egg/mrcnn/model.py", line 1695, in data_generator
    use_mini_mask=config.USE_MINI_MASK)
  File "/home/fas/leonard/swk2/miniconda3/envs/maskRCNN/lib/python3.6/site-packages/mask_rcnn-2.1-py3.6.egg/mrcnn/model.py", line 1210, in load_image_gt
    mask, class_ids = dataset.load_mask(image_id)
  File "balloon.py", line 171, in load_mask
    mask[rr, cc, i] = 1
IndexError: index 2025 is out of bounds for axis 1 with size 2025
blarg [ 594  594  594 ... 1512 1512 1512] [ 715  716  717 ... 2784 2785 2786]
blarg [ 263  263  263 ... 1572 1572 1572] [  64   65   66 ... 1160 1161 1162]
blarg [150 150 150 ... 830 830 830] [1200 1201 1202 ... 2110 2111 2112]
blarg [ 143  143  143 ... 1037 1037 1037] [519 520 521 ... 902 903 904]
blarg [ 857  857  857 ... 1735 1735 1735] [1201 1202 1203 ... 2463 2464 2465]
blarg [ 618  618  618 ... 1157 1157 1157] [ 705  706  707 ... 1519 1520 1521]
blarg [1332 1332 1332 ... 1700 1700 1700] [1990 1991 1992 ... 2636 2637 2638]
blarg [ 228  228  228 ... 2022 2022 2022] [ 498  499  500 ... 2912 2913 2914]
blarg [ 937  937  937 ... 1665 1665 1665] [1200 1201 1202 ... 2127 2128 2129]
Traceback (most recent call last):
  File "/home/fas/leonard/swk2/miniconda3/envs/maskRCNN/lib/python3.6/site-packages/keras/utils/data_utils.py", line 677, in _data_generator_task
    generator_output = next(self._generator)
  File "/home/fas/leonard/swk2/miniconda3/envs/maskRCNN/lib/python3.6/site-packages/mask_rcnn-2.1-py3.6.egg/mrcnn/model.py", line 1695, in data_generator
    use_mini_mask=config.USE_MINI_MASK)
  File "/home/fas/leonard/swk2/miniconda3/envs/maskRCNN/lib/python3.6/site-packages/mask_rcnn-2.1-py3.6.egg/mrcnn/model.py", line 1210, in load_image_gt
    mask, class_ids = dataset.load_mask(image_id)
  File "balloon.py", line 171, in load_mask
    mask[rr, cc, i] = 1
IndexError: index 2025 is out of bounds for axis 1 with size 2025
ERROR:root:Error processing image {'id': 'b21286711_0231.jpg', 'source': 'balloon', 'path': '../../datasets/illustrations/train/b21286711_0231.jpg', 'width': 1812, 'height': 3270, 'polygons': [{'name': 'rect', 'x': 900, 'y': 961, 'width': 754, 'height': 1120}]}
Traceback (most recent call last):
  File "/home/fas/leonard/swk2/miniconda3/envs/maskRCNN/lib/python3.6/site-packages/mask_rcnn-2.1-py3.6.egg/mrcnn/model.py", line 1695, in data_generator
    use_mini_mask=config.USE_MINI_MASK)
  File "/home/fas/leonard/swk2/miniconda3/envs/maskRCNN/lib/python3.6/site-packages/mask_rcnn-2.1-py3.6.egg/mrcnn/model.py", line 1210, in load_image_gt
    mask, class_ids = dataset.load_mask(image_id)
  File "balloon.py", line 171, in load_mask
    mask[rr, cc, i] = 1
IndexError: index 1812 is out of bounds for axis 1 with size 1812
ERROR:root:Error processing image {'id': 'americanjournal46ameruoft_0831.jpg', 'source': 'balloon', 'path': '../../datasets/illustrations/train/americanjournal46ameruoft_0831.jpg', 'width': 2137, 'height': 3279, 'polygons': [{'name': 'rect', 'x': 487, 'y': 991, 'width': 1065, 'height': 1283}]}
Traceback (most recent call last):
  File "/home/fas/leonard/swk2/miniconda3/envs/maskRCNN/lib/python3.6/site-packages/mask_rcnn-2.1-py3.6.egg/mrcnn/model.py", line 1695, in data_generator
    use_mini_mask=config.USE_MINI_MASK)
  File "/home/fas/leonard/swk2/miniconda3/envs/maskRCNN/lib/python3.6/site-packages/mask_rcnn-2.1-py3.6.egg/mrcnn/model.py", line 1210, in load_image_gt
    mask, class_ids = dataset.load_mask(image_id)
  File "balloon.py", line 171, in load_mask
    mask[rr, cc, i] = 1
IndexError: index 2137 is out of bounds for axis 1 with size 2137
ERROR:root:Error processing image {'id': 'textbookofbotany00strauoft_0416.jpg', 'source': 'balloon', 'path': '../../datasets/illustrations/train/textbookofbotany00strauoft_0416.jpg', 'width': 1918, 'height': 3216, 'polygons': [{'name': 'rect', 'x': 143, 'y': 519, 'width': 895, 'height': 386}, {'name': 'rect', 'x': 857, 'y': 1201, 'width': 879, 'height': 1265}]}
Traceback (most recent call last):
  File "/home/fas/leonard/swk2/miniconda3/envs/maskRCNN/lib/python3.6/site-packages/mask_rcnn-2.1-py3.6.egg/mrcnn/model.py", line 1695, in data_generator
    use_mini_mask=config.USE_MINI_MASK)
  File "/home/fas/leonard/swk2/miniconda3/envs/maskRCNN/lib/python3.6/site-packages/mask_rcnn-2.1-py3.6.egg/mrcnn/model.py", line 1210, in load_image_gt
    mask, class_ids = dataset.load_mask(image_id)
  File "balloon.py", line 171, in load_mask
    mask[rr, cc, i] = 1
IndexError: index 1918 is out of bounds for axis 1 with size 1918
ERROR:root:Error processing image {'id': 'b2150751x_0001_0585.jpg', 'source': 'balloon', 'path': '../../datasets/illustrations/train/b2150751x_0001_0585.jpg', 'width': 2025, 'height': 3331, 'polygons': [{'name': 'rect', 'x': 937, 'y': 1200, 'width': 729, 'height': 930}]}
Traceback (most recent call last):
  File "/home/fas/leonard/swk2/miniconda3/envs/maskRCNN/lib/python3.6/site-packages/mask_rcnn-2.1-py3.6.egg/mrcnn/model.py", line 1695, in data_generator
    use_mini_mask=config.USE_MINI_MASK)
  File "/home/fas/leonard/swk2/miniconda3/envs/maskRCNN/lib/python3.6/site-packages/mask_rcnn-2.1-py3.6.egg/mrcnn/model.py", line 1210, in load_image_gt
    mask, class_ids = dataset.load_mask(image_id)
  File "balloon.py", line 171, in load_mask
    mask[rr, cc, i] = 1
IndexError: index 2025 is out of bounds for axis 1 with size 2025
ERROR:root:Error processing image {'id': 'transactionsstud4161coll_0123.jpg', 'source': 'balloon', 'path': '../../datasets/illustrations/train/transactionsstud4161coll_0123.jpg', 'width': 2204, 'height': 3345, 'polygons': [{'name': 'rect', 'x': 46, 'y': 219, 'width': 2002, 'height': 1558}, {'name': 'rect', 'x': 388, 'y': 1853, 'width': 1299, 'height': 1021}]}
Traceback (most recent call last):
  File "/home/fas/leonard/swk2/miniconda3/envs/maskRCNN/lib/python3.6/site-packages/mask_rcnn-2.1-py3.6.egg/mrcnn/model.py", line 1695, in data_generator
    use_mini_mask=config.USE_MINI_MASK)
  File "/home/fas/leonard/swk2/miniconda3/envs/maskRCNN/lib/python3.6/site-packages/mask_rcnn-2.1-py3.6.egg/mrcnn/model.py", line 1210, in load_image_gt
    mask, class_ids = dataset.load_mask(image_id)
  File "balloon.py", line 171, in load_mask
    mask[rr, cc, i] = 1
IndexError: index 2204 is out of bounds for axis 1 with size 2204
ERROR:root:Error processing image {'id': 'exceptionalchild00roma_0013.jpg', 'source': 'balloon', 'path': '../../datasets/illustrations/train/exceptionalchild00roma_0013.jpg', 'width': 2853, 'height': 2081, 'polygons': [{'name': 'rect', 'x': 173, 'y': 445, 'width': 2130, 'height': 1341}]}
Traceback (most recent call last):
  File "/home/fas/leonard/swk2/miniconda3/envs/maskRCNN/lib/python3.6/site-packages/mask_rcnn-2.1-py3.6.egg/mrcnn/model.py", line 1695, in data_generator
    use_mini_mask=config.USE_MINI_MASK)
  File "/home/fas/leonard/swk2/miniconda3/envs/maskRCNN/lib/python3.6/site-packages/mask_rcnn-2.1-py3.6.egg/mrcnn/model.py", line 1210, in load_image_gt
    mask, class_ids = dataset.load_mask(image_id)
  File "balloon.py", line 171, in load_mask
    mask[rr, cc, i] = 1
IndexError: index 2081 is out of bounds for axis 0 with size 2081
ERROR:root:Error processing image {'id': 'b21648979_0064.jpg', 'source': 'balloon', 'path': '../../datasets/illustrations/train/b21648979_0064.jpg', 'width': 2309, 'height': 4147, 'polygons': [{'name': 'rect', 'x': 440, 'y': 1097, 'width': 1438, 'height': 1491}]}
Traceback (most recent call last):
  File "/home/fas/leonard/swk2/miniconda3/envs/maskRCNN/lib/python3.6/site-packages/mask_rcnn-2.1-py3.6.egg/mrcnn/model.py", line 1695, in data_generator
    use_mini_mask=config.USE_MINI_MASK)
  File "/home/fas/leonard/swk2/miniconda3/envs/maskRCNN/lib/python3.6/site-packages/mask_rcnn-2.1-py3.6.egg/mrcnn/model.py", line 1210, in load_image_gt
    mask, class_ids = dataset.load_mask(image_id)
  File "balloon.py", line 171, in load_mask
    mask[rr, cc, i] = 1
IndexError: index 2309 is out of bounds for axis 1 with size 2309
ERROR:root:Error processing image {'id': 'b21286711_0231.jpg', 'source': 'balloon', 'path': '../../datasets/illustrations/train/b21286711_0231.jpg', 'width': 1812, 'height': 3270, 'polygons': [{'name': 'rect', 'x': 900, 'y': 961, 'width': 754, 'height': 1120}]}
Traceback (most recent call last):
  File "/home/fas/leonard/swk2/miniconda3/envs/maskRCNN/lib/python3.6/site-packages/mask_rcnn-2.1-py3.6.egg/mrcnn/model.py", line 1695, in data_generator
    use_mini_mask=config.USE_MINI_MASK)
  File "/home/fas/leonard/swk2/miniconda3/envs/maskRCNN/lib/python3.6/site-packages/mask_rcnn-2.1-py3.6.egg/mrcnn/model.py", line 1210, in load_image_gt
    mask, class_ids = dataset.load_mask(image_id)
  File "balloon.py", line 171, in load_mask
    mask[rr, cc, i] = 1
IndexError: index 1812 is out of bounds for axis 1 with size 1812
ERROR:root:Error processing image {'id': 'b21932323_0188.jpg', 'source': 'balloon', 'path': '../../datasets/illustrations/train/b21932323_0188.jpg', 'width': 1811, 'height': 2946, 'polygons': [{'name': 'rect', 'x': 271, 'y': 612, 'width': 1315, 'height': 1362}]}
Traceback (most recent call last):
  File "/home/fas/leonard/swk2/miniconda3/envs/maskRCNN/lib/python3.6/site-packages/mask_rcnn-2.1-py3.6.egg/mrcnn/model.py", line 1695, in data_generator
    use_mini_mask=config.USE_MINI_MASK)
  File "/home/fas/leonard/swk2/miniconda3/envs/maskRCNN/lib/python3.6/site-packages/mask_rcnn-2.1-py3.6.egg/mrcnn/model.py", line 1210, in load_image_gt
    mask, class_ids = dataset.load_mask(image_id)
  File "balloon.py", line 171, in load_mask
    mask[rr, cc, i] = 1
IndexError: index 1811 is out of bounds for axis 1 with size 1811
ERROR:root:Error processing image {'id': 'gynecology00grav_0453.jpg', 'source': 'balloon', 'path': '../../datasets/illustrations/train/gynecology00grav_0453.jpg', 'width': 2329, 'height': 3708, 'polygons': [{'name': 'rect', 'x': 169, 'y': 533, 'width': 933, 'height': 834}, {'name': 'rect', 'x': 1161, 'y': 547, 'width': 933, 'height': 816}, {'name': 'rect', 'x': 617, 'y': 1987, 'width': 1021, 'height': 896}]}
Traceback (most recent call last):
  File "/home/fas/leonard/swk2/miniconda3/envs/maskRCNN/lib/python3.6/site-packages/mask_rcnn-2.1-py3.6.egg/mrcnn/model.py", line 1695, in data_generator
    use_mini_mask=config.USE_MINI_MASK)
  File "/home/fas/leonard/swk2/miniconda3/envs/maskRCNN/lib/python3.6/site-packages/mask_rcnn-2.1-py3.6.egg/mrcnn/model.py", line 1210, in load_image_gt
    mask, class_ids = dataset.load_mask(image_id)
  File "balloon.py", line 171, in load_mask
    mask[rr, cc, i] = 1
IndexError: index 2329 is out of bounds for axis 1 with size 2329
ERROR:root:Error processing image {'id': 'textbookofbotany00strauoft_0681.jpg', 'source': 'balloon', 'path': '../../datasets/illustrations/train/textbookofbotany00strauoft_0681.jpg', 'width': 1918, 'height': 3216, 'polygons': [{'name': 'rect', 'x': 201, 'y': 366, 'width': 1354, 'height': 2425}]}
Traceback (most recent call last):
  File "/home/fas/leonard/swk2/miniconda3/envs/maskRCNN/lib/python3.6/site-packages/mask_rcnn-2.1-py3.6.egg/mrcnn/model.py", line 1695, in data_generator
    use_mini_mask=config.USE_MINI_MASK)
  File "/home/fas/leonard/swk2/miniconda3/envs/maskRCNN/lib/python3.6/site-packages/mask_rcnn-2.1-py3.6.egg/mrcnn/model.py", line 1210, in load_image_gt
    mask, class_ids = dataset.load_mask(image_id)
  File "balloon.py", line 171, in load_mask
    mask[rr, cc, i] = 1
IndexError: index 1918 is out of bounds for axis 1 with size 1918
ERROR:root:Error processing image {'id': 'gynecology00grav_0307.jpg', 'source': 'balloon', 'path': '../../datasets/illustrations/train/gynecology00grav_0307.jpg', 'width': 2329, 'height': 3708, 'polygons': [{'name': 'rect', 'x': 279, 'y': 882, 'width': 1649, 'height': 1638}]}
Traceback (most recent call last):
  File "/home/fas/leonard/swk2/miniconda3/envs/maskRCNN/lib/python3.6/site-packages/mask_rcnn-2.1-py3.6.egg/mrcnn/model.py", line 1695, in data_generator
    use_mini_mask=config.USE_MINI_MASK)
  File "/home/fas/leonard/swk2/miniconda3/envs/maskRCNN/lib/python3.6/site-packages/mask_rcnn-2.1-py3.6.egg/mrcnn/model.py", line 1210, in load_image_gt
    mask, class_ids = dataset.load_mask(image_id)
  File "balloon.py", line 171, in load_mask
    mask[rr, cc, i] = 1
IndexError: index 2329 is out of bounds for axis 1 with size 2329
blarg [ 211  211  211 ... 1778 1778 1778] [ 905  906  907 ... 2178 2179 2180]
blarg [ 225  225  225 ... 1553 1553 1553] [657 658 659 ... 891 892 893]
blarg [ 801  801  801 ... 1775 1775 1775] [ 385  386  387 ... 1272 1273 1274]
blarg [ 460  460  460 ... 1604 1604 1604] [1046 1047 1048 ... 2293 2294 2295]
blarg [  23   23   23 ... 2010 2010 2010] [ 788  789  790 ... 2319 2320 2321]
blarg [261 261 261 ... 658 658 658] [2208 2209 2210 ... 2626 2627 2628]
blarg [1314 1314 1314 ... 1633 1633 1633] [469 470 471 ... 880 881 882]
blarg [1172 1172 1172 ... 1812 1812 1812] [1042 1043 1044 ... 2699 2700 2701]
blarg [ 201  201  201 ... 1554 1554 1554] [ 366  367  368 ... 2788 2789 2790]
Traceback (most recent call last):
  File "/home/fas/leonard/swk2/miniconda3/envs/maskRCNN/lib/python3.6/site-packages/keras/utils/data_utils.py", line 677, in _data_generator_task
    generator_output = next(self._generator)
  File "/home/fas/leonard/swk2/miniconda3/envs/maskRCNN/lib/python3.6/site-packages/mask_rcnn-2.1-py3.6.egg/mrcnn/model.py", line 1695, in data_generator
    use_mini_mask=config.USE_MINI_MASK)
  File "/home/fas/leonard/swk2/miniconda3/envs/maskRCNN/lib/python3.6/site-packages/mask_rcnn-2.1-py3.6.egg/mrcnn/model.py", line 1210, in load_image_gt
    mask, class_ids = dataset.load_mask(image_id)
  File "balloon.py", line 171, in load_mask
    mask[rr, cc, i] = 1
IndexError: index 1918 is out of bounds for axis 1 with size 1918
blarg [ 145  145  145 ... 1140 1140 1140] [ 683  684  685 ... 1447 1448 1449]
blarg [1209 1209 1209 ... 2353 2353 2353] [ 546  547  548 ... 1531 1532 1533]
blarg [  76   76   76 ... 1236 1236 1236] [2149 2150 2151 ... 3174 3175 3176]
blarg [1059 1059 1059 ... 1934 1934 1934] [ 570  571  572 ... 1653 1654 1655]
blarg [ 594  594  594 ... 1512 1512 1512] [ 715  716  717 ... 2784 2785 2786]
blarg [ 368  368  368 ... 1570 1570 1570] [ 593  594  595 ... 2876 2877 2878]
blarg [ 440  440  440 ... 1877 1877 1877] [1097 1098 1099 ... 2585 2586 2587]
blarg [ 225  225  225 ... 1553 1553 1553] [657 658 659 ... 891 892 893]
ERROR:root:Error processing image {'id': 'b28120553_0263.jpg', 'source': 'balloon', 'path': '../../datasets/illustrations/train/b28120553_0263.jpg', 'width': 1789, 'height': 3082, 'polygons': [{'name': 'rect', 'x': 263, 'y': 64, 'width': 1310, 'height': 1099}, {'name': 'rect', 'x': 150, 'y': 1200, 'width': 681, 'height': 913}, {'name': 'rect', 'x': 1087, 'y': 1380, 'width': 614, 'height': 632}, {'name': 'rect', 'x': 986, 'y': 2158, 'width': 720, 'height': 757}, {'name': 'rect', 'x': 128, 'y': 2223, 'width': 659, 'height': 684}]}
Traceback (most recent call last):
  File "/home/fas/leonard/swk2/miniconda3/envs/maskRCNN/lib/python3.6/site-packages/mask_rcnn-2.1-py3.6.egg/mrcnn/model.py", line 1695, in data_generator
    use_mini_mask=config.USE_MINI_MASK)
  File "/home/fas/leonard/swk2/miniconda3/envs/maskRCNN/lib/python3.6/site-packages/mask_rcnn-2.1-py3.6.egg/mrcnn/model.py", line 1210, in load_image_gt
    mask, class_ids = dataset.load_mask(image_id)
  File "balloon.py", line 171, in load_mask
    mask[rr, cc, i] = 1
IndexError: index 1789 is out of bounds for axis 1 with size 1789
ERROR:root:Error processing image {'id': 'b21932323_0260.jpg', 'source': 'balloon', 'path': '../../datasets/illustrations/train/b21932323_0260.jpg', 'width': 1811, 'height': 2946, 'polygons': [{'name': 'rect', 'x': 782, 'y': 1881, 'width': 373, 'height': 385}]}
Traceback (most recent call last):
  File "/home/fas/leonard/swk2/miniconda3/envs/maskRCNN/lib/python3.6/site-packages/mask_rcnn-2.1-py3.6.egg/mrcnn/model.py", line 1695, in data_generator
    use_mini_mask=config.USE_MINI_MASK)
  File "/home/fas/leonard/swk2/miniconda3/envs/maskRCNN/lib/python3.6/site-packages/mask_rcnn-2.1-py3.6.egg/mrcnn/model.py", line 1210, in load_image_gt
    mask, class_ids = dataset.load_mask(image_id)
  File "balloon.py", line 171, in load_mask
    mask[rr, cc, i] = 1
IndexError: index 1881 is out of bounds for axis 1 with size 1811
ERROR:root:Error processing image {'id': 'b21357298_0133.jpg', 'source': 'balloon', 'path': '../../datasets/illustrations/train/b21357298_0133.jpg', 'width': 1660, 'height': 2826, 'polygons': [{'name': 'rect', 'x': 115, 'y': 647, 'width': 1257, 'height': 1366}]}
Traceback (most recent call last):
  File "/home/fas/leonard/swk2/miniconda3/envs/maskRCNN/lib/python3.6/site-packages/mask_rcnn-2.1-py3.6.egg/mrcnn/model.py", line 1695, in data_generator
    use_mini_mask=config.USE_MINI_MASK)
  File "/home/fas/leonard/swk2/miniconda3/envs/maskRCNN/lib/python3.6/site-packages/mask_rcnn-2.1-py3.6.egg/mrcnn/model.py", line 1210, in load_image_gt
    mask, class_ids = dataset.load_mask(image_id)
  File "balloon.py", line 171, in load_mask
    mask[rr, cc, i] = 1
IndexError: index 1660 is out of bounds for axis 1 with size 1660
ERROR:root:Error processing image {'id': 'gynecology00grav_0453.jpg', 'source': 'balloon', 'path': '../../datasets/illustrations/train/gynecology00grav_0453.jpg', 'width': 2329, 'height': 3708, 'polygons': [{'name': 'rect', 'x': 169, 'y': 533, 'width': 933, 'height': 834}, {'name': 'rect', 'x': 1161, 'y': 547, 'width': 933, 'height': 816}, {'name': 'rect', 'x': 617, 'y': 1987, 'width': 1021, 'height': 896}]}
Traceback (most recent call last):
  File "/home/fas/leonard/swk2/miniconda3/envs/maskRCNN/lib/python3.6/site-packages/mask_rcnn-2.1-py3.6.egg/mrcnn/model.py", line 1695, in data_generator
    use_mini_mask=config.USE_MINI_MASK)
  File "/home/fas/leonard/swk2/miniconda3/envs/maskRCNN/lib/python3.6/site-packages/mask_rcnn-2.1-py3.6.egg/mrcnn/model.py", line 1210, in load_image_gt
    mask, class_ids = dataset.load_mask(image_id)
  File "balloon.py", line 171, in load_mask
    mask[rr, cc, i] = 1
IndexError: index 2329 is out of bounds for axis 1 with size 2329
blarg [ 267  267  267 ... 1621 1621 1621] [ 320  321  322 ... 1482 1483 1484]
blarg [ 311  311  311 ... 1570 1570 1570] [1717 1718 1719 ... 2806 2807 2808]
blarg [ 143  143  143 ... 1037 1037 1037] [519 520 521 ... 902 903 904]
blarg [ 857  857  857 ... 1735 1735 1735] [1201 1202 1203 ... 2463 2464 2465]
blarg [1059 1059 1059 ... 1934 1934 1934] [ 570  571  572 ... 1653 1654 1655]
blarg [ 241  241  241 ... 1156 1156 1156] [ 285  286  287 ... 1381 1382 1383]
blarg [1285 1285 1285 ... 2027 2027 2027] [ 471  472  473 ... 1190 1191 1192]
blarg [ 264  264  264 ... 1019 1019 1019] [1801 1802 1803 ... 2561 2562 2563]
blarg [ 594  594  594 ... 1512 1512 1512] [ 715  716  717 ... 2784 2785 2786]
blarg [ 937  937  937 ... 1665 1665 1665] [1200 1201 1202 ... 2127 2128 2129]
blarg [ 169  169  169 ... 1101 1101 1101] [ 533  534  535 ... 1364 1365 1366]
blarg [1161 1161 1161 ... 2093 2093 2093] [ 547  548  549 ... 1360 1361 1362]
blarg [ 617  617  617 ... 1637 1637 1637] [1987 1988 1989 ... 2880 2881 2882]
Traceback (most recent call last):
  File "/home/fas/leonard/swk2/miniconda3/envs/maskRCNN/lib/python3.6/site-packages/keras/utils/data_utils.py", line 677, in _data_generator_task
    generator_output = next(self._generator)
  File "/home/fas/leonard/swk2/miniconda3/envs/maskRCNN/lib/python3.6/site-packages/mask_rcnn-2.1-py3.6.egg/mrcnn/model.py", line 1695, in data_generator
    use_mini_mask=config.USE_MINI_MASK)
  File "/home/fas/leonard/swk2/miniconda3/envs/maskRCNN/lib/python3.6/site-packages/mask_rcnn-2.1-py3.6.egg/mrcnn/model.py", line 1210, in load_image_gt
    mask, class_ids = dataset.load_mask(image_id)
  File "balloon.py", line 171, in load_mask
    mask[rr, cc, i] = 1
IndexError: index 2329 is out of bounds for axis 1 with size 2329
ERROR:root:Error processing image {'id': 'b22365977_0007.jpg', 'source': 'balloon', 'path': '../../datasets/illustrations/train/b22365977_0007.jpg', 'width': 2642, 'height': 4292, 'polygons': [{'name': 'rect', 'x': 348, 'y': 556, 'width': 2064, 'height': 1657}, {'name': 'rect', 'x': 527, 'y': 2629, 'width': 1606, 'height': 1121}]}
Traceback (most recent call last):
  File "/home/fas/leonard/swk2/miniconda3/envs/maskRCNN/lib/python3.6/site-packages/mask_rcnn-2.1-py3.6.egg/mrcnn/model.py", line 1695, in data_generator
    use_mini_mask=config.USE_MINI_MASK)
  File "/home/fas/leonard/swk2/miniconda3/envs/maskRCNN/lib/python3.6/site-packages/mask_rcnn-2.1-py3.6.egg/mrcnn/model.py", line 1210, in load_image_gt
    mask, class_ids = dataset.load_mask(image_id)
  File "balloon.py", line 171, in load_mask
    mask[rr, cc, i] = 1
IndexError: index 2642 is out of bounds for axis 1 with size 2642
ERROR:root:Error processing image {'id': 'newyorkpresbyter00newy_2_0024.jpg', 'source': 'balloon', 'path': '../../datasets/illustrations/train/newyorkpresbyter00newy_2_0024.jpg', 'width': 2870, 'height': 3820, 'polygons': [{'name': 'rect', 'x': 95, 'y': 942, 'width': 2707, 'height': 2613}]}
Traceback (most recent call last):
  File "/home/fas/leonard/swk2/miniconda3/envs/maskRCNN/lib/python3.6/site-packages/mask_rcnn-2.1-py3.6.egg/mrcnn/model.py", line 1695, in data_generator
    use_mini_mask=config.USE_MINI_MASK)
  File "/home/fas/leonard/swk2/miniconda3/envs/maskRCNN/lib/python3.6/site-packages/mask_rcnn-2.1-py3.6.egg/mrcnn/model.py", line 1210, in load_image_gt
    mask, class_ids = dataset.load_mask(image_id)
  File "balloon.py", line 171, in load_mask
    mask[rr, cc, i] = 1
IndexError: index 2870 is out of bounds for axis 1 with size 2870
ERROR:root:Error processing image {'id': 'gynecology00grav_0127.jpg', 'source': 'balloon', 'path': '../../datasets/illustrations/train/gynecology00grav_0127.jpg', 'width': 2329, 'height': 3708, 'polygons': [{'name': 'rect', 'x': 198, 'y': 1227, 'width': 1888, 'height': 1271}]}
Traceback (most recent call last):
  File "/home/fas/leonard/swk2/miniconda3/envs/maskRCNN/lib/python3.6/site-packages/mask_rcnn-2.1-py3.6.egg/mrcnn/model.py", line 1695, in data_generator
    use_mini_mask=config.USE_MINI_MASK)
  File "/home/fas/leonard/swk2/miniconda3/envs/maskRCNN/lib/python3.6/site-packages/mask_rcnn-2.1-py3.6.egg/mrcnn/model.py", line 1210, in load_image_gt
    mask, class_ids = dataset.load_mask(image_id)
  File "balloon.py", line 171, in load_mask
    mask[rr, cc, i] = 1
IndexError: index 2329 is out of bounds for axis 1 with size 2329
ERROR:root:Error processing image {'id': 'americanjournal46ameruoft_0831.jpg', 'source': 'balloon', 'path': '../../datasets/illustrations/train/americanjournal46ameruoft_0831.jpg', 'width': 2137, 'height': 3279, 'polygons': [{'name': 'rect', 'x': 487, 'y': 991, 'width': 1065, 'height': 1283}]}
Traceback (most recent call last):
  File "/home/fas/leonard/swk2/miniconda3/envs/maskRCNN/lib/python3.6/site-packages/mask_rcnn-2.1-py3.6.egg/mrcnn/model.py", line 1695, in data_generator
    use_mini_mask=config.USE_MINI_MASK)
  File "/home/fas/leonard/swk2/miniconda3/envs/maskRCNN/lib/python3.6/site-packages/mask_rcnn-2.1-py3.6.egg/mrcnn/model.py", line 1210, in load_image_gt
    mask, class_ids = dataset.load_mask(image_id)
  File "balloon.py", line 171, in load_mask
    mask[rr, cc, i] = 1
IndexError: index 2137 is out of bounds for axis 1 with size 2137
ERROR:root:Error processing image {'id': 'b21303502_0001_0191.jpg', 'source': 'balloon', 'path': '../../datasets/illustrations/train/b21303502_0001_0191.jpg', 'width': 1790, 'height': 3122, 'polygons': [{'name': 'rect', 'x': 297, 'y': 1011, 'width': 1085, 'height': 1029}]}
Traceback (most recent call last):
  File "/home/fas/leonard/swk2/miniconda3/envs/maskRCNN/lib/python3.6/site-packages/mask_rcnn-2.1-py3.6.egg/mrcnn/model.py", line 1695, in data_generator
    use_mini_mask=config.USE_MINI_MASK)
  File "/home/fas/leonard/swk2/miniconda3/envs/maskRCNN/lib/python3.6/site-packages/mask_rcnn-2.1-py3.6.egg/mrcnn/model.py", line 1210, in load_image_gt
    mask, class_ids = dataset.load_mask(image_id)
  File "balloon.py", line 171, in load_mask
    mask[rr, cc, i] = 1
IndexError: index 1790 is out of bounds for axis 1 with size 1790
ERROR:root:Error processing image {'id': 'differentialdiag002cabo_0138.jpg', 'source': 'balloon', 'path': '../../datasets/illustrations/train/differentialdiag002cabo_0138.jpg', 'width': 2102, 'height': 3453, 'polygons': [{'name': 'rect', 'x': 608, 'y': 885, 'width': 1114, 'height': 1470}]}
Traceback (most recent call last):
  File "/home/fas/leonard/swk2/miniconda3/envs/maskRCNN/lib/python3.6/site-packages/mask_rcnn-2.1-py3.6.egg/mrcnn/model.py", line 1695, in data_generator
    use_mini_mask=config.USE_MINI_MASK)
  File "/home/fas/leonard/swk2/miniconda3/envs/maskRCNN/lib/python3.6/site-packages/mask_rcnn-2.1-py3.6.egg/mrcnn/model.py", line 1210, in load_image_gt
    mask, class_ids = dataset.load_mask(image_id)
  File "balloon.py", line 171, in load_mask
    mask[rr, cc, i] = 1
IndexError: index 2102 is out of bounds for axis 1 with size 2102
ERROR:root:Error processing image {'id': 'differentialdiag002cabo_0293.jpg', 'source': 'balloon', 'path': '../../datasets/illustrations/train/differentialdiag002cabo_0293.jpg', 'width': 2102, 'height': 3453, 'polygons': [{'name': 'rect', 'x': 431, 'y': 1121, 'width': 1152, 'height': 1230}]}
Traceback (most recent call last):
  File "/home/fas/leonard/swk2/miniconda3/envs/maskRCNN/lib/python3.6/site-packages/mask_rcnn-2.1-py3.6.egg/mrcnn/model.py", line 1695, in data_generator
    use_mini_mask=config.USE_MINI_MASK)
  File "/home/fas/leonard/swk2/miniconda3/envs/maskRCNN/lib/python3.6/site-packages/mask_rcnn-2.1-py3.6.egg/mrcnn/model.py", line 1210, in load_image_gt
    mask, class_ids = dataset.load_mask(image_id)
  File "balloon.py", line 171, in load_mask
    mask[rr, cc, i] = 1
IndexError: index 2102 is out of bounds for axis 1 with size 2102
ERROR:root:Error processing image {'id': 'newyorkpresbyter00newy_2_0024.jpg', 'source': 'balloon', 'path': '../../datasets/illustrations/train/newyorkpresbyter00newy_2_0024.jpg', 'width': 2870, 'height': 3820, 'polygons': [{'name': 'rect', 'x': 95, 'y': 942, 'width': 2707, 'height': 2613}]}
Traceback (most recent call last):
  File "/home/fas/leonard/swk2/miniconda3/envs/maskRCNN/lib/python3.6/site-packages/mask_rcnn-2.1-py3.6.egg/mrcnn/model.py", line 1695, in data_generator
    use_mini_mask=config.USE_MINI_MASK)
  File "/home/fas/leonard/swk2/miniconda3/envs/maskRCNN/lib/python3.6/site-packages/mask_rcnn-2.1-py3.6.egg/mrcnn/model.py", line 1210, in load_image_gt
    mask, class_ids = dataset.load_mask(image_id)
  File "balloon.py", line 171, in load_mask
    mask[rr, cc, i] = 1
IndexError: index 2870 is out of bounds for axis 1 with size 2870
ERROR:root:Error processing image {'id': 'proceedingsofann1875ameruoft_0636.jpg', 'source': 'balloon', 'path': '../../datasets/illustrations/train/proceedingsofann1875ameruoft_0636.jpg', 'width': 2003, 'height': 3439, 'polygons': [{'name': 'rect', 'x': 518, 'y': 1128, 'width': 1206, 'height': 1553}]}
Traceback (most recent call last):
  File "/home/fas/leonard/swk2/miniconda3/envs/maskRCNN/lib/python3.6/site-packages/mask_rcnn-2.1-py3.6.egg/mrcnn/model.py", line 1695, in data_generator
    use_mini_mask=config.USE_MINI_MASK)
  File "/home/fas/leonard/swk2/miniconda3/envs/maskRCNN/lib/python3.6/site-packages/mask_rcnn-2.1-py3.6.egg/mrcnn/model.py", line 1210, in load_image_gt
    mask, class_ids = dataset.load_mask(image_id)
  File "balloon.py", line 171, in load_mask
    mask[rr, cc, i] = 1
IndexError: index 2003 is out of bounds for axis 1 with size 2003
blarg [ 496  496  496 ... 1578 1578 1578] [1502 1503 1504 ... 3081 3082 3083]
blarg [ 267  267  267 ... 1621 1621 1621] [ 320  321  322 ... 1482 1483 1484]
blarg [ 311  311  311 ... 1570 1570 1570] [1717 1718 1719 ... 2806 2807 2808]
blarg [ 173  173  173 ... 2302 2302 2302] [ 445  446  447 ... 1783 1784 1785]
blarg [ 468  468  468 ... 2431 2431 2431] [ 948  949  950 ... 2131 2132 2133]
blarg [ 900  900  900 ... 1653 1653 1653] [ 961  962  963 ... 2078 2079 2080]
blarg [ 115  115  115 ... 1371 1371 1371] [ 647  648  649 ... 2010 2011 2012]
blarg [ 518  518  518 ... 1723 1723 1723] [1128 1129 1130 ... 2678 2679 2680]
Traceback (most recent call last):
  File "/home/fas/leonard/swk2/miniconda3/envs/maskRCNN/lib/python3.6/site-packages/keras/utils/data_utils.py", line 677, in _data_generator_task
    generator_output = next(self._generator)
  File "/home/fas/leonard/swk2/miniconda3/envs/maskRCNN/lib/python3.6/site-packages/mask_rcnn-2.1-py3.6.egg/mrcnn/model.py", line 1695, in data_generator
    use_mini_mask=config.USE_MINI_MASK)
  File "/home/fas/leonard/swk2/miniconda3/envs/maskRCNN/lib/python3.6/site-packages/mask_rcnn-2.1-py3.6.egg/mrcnn/model.py", line 1210, in load_image_gt
    mask, class_ids = dataset.load_mask(image_id)
  File "balloon.py", line 171, in load_mask
    mask[rr, cc, i] = 1
IndexError: index 2003 is out of bounds for axis 1 with size 2003
ERROR:root:Error processing image {'id': 'b21303502_0001_0191.jpg', 'source': 'balloon', 'path': '../../datasets/illustrations/train/b21303502_0001_0191.jpg', 'width': 1790, 'height': 3122, 'polygons': [{'name': 'rect', 'x': 297, 'y': 1011, 'width': 1085, 'height': 1029}]}
Traceback (most recent call last):
  File "/home/fas/leonard/swk2/miniconda3/envs/maskRCNN/lib/python3.6/site-packages/mask_rcnn-2.1-py3.6.egg/mrcnn/model.py", line 1695, in data_generator
    use_mini_mask=config.USE_MINI_MASK)
  File "/home/fas/leonard/swk2/miniconda3/envs/maskRCNN/lib/python3.6/site-packages/mask_rcnn-2.1-py3.6.egg/mrcnn/model.py", line 1210, in load_image_gt
    mask, class_ids = dataset.load_mask(image_id)
  File "balloon.py", line 171, in load_mask
    mask[rr, cc, i] = 1
IndexError: index 1790 is out of bounds for axis 1 with size 1790
ERROR:root:Error processing image {'id': 'transactionsstud4161coll_0123.jpg', 'source': 'balloon', 'path': '../../datasets/illustrations/train/transactionsstud4161coll_0123.jpg', 'width': 2204, 'height': 3345, 'polygons': [{'name': 'rect', 'x': 46, 'y': 219, 'width': 2002, 'height': 1558}, {'name': 'rect', 'x': 388, 'y': 1853, 'width': 1299, 'height': 1021}]}
Traceback (most recent call last):
  File "/home/fas/leonard/swk2/miniconda3/envs/maskRCNN/lib/python3.6/site-packages/mask_rcnn-2.1-py3.6.egg/mrcnn/model.py", line 1695, in data_generator
    use_mini_mask=config.USE_MINI_MASK)
  File "/home/fas/leonard/swk2/miniconda3/envs/maskRCNN/lib/python3.6/site-packages/mask_rcnn-2.1-py3.6.egg/mrcnn/model.py", line 1210, in load_image_gt
    mask, class_ids = dataset.load_mask(image_id)
  File "balloon.py", line 171, in load_mask
    mask[rr, cc, i] = 1
IndexError: index 2204 is out of bounds for axis 1 with size 2204
blarg [ 241  241  241 ... 1661 1661 1661] [ 740  741  742 ... 1729 1730 1731]
blarg [ 468  468  468 ... 2431 2431 2431] [ 948  949  950 ... 2131 2132 2133]
blarg [ 450  450  450 ... 1325 1325 1325] [ 557  558  559 ... 1487 1488 1489]
blarg [ 514  514  514 ... 1795 1795 1795] [1353 1354 1355 ... 1882 1883 1884]
blarg [ 332  332  332 ... 1142 1142 1142] [378 379 380 ... 697 698 699]
blarg [ 263  263  263 ... 1572 1572 1572] [  64   65   66 ... 1160 1161 1162]
blarg [150 150 150 ... 830 830 830] [1200 1201 1202 ... 2110 2111 2112]
blarg [ 280  280  280 ... 1044 1044 1044] [ 226  227  228 ... 1701 1702 1703]
blarg [1076 1076 1076 ... 1722 1722 1722] [ 490  491  492 ... 1451 1452 1453]
ERROR:root:Error processing image {'id': 'americantextbook00essi_0594.jpg', 'source': 'balloon', 'path': '../../datasets/illustrations/train/americantextbook00essi_0594.jpg', 'width': 2121, 'height': 3452, 'polygons': [{'name': 'rect', 'x': 157, 'y': 1619, 'width': 663, 'height': 324}, {'name': 'rect', 'x': 301, 'y': 2630, 'width': 779, 'height': 434}, {'name': 'rect', 'x': 1346, 'y': 2637, 'width': 492, 'height': 413}]}
Traceback (most recent call last):
  File "/home/fas/leonard/swk2/miniconda3/envs/maskRCNN/lib/python3.6/site-packages/mask_rcnn-2.1-py3.6.egg/mrcnn/model.py", line 1695, in data_generator
    use_mini_mask=config.USE_MINI_MASK)
  File "/home/fas/leonard/swk2/miniconda3/envs/maskRCNN/lib/python3.6/site-packages/mask_rcnn-2.1-py3.6.egg/mrcnn/model.py", line 1210, in load_image_gt
    mask, class_ids = dataset.load_mask(image_id)
  File "balloon.py", line 171, in load_mask
    mask[rr, cc, i] = 1
IndexError: index 2630 is out of bounds for axis 1 with size 2121
blarg [ 173  173  173 ... 2302 2302 2302] [ 445  446  447 ... 1783 1784 1785]
blarg [ 271  271  271 ... 1585 1585 1585] [ 612  613  614 ... 1971 1972 1973]
blarg [ 552  552  552 ... 1707 1707 1707] [1137 1138 1139 ... 2082 2083 2084]
blarg [ 241  241  241 ... 1661 1661 1661] [ 740  741  742 ... 1729 1730 1731]
blarg [ 566  566  566 ... 1305 1305 1305] [ 730  731  732 ... 1717 1718 1719]
blarg [ 169  169  169 ... 1101 1101 1101] [ 533  534  535 ... 1364 1365 1366]
blarg [1161 1161 1161 ... 2093 2093 2093] [ 547  548  549 ... 1360 1361 1362]
blarg [ 617  617  617 ... 1637 1637 1637] [1987 1988 1989 ... 2880 2881 2882]
blarg [ 782  782  782 ... 1154 1154 1154] [1881 1882 1883 ... 2263 2264 2265]
blarg [ 431  431  431 ... 1582 1582 1582] [1121 1122 1123 ... 2348 2349 2350]
blarg [157 157 157 ... 819 819 819] [1619 1620 1621 ... 1940 1941 1942]
blarg [ 301  301  301 ... 1079 1079 1079] [2630 2631 2632 ... 3061 3062 3063]
Traceback (most recent call last):
  File "/home/fas/leonard/swk2/miniconda3/envs/maskRCNN/lib/python3.6/site-packages/keras/utils/data_utils.py", line 677, in _data_generator_task
    generator_output = next(self._generator)
  File "/home/fas/leonard/swk2/miniconda3/envs/maskRCNN/lib/python3.6/site-packages/mask_rcnn-2.1-py3.6.egg/mrcnn/model.py", line 1695, in data_generator
    use_mini_mask=config.USE_MINI_MASK)
  File "/home/fas/leonard/swk2/miniconda3/envs/maskRCNN/lib/python3.6/site-packages/mask_rcnn-2.1-py3.6.egg/mrcnn/model.py", line 1210, in load_image_gt
    mask, class_ids = dataset.load_mask(image_id)
  File "balloon.py", line 171, in load_mask
    mask[rr, cc, i] = 1
IndexError: index 2630 is out of bounds for axis 1 with size 2121
ERROR:root:Error processing image {'id': 'hotspringsofbath00hattuoft_0009.jpg', 'source': 'balloon', 'path': '../../datasets/illustrations/train/hotspringsofbath00hattuoft_0009.jpg', 'width': 2027, 'height': 3192, 'polygons': [{'name': 'rect', 'x': 190, 'y': 421, 'width': 1518, 'height': 2223}]}
Traceback (most recent call last):
  File "/home/fas/leonard/swk2/miniconda3/envs/maskRCNN/lib/python3.6/site-packages/mask_rcnn-2.1-py3.6.egg/mrcnn/model.py", line 1695, in data_generator
    use_mini_mask=config.USE_MINI_MASK)
  File "/home/fas/leonard/swk2/miniconda3/envs/maskRCNN/lib/python3.6/site-packages/mask_rcnn-2.1-py3.6.egg/mrcnn/model.py", line 1210, in load_image_gt
    mask, class_ids = dataset.load_mask(image_id)
  File "balloon.py", line 171, in load_mask
    mask[rr, cc, i] = 1
IndexError: index 2027 is out of bounds for axis 1 with size 2027
ERROR:root:Error processing image {'id': 'hughespracticeof1911hugh_0460.jpg', 'source': 'balloon', 'path': '../../datasets/illustrations/train/hughespracticeof1911hugh_0460.jpg', 'width': 2177, 'height': 3424, 'polygons': [{'name': 'rect', 'x': 241, 'y': 285, 'width': 916, 'height': 1099}, {'name': 'rect', 'x': 1285, 'y': 471, 'width': 743, 'height': 722}, {'name': 'rect', 'x': 264, 'y': 1801, 'width': 756, 'height': 763}, {'name': 'rect', 'x': 1265, 'y': 1750, 'width': 783, 'height': 807}]}
Traceback (most recent call last):
  File "/home/fas/leonard/swk2/miniconda3/envs/maskRCNN/lib/python3.6/site-packages/mask_rcnn-2.1-py3.6.egg/mrcnn/model.py", line 1695, in data_generator
    use_mini_mask=config.USE_MINI_MASK)
  File "/home/fas/leonard/swk2/miniconda3/envs/maskRCNN/lib/python3.6/site-packages/mask_rcnn-2.1-py3.6.egg/mrcnn/model.py", line 1210, in load_image_gt
    mask, class_ids = dataset.load_mask(image_id)
  File "balloon.py", line 171, in load_mask
    mask[rr, cc, i] = 1
IndexError: index 2177 is out of bounds for axis 1 with size 2177
blarg [ 212  212  212 ... 1512 1512 1512] [ 717  718  719 ... 2504 2505 2506]
blarg [ 193  193  193 ... 1561 1561 1561] [  95   96   97 ... 2800 2801 2802]
blarg [261 261 261 ... 658 658 658] [2208 2209 2210 ... 2626 2627 2628]
blarg [ 270  270  270 ... 2237 2237 2237] [ 252  253  254 ... 1564 1565 1566]
blarg [ 348  348  348 ... 2411 2411 2411] [ 556  557  558 ... 2210 2211 2212]
blarg [ 527  527  527 ... 2132 2132 2132] [2629 2630 2631 ... 3747 3748 3749]
blarg [ 608  608  608 ... 1721 1721 1721] [ 885  886  887 ... 2352 2353 2354]
blarg [ 241  241  241 ... 1156 1156 1156] [ 285  286  287 ... 1381 1382 1383]
blarg [1285 1285 1285 ... 2027 2027 2027] [ 471  472  473 ... 1190 1191 1192]
blarg [ 264  264  264 ... 1019 1019 1019] [1801 1802 1803 ... 2561 2562 2563]
Traceback (most recent call last):
  File "/home/fas/leonard/swk2/miniconda3/envs/maskRCNN/lib/python3.6/site-packages/keras/utils/data_utils.py", line 677, in _data_generator_task
    generator_output = next(self._generator)
  File "/home/fas/leonard/swk2/miniconda3/envs/maskRCNN/lib/python3.6/site-packages/mask_rcnn-2.1-py3.6.egg/mrcnn/model.py", line 1695, in data_generator
    use_mini_mask=config.USE_MINI_MASK)
  File "/home/fas/leonard/swk2/miniconda3/envs/maskRCNN/lib/python3.6/site-packages/mask_rcnn-2.1-py3.6.egg/mrcnn/model.py", line 1210, in load_image_gt
    mask, class_ids = dataset.load_mask(image_id)
  File "balloon.py", line 171, in load_mask
    mask[rr, cc, i] = 1
IndexError: index 2177 is out of bounds for axis 1 with size 2177
ERROR:root:Error processing image {'id': 'b21286711_0231.jpg', 'source': 'balloon', 'path': '../../datasets/illustrations/train/b21286711_0231.jpg', 'width': 1812, 'height': 3270, 'polygons': [{'name': 'rect', 'x': 900, 'y': 961, 'width': 754, 'height': 1120}]}
Traceback (most recent call last):
  File "/home/fas/leonard/swk2/miniconda3/envs/maskRCNN/lib/python3.6/site-packages/mask_rcnn-2.1-py3.6.egg/mrcnn/model.py", line 1695, in data_generator
    use_mini_mask=config.USE_MINI_MASK)
  File "/home/fas/leonard/swk2/miniconda3/envs/maskRCNN/lib/python3.6/site-packages/mask_rcnn-2.1-py3.6.egg/mrcnn/model.py", line 1210, in load_image_gt
    mask, class_ids = dataset.load_mask(image_id)
  File "balloon.py", line 171, in load_mask
    mask[rr, cc, i] = 1
IndexError: index 1812 is out of bounds for axis 1 with size 1812
ERROR:root:Error processing image {'id': 'terramariaemedic00unse_14_0128.jpg', 'source': 'balloon', 'path': '../../datasets/illustrations/train/terramariaemedic00unse_14_0128.jpg', 'width': 3546, 'height': 4678, 'polygons': [{'name': 'rect', 'x': 819, 'y': 875, 'width': 1018, 'height': 1301}, {'name': 'rect', 'x': 1898, 'y': 5, 'width': 1592, 'height': 2162}, {'name': 'rect', 'x': 523, 'y': 3449, 'width': 1528, 'height': 870}, {'name': 'rect', 'x': 2111, 'y': 3032, 'width': 1370, 'height': 995}, {'name': 'rect', 'x': 176, 'y': 2236, 'width': 1870, 'height': 1153}]}
Traceback (most recent call last):
  File "/home/fas/leonard/swk2/miniconda3/envs/maskRCNN/lib/python3.6/site-packages/mask_rcnn-2.1-py3.6.egg/mrcnn/model.py", line 1695, in data_generator
    use_mini_mask=config.USE_MINI_MASK)
  File "/home/fas/leonard/swk2/miniconda3/envs/maskRCNN/lib/python3.6/site-packages/mask_rcnn-2.1-py3.6.egg/mrcnn/model.py", line 1210, in load_image_gt
    mask, class_ids = dataset.load_mask(image_id)
  File "balloon.py", line 171, in load_mask
    mask[rr, cc, i] = 1
IndexError: index 3546 is out of bounds for axis 1 with size 3546
ERROR:root:Error processing image {'id': 'b2491051x_0259.jpg', 'source': 'balloon', 'path': '../../datasets/illustrations/train/b2491051x_0259.jpg', 'width': 2182, 'height': 3479, 'polygons': [{'name': 'rect', 'x': 134, 'y': 538, 'width': 1658, 'height': 2410}]}
Traceback (most recent call last):
  File "/home/fas/leonard/swk2/miniconda3/envs/maskRCNN/lib/python3.6/site-packages/mask_rcnn-2.1-py3.6.egg/mrcnn/model.py", line 1695, in data_generator
    use_mini_mask=config.USE_MINI_MASK)
  File "/home/fas/leonard/swk2/miniconda3/envs/maskRCNN/lib/python3.6/site-packages/mask_rcnn-2.1-py3.6.egg/mrcnn/model.py", line 1210, in load_image_gt
    mask, class_ids = dataset.load_mask(image_id)
  File "balloon.py", line 171, in load_mask
    mask[rr, cc, i] = 1
IndexError: index 2182 is out of bounds for axis 1 with size 2182
blarg [ 487  487  487 ... 1551 1551 1551] [ 991  992  993 ... 2271 2272 2273]
blarg [261 261 261 ... 658 658 658] [2208 2209 2210 ... 2626 2627 2628]
blarg [  95   95   95 ... 2801 2801 2801] [ 942  943  944 ... 3552 3553 3554]
blarg [ 263  263  263 ... 1572 1572 1572] [  64   65   66 ... 1160 1161 1162]
blarg [150 150 150 ... 830 830 830] [1200 1201 1202 ... 2110 2111 2112]
blarg [ 538  538  538 ... 1595 1595 1595] [ 520  521  522 ... 1724 1725 1726]
blarg [ 198  198  198 ... 2085 2085 2085] [1227 1228 1229 ... 2495 2496 2497]
blarg [ 134  134  134 ... 1791 1791 1791] [ 538  539  540 ... 2945 2946 2947]
Traceback (most recent call last):
  File "/home/fas/leonard/swk2/miniconda3/envs/maskRCNN/lib/python3.6/site-packages/keras/utils/data_utils.py", line 677, in _data_generator_task
    generator_output = next(self._generator)
  File "/home/fas/leonard/swk2/miniconda3/envs/maskRCNN/lib/python3.6/site-packages/mask_rcnn-2.1-py3.6.egg/mrcnn/model.py", line 1695, in data_generator
    use_mini_mask=config.USE_MINI_MASK)
  File "/home/fas/leonard/swk2/miniconda3/envs/maskRCNN/lib/python3.6/site-packages/mask_rcnn-2.1-py3.6.egg/mrcnn/model.py", line 1210, in load_image_gt
    mask, class_ids = dataset.load_mask(image_id)
  File "balloon.py", line 171, in load_mask
    mask[rr, cc, i] = 1
IndexError: index 2182 is out of bounds for axis 1 with size 2182
ERROR:root:Error processing image {'id': 'differentialdiag002cabo_0117.jpg', 'source': 'balloon', 'path': '../../datasets/illustrations/train/differentialdiag002cabo_0117.jpg', 'width': 2102, 'height': 3453, 'polygons': [{'name': 'rect', 'x': 362, 'y': 885, 'width': 1142, 'height': 1477}]}
Traceback (most recent call last):
  File "/home/fas/leonard/swk2/miniconda3/envs/maskRCNN/lib/python3.6/site-packages/mask_rcnn-2.1-py3.6.egg/mrcnn/model.py", line 1695, in data_generator
    use_mini_mask=config.USE_MINI_MASK)
  File "/home/fas/leonard/swk2/miniconda3/envs/maskRCNN/lib/python3.6/site-packages/mask_rcnn-2.1-py3.6.egg/mrcnn/model.py", line 1210, in load_image_gt
    mask, class_ids = dataset.load_mask(image_id)
  File "balloon.py", line 171, in load_mask
    mask[rr, cc, i] = 1
IndexError: index 2102 is out of bounds for axis 1 with size 2102
blarg [ 263  263  263 ... 1572 1572 1572] [  64   65   66 ... 1160 1161 1162]
blarg [150 150 150 ... 830 830 830] [1200 1201 1202 ... 2110 2111 2112]
blarg [ 241  241  241 ... 1156 1156 1156] [ 285  286  287 ... 1381 1382 1383]
blarg [1285 1285 1285 ... 2027 2027 2027] [ 471  472  473 ... 1190 1191 1192]
blarg [ 264  264  264 ... 1019 1019 1019] [1801 1802 1803 ... 2561 2562 2563]
blarg [ 267  267  267 ... 1621 1621 1621] [ 320  321  322 ... 1482 1483 1484]
blarg [ 311  311  311 ... 1570 1570 1570] [1717 1718 1719 ... 2806 2807 2808]
blarg [1059 1059 1059 ... 1934 1934 1934] [ 570  571  572 ... 1653 1654 1655]
blarg [ 274  274  274 ... 1348 1348 1348] [ 530  531  532 ... 1270 1271 1272]
blarg [ 271  271  271 ... 1345 1345 1345] [2052 2053 2054 ... 2788 2789 2790]
blarg [  95   95   95 ... 2801 2801 2801] [ 942  943  944 ... 3552 3553 3554]
blarg [ 362  362  362 ... 1503 1503 1503] [ 885  886  887 ... 2359 2360 2361]
Traceback (most recent call last):
  File "/home/fas/leonard/swk2/miniconda3/envs/maskRCNN/lib/python3.6/site-packages/keras/utils/data_utils.py", line 677, in _data_generator_task
    generator_output = next(self._generator)
  File "/home/fas/leonard/swk2/miniconda3/envs/maskRCNN/lib/python3.6/site-packages/mask_rcnn-2.1-py3.6.egg/mrcnn/model.py", line 1695, in data_generator
    use_mini_mask=config.USE_MINI_MASK)
  File "/home/fas/leonard/swk2/miniconda3/envs/maskRCNN/lib/python3.6/site-packages/mask_rcnn-2.1-py3.6.egg/mrcnn/model.py", line 1210, in load_image_gt
    mask, class_ids = dataset.load_mask(image_id)
  File "balloon.py", line 171, in load_mask
    mask[rr, cc, i] = 1
IndexError: index 2102 is out of bounds for axis 1 with size 2102
blarg [ 211  211  211 ... 1778 1778 1778] [ 905  906  907 ... 2178 2179 2180]
blarg [ 596  596  596 ... 2493 2493 2493] [ 618  619  620 ... 2066 2067 2068]
blarg [ 543  543  543 ... 2540 2540 2540] [2331 2332 2333 ... 3765 3766 3767]
blarg [ 468  468  468 ... 2431 2431 2431] [ 948  949  950 ... 2131 2132 2133]
blarg [ 408  408  408 ... 1279 1279 1279] [ 726  727  728 ... 2064 2065 2066]
blarg [ 279  279  279 ... 1927 1927 1927] [ 882  883  884 ... 2517 2518 2519]
blarg [ 563  563  563 ... 1375 1375 1375] [110 111 112 ... 909 910 911]
blarg [1433 1433 1433 ... 2109 2109 2109] [113 114 115 ... 904 905 906]
blarg [2148 2148 2148 ... 2756 2756 2756] [102 103 104 ... 912 913 914]
ERROR:root:Error processing image {'id': 'terramariaemedic00unse_14_0128.jpg', 'source': 'balloon', 'path': '../../datasets/illustrations/train/terramariaemedic00unse_14_0128.jpg', 'width': 3546, 'height': 4678, 'polygons': [{'name': 'rect', 'x': 819, 'y': 875, 'width': 1018, 'height': 1301}, {'name': 'rect', 'x': 1898, 'y': 5, 'width': 1592, 'height': 2162}, {'name': 'rect', 'x': 523, 'y': 3449, 'width': 1528, 'height': 870}, {'name': 'rect', 'x': 2111, 'y': 3032, 'width': 1370, 'height': 995}, {'name': 'rect', 'x': 176, 'y': 2236, 'width': 1870, 'height': 1153}]}
Traceback (most recent call last):
  File "/home/fas/leonard/swk2/miniconda3/envs/maskRCNN/lib/python3.6/site-packages/mask_rcnn-2.1-py3.6.egg/mrcnn/model.py", line 1695, in data_generator
    use_mini_mask=config.USE_MINI_MASK)
  File "/home/fas/leonard/swk2/miniconda3/envs/maskRCNN/lib/python3.6/site-packages/mask_rcnn-2.1-py3.6.egg/mrcnn/model.py", line 1210, in load_image_gt
    mask, class_ids = dataset.load_mask(image_id)
  File "balloon.py", line 171, in load_mask
    mask[rr, cc, i] = 1
IndexError: index 3546 is out of bounds for axis 1 with size 3546
blarg [ 468  468  468 ... 2431 2431 2431] [ 948  949  950 ... 2131 2132 2133]
blarg [ 267  267  267 ... 1621 1621 1621] [ 320  321  322 ... 1482 1483 1484]
blarg [ 311  311  311 ... 1570 1570 1570] [1717 1718 1719 ... 2806 2807 2808]
blarg [ 552  552  552 ... 1707 1707 1707] [1137 1138 1139 ... 2082 2083 2084]
blarg [  46   46   46 ... 2047 2047 2047] [ 219  220  221 ... 1774 1775 1776]
blarg [ 388  388  388 ... 1686 1686 1686] [1853 1854 1855 ... 2871 2872 2873]
blarg [ 538  538  538 ... 1595 1595 1595] [ 520  521  522 ... 1724 1725 1726]
blarg [ 190  190  190 ... 1707 1707 1707] [ 421  422  423 ... 2641 2642 2643]
blarg [ 557  557  557 ... 1268 1268 1268] [ 709  710  711 ... 1523 1524 1525]
ERROR:root:Error processing image {'id': '67440190R_0259.jpg', 'source': 'balloon', 'path': '../../datasets/illustrations/train/67440190R_0259.jpg', 'width': 3357, 'height': 4424, 'polygons': [{'name': 'rect', 'x': 596, 'y': 618, 'width': 1898, 'height': 1451}, {'name': 'rect', 'x': 543, 'y': 2331, 'width': 1998, 'height': 1437}]}
Traceback (most recent call last):
  File "/home/fas/leonard/swk2/miniconda3/envs/maskRCNN/lib/python3.6/site-packages/mask_rcnn-2.1-py3.6.egg/mrcnn/model.py", line 1695, in data_generator
    use_mini_mask=config.USE_MINI_MASK)
  File "/home/fas/leonard/swk2/miniconda3/envs/maskRCNN/lib/python3.6/site-packages/mask_rcnn-2.1-py3.6.egg/mrcnn/model.py", line 1210, in load_image_gt
    mask, class_ids = dataset.load_mask(image_id)
  File "balloon.py", line 171, in load_mask
    mask[rr, cc, i] = 1
IndexError: index 3357 is out of bounds for axis 1 with size 3357
ERROR:root:Error processing image {'id': '67440190R_0259.jpg', 'source': 'balloon', 'path': '../../datasets/illustrations/train/67440190R_0259.jpg', 'width': 3357, 'height': 4424, 'polygons': [{'name': 'rect', 'x': 596, 'y': 618, 'width': 1898, 'height': 1451}, {'name': 'rect', 'x': 543, 'y': 2331, 'width': 1998, 'height': 1437}]}
Traceback (most recent call last):
  File "/home/fas/leonard/swk2/miniconda3/envs/maskRCNN/lib/python3.6/site-packages/mask_rcnn-2.1-py3.6.egg/mrcnn/model.py", line 1695, in data_generator
    use_mini_mask=config.USE_MINI_MASK)
  File "/home/fas/leonard/swk2/miniconda3/envs/maskRCNN/lib/python3.6/site-packages/mask_rcnn-2.1-py3.6.egg/mrcnn/model.py", line 1210, in load_image_gt
    mask, class_ids = dataset.load_mask(image_id)
  File "balloon.py", line 171, in load_mask
    mask[rr, cc, i] = 1
IndexError: index 3357 is out of bounds for axis 1 with size 3357
ERROR:root:Error processing image {'id': 'gynecology00grav_0307.jpg', 'source': 'balloon', 'path': '../../datasets/illustrations/train/gynecology00grav_0307.jpg', 'width': 2329, 'height': 3708, 'polygons': [{'name': 'rect', 'x': 279, 'y': 882, 'width': 1649, 'height': 1638}]}
Traceback (most recent call last):
  File "/home/fas/leonard/swk2/miniconda3/envs/maskRCNN/lib/python3.6/site-packages/mask_rcnn-2.1-py3.6.egg/mrcnn/model.py", line 1695, in data_generator
    use_mini_mask=config.USE_MINI_MASK)
  File "/home/fas/leonard/swk2/miniconda3/envs/maskRCNN/lib/python3.6/site-packages/mask_rcnn-2.1-py3.6.egg/mrcnn/model.py", line 1210, in load_image_gt
    mask, class_ids = dataset.load_mask(image_id)
  File "balloon.py", line 171, in load_mask
    mask[rr, cc, i] = 1
IndexError: index 2329 is out of bounds for axis 1 with size 2329
ERROR:root:Error processing image {'id': 'b21648979_0064.jpg', 'source': 'balloon', 'path': '../../datasets/illustrations/train/b21648979_0064.jpg', 'width': 2309, 'height': 4147, 'polygons': [{'name': 'rect', 'x': 440, 'y': 1097, 'width': 1438, 'height': 1491}]}
Traceback (most recent call last):
  File "/home/fas/leonard/swk2/miniconda3/envs/maskRCNN/lib/python3.6/site-packages/mask_rcnn-2.1-py3.6.egg/mrcnn/model.py", line 1695, in data_generator
    use_mini_mask=config.USE_MINI_MASK)
  File "/home/fas/leonard/swk2/miniconda3/envs/maskRCNN/lib/python3.6/site-packages/mask_rcnn-2.1-py3.6.egg/mrcnn/model.py", line 1210, in load_image_gt
    mask, class_ids = dataset.load_mask(image_id)
  File "balloon.py", line 171, in load_mask
    mask[rr, cc, i] = 1
IndexError: index 2309 is out of bounds for axis 1 with size 2309
blarg [ 541  541  541 ... 1774 1774 1774] [ 117  118  119 ... 1328 1329 1330]
blarg [ 563  563  563 ... 1375 1375 1375] [110 111 112 ... 909 910 911]
blarg [1433 1433 1433 ... 2109 2109 2109] [113 114 115 ... 904 905 906]
blarg [2148 2148 2148 ... 2756 2756 2756] [102 103 104 ... 912 913 914]
blarg [ 460  460  460 ... 1604 1604 1604] [1046 1047 1048 ... 2293 2294 2295]
blarg [ 169  169  169 ... 1101 1101 1101] [ 533  534  535 ... 1364 1365 1366]
blarg [1161 1161 1161 ... 2093 2093 2093] [ 547  548  549 ... 1360 1361 1362]
blarg [ 617  617  617 ... 1637 1637 1637] [1987 1988 1989 ... 2880 2881 2882]
blarg [ 450  450  450 ... 1325 1325 1325] [ 557  558  559 ... 1487 1488 1489]
blarg [ 487  487  487 ... 1551 1551 1551] [ 991  992  993 ... 2271 2272 2273]
blarg [ 297  297  297 ... 1381 1381 1381] [1011 1012 1013 ... 2037 2038 2039]
blarg [ 900  900  900 ... 1653 1653 1653] [ 961  962  963 ... 2078 2079 2080]
blarg [ 440  440  440 ... 1877 1877 1877] [1097 1098 1099 ... 2585 2586 2587]
Traceback (most recent call last):
  File "/home/fas/leonard/swk2/miniconda3/envs/maskRCNN/lib/python3.6/site-packages/keras/utils/data_utils.py", line 677, in _data_generator_task
    generator_output = next(self._generator)
  File "/home/fas/leonard/swk2/miniconda3/envs/maskRCNN/lib/python3.6/site-packages/mask_rcnn-2.1-py3.6.egg/mrcnn/model.py", line 1695, in data_generator
    use_mini_mask=config.USE_MINI_MASK)
  File "/home/fas/leonard/swk2/miniconda3/envs/maskRCNN/lib/python3.6/site-packages/mask_rcnn-2.1-py3.6.egg/mrcnn/model.py", line 1210, in load_image_gt
    mask, class_ids = dataset.load_mask(image_id)
  File "balloon.py", line 171, in load_mask
    mask[rr, cc, i] = 1
IndexError: index 2309 is out of bounds for axis 1 with size 2309
ERROR:root:Error processing image {'id': 'b21932323_0260.jpg', 'source': 'balloon', 'path': '../../datasets/illustrations/train/b21932323_0260.jpg', 'width': 1811, 'height': 2946, 'polygons': [{'name': 'rect', 'x': 782, 'y': 1881, 'width': 373, 'height': 385}]}
Traceback (most recent call last):
  File "/home/fas/leonard/swk2/miniconda3/envs/maskRCNN/lib/python3.6/site-packages/mask_rcnn-2.1-py3.6.egg/mrcnn/model.py", line 1695, in data_generator
    use_mini_mask=config.USE_MINI_MASK)
  File "/home/fas/leonard/swk2/miniconda3/envs/maskRCNN/lib/python3.6/site-packages/mask_rcnn-2.1-py3.6.egg/mrcnn/model.py", line 1210, in load_image_gt
    mask, class_ids = dataset.load_mask(image_id)
  File "balloon.py", line 171, in load_mask
    mask[rr, cc, i] = 1
IndexError: index 1881 is out of bounds for axis 1 with size 1811
blarg [1565 1565 1565 ... 2315 2315 2315] [1622 1623 1624 ... 3528 3529 3530]
blarg [ 557  557  557 ... 1268 1268 1268] [ 709  710  711 ... 1523 1524 1525]
blarg [ 198  198  198 ... 2085 2085 2085] [1227 1228 1229 ... 2495 2496 2497]
blarg [ 173  173  173 ... 2302 2302 2302] [ 445  446  447 ... 1783 1784 1785]
blarg [  46   46   46 ... 2047 2047 2047] [ 219  220  221 ... 1774 1775 1776]
blarg [ 388  388  388 ... 1686 1686 1686] [1853 1854 1855 ... 2871 2872 2873]
blarg [ 538  538  538 ... 1595 1595 1595] [ 520  521  522 ... 1724 1725 1726]
blarg [ 541  541  541 ... 1774 1774 1774] [ 117  118  119 ... 1328 1329 1330]
ERROR:root:Error processing image {'id': 'terramariaemedic00unse_14_0140.jpg', 'source': 'balloon', 'path': '../../datasets/illustrations/train/terramariaemedic00unse_14_0140.jpg', 'width': 3527, 'height': 4678, 'polygons': [{'name': 'rect', 'x': 894, 'y': 158, 'width': 1024, 'height': 1808}, {'name': 'rect', 'x': 0, 'y': 2030, 'width': 1488, 'height': 1455}, {'name': 'rect', 'x': 1543, 'y': 2322, 'width': 1075, 'height': 1163}, {'name': 'rect', 'x': 2688, 'y': 2322, 'width': 830, 'height': 1159}, {'name': 'rect', 'x': 1974, 'y': 1242, 'width': 1539, 'height': 1010}, {'name': 'rect', 'x': 1891, 'y': 3532, 'width': 1622, 'height': 802}]}
Traceback (most recent call last):
  File "/home/fas/leonard/swk2/miniconda3/envs/maskRCNN/lib/python3.6/site-packages/mask_rcnn-2.1-py3.6.egg/mrcnn/model.py", line 1695, in data_generator
    use_mini_mask=config.USE_MINI_MASK)
  File "/home/fas/leonard/swk2/miniconda3/envs/maskRCNN/lib/python3.6/site-packages/mask_rcnn-2.1-py3.6.egg/mrcnn/model.py", line 1210, in load_image_gt
    mask, class_ids = dataset.load_mask(image_id)
  File "balloon.py", line 171, in load_mask
    mask[rr, cc, i] = 1
IndexError: index 3532 is out of bounds for axis 1 with size 3527
blarg [ 190  190  190 ... 1707 1707 1707] [ 421  422  423 ... 2641 2642 2643]
blarg [ 368  368  368 ... 1570 1570 1570] [ 593  594  595 ... 2876 2877 2878]
blarg [ 280  280  280 ... 1044 1044 1044] [ 226  227  228 ... 1701 1702 1703]
blarg [1076 1076 1076 ... 1722 1722 1722] [ 490  491  492 ... 1451 1452 1453]
blarg [ 460  460  460 ... 1604 1604 1604] [1046 1047 1048 ... 2293 2294 2295]
blarg [ 143  143  143 ... 1037 1037 1037] [519 520 521 ... 902 903 904]
blarg [ 857  857  857 ... 1735 1735 1735] [1201 1202 1203 ... 2463 2464 2465]
blarg [ 819  819  819 ... 1836 1836 1836] [ 875  876  877 ... 2173 2174 2175]
blarg [1898 1898 1898 ... 3489 3489 3489] [   5    6    7 ... 2164 2165 2166]
blarg [ 523  523  523 ... 2050 2050 2050] [3449 3450 3451 ... 4316 4317 4318]
blarg [107 107 107 ... 531 531 531] [ 978  979  980 ... 1578 1579 1580]
blarg [559 559 559 ... 980 980 980] [ 975  976  977 ... 1575 1576 1577]
blarg [ 985  985  985 ... 1393 1393 1393] [ 985  986  987 ... 1578 1579 1580]
blarg [1394 1394 1394 ... 1912 1912 1912] [1042 1043 1044 ... 1582 1583 1584]
blarg [ 431  431  431 ... 1582 1582 1582] [1121 1122 1123 ... 2348 2349 2350]
blarg [ 212  212  212 ... 1512 1512 1512] [ 717  718  719 ... 2504 2505 2506]
blarg [ 297  297  297 ... 1381 1381 1381] [1011 1012 1013 ... 2037 2038 2039]
blarg [ 189  189  189 ... 2609 2609 2609] [1028 1029 1030 ... 2681 2682 2683]
blarg [ 900  900  900 ... 1653 1653 1653] [ 961  962  963 ... 2078 2079 2080]
blarg [ 271  271  271 ... 1585 1585 1585] [ 612  613  614 ... 1971 1972 1973]
blarg [ 894  894  894 ... 1917 1917 1917] [ 158  159  160 ... 1963 1964 1965]
blarg [   0    0    0 ... 1487 1487 1487] [2030 2031 2032 ... 3482 3483 3484]
blarg [1543 1543 1543 ... 2617 2617 2617] [2322 2323 2324 ... 3482 3483 3484]
blarg [2688 2688 2688 ... 3517 3517 3517] [2322 2323 2324 ... 3478 3479 3480]
blarg [1974 1974 1974 ... 3512 3512 3512] [1242 1243 1244 ... 2249 2250 2251]
blarg [1891 1891 1891 ... 3512 3512 3512] [3532 3533 3534 ... 4331 4332 4333]
Traceback (most recent call last):
  File "/home/fas/leonard/swk2/miniconda3/envs/maskRCNN/lib/python3.6/site-packages/keras/utils/data_utils.py", line 677, in _data_generator_task
    generator_output = next(self._generator)
  File "/home/fas/leonard/swk2/miniconda3/envs/maskRCNN/lib/python3.6/site-packages/mask_rcnn-2.1-py3.6.egg/mrcnn/model.py", line 1695, in data_generator
    use_mini_mask=config.USE_MINI_MASK)
  File "/home/fas/leonard/swk2/miniconda3/envs/maskRCNN/lib/python3.6/site-packages/mask_rcnn-2.1-py3.6.egg/mrcnn/model.py", line 1210, in load_image_gt
    mask, class_ids = dataset.load_mask(image_id)
  File "balloon.py", line 171, in load_mask
    mask[rr, cc, i] = 1
IndexError: index 3532 is out of bounds for axis 1 with size 3527
ERROR:root:Error processing image {'id': 'transactionsstud4161coll_0123.jpg', 'source': 'balloon', 'path': '../../datasets/illustrations/train/transactionsstud4161coll_0123.jpg', 'width': 2204, 'height': 3345, 'polygons': [{'name': 'rect', 'x': 46, 'y': 219, 'width': 2002, 'height': 1558}, {'name': 'rect', 'x': 388, 'y': 1853, 'width': 1299, 'height': 1021}]}
Traceback (most recent call last):
  File "/home/fas/leonard/swk2/miniconda3/envs/maskRCNN/lib/python3.6/site-packages/mask_rcnn-2.1-py3.6.egg/mrcnn/model.py", line 1695, in data_generator
    use_mini_mask=config.USE_MINI_MASK)
  File "/home/fas/leonard/swk2/miniconda3/envs/maskRCNN/lib/python3.6/site-packages/mask_rcnn-2.1-py3.6.egg/mrcnn/model.py", line 1210, in load_image_gt
    mask, class_ids = dataset.load_mask(image_id)
  File "balloon.py", line 171, in load_mask
    mask[rr, cc, i] = 1
IndexError: index 2204 is out of bounds for axis 1 with size 2204
blarg [ 398  398  398 ... 1831 1831 1831] [1125 1126 1127 ... 2511 2512 2513]
blarg [ 190  190  190 ... 1707 1707 1707] [ 421  422  423 ... 2641 2642 2643]
blarg [ 228  228  228 ... 2022 2022 2022] [ 498  499  500 ... 2912 2913 2914]
blarg [  69   69   69 ... 2026 2026 2026] [ 890  891  892 ... 3141 3142 3143]
blarg [ 487  487  487 ... 1551 1551 1551] [ 991  992  993 ... 2271 2272 2273]
blarg [1565 1565 1565 ... 2315 2315 2315] [1622 1623 1624 ... 3528 3529 3530]
blarg [  46   46   46 ... 2047 2047 2047] [ 219  220  221 ... 1774 1775 1776]
blarg [ 388  388  388 ... 1686 1686 1686] [1853 1854 1855 ... 2871 2872 2873]
Traceback (most recent call last):
  File "/home/fas/leonard/swk2/miniconda3/envs/maskRCNN/lib/python3.6/site-packages/keras/utils/data_utils.py", line 677, in _data_generator_task
    generator_output = next(self._generator)
  File "/home/fas/leonard/swk2/miniconda3/envs/maskRCNN/lib/python3.6/site-packages/mask_rcnn-2.1-py3.6.egg/mrcnn/model.py", line 1695, in data_generator
    use_mini_mask=config.USE_MINI_MASK)
  File "/home/fas/leonard/swk2/miniconda3/envs/maskRCNN/lib/python3.6/site-packages/mask_rcnn-2.1-py3.6.egg/mrcnn/model.py", line 1210, in load_image_gt
    mask, class_ids = dataset.load_mask(image_id)
  File "balloon.py", line 171, in load_mask
    mask[rr, cc, i] = 1
IndexError: index 2204 is out of bounds for axis 1 with size 2204
ERROR:root:Error processing image {'id': 'lehrbuchderspeci001strm_0639.jpg', 'source': 'balloon', 'path': '../../datasets/illustrations/train/lehrbuchderspeci001strm_0639.jpg', 'width': 2065, 'height': 3269, 'polygons': [{'name': 'rect', 'x': 1314, 'y': 469, 'width': 320, 'height': 414}, {'name': 'rect', 'x': 1172, 'y': 1042, 'width': 641, 'height': 1660}]}
Traceback (most recent call last):
  File "/home/fas/leonard/swk2/miniconda3/envs/maskRCNN/lib/python3.6/site-packages/mask_rcnn-2.1-py3.6.egg/mrcnn/model.py", line 1695, in data_generator
    use_mini_mask=config.USE_MINI_MASK)
  File "/home/fas/leonard/swk2/miniconda3/envs/maskRCNN/lib/python3.6/site-packages/mask_rcnn-2.1-py3.6.egg/mrcnn/model.py", line 1210, in load_image_gt
    mask, class_ids = dataset.load_mask(image_id)
  File "balloon.py", line 171, in load_mask
    mask[rr, cc, i] = 1
IndexError: index 2065 is out of bounds for axis 1 with size 2065
blarg [ 198  198  198 ... 2085 2085 2085] [1227 1228 1229 ... 2495 2496 2497]
blarg [ 801  801  801 ... 1775 1775 1775] [ 385  386  387 ... 1272 1273 1274]
blarg [ 403  403  403 ... 1393 1393 1393] [ 330  331  332 ... 1449 1450 1451]
blarg [ 782  782  782 ... 1154 1154 1154] [1881 1882 1883 ... 2263 2264 2265]
blarg [ 368  368  368 ... 1570 1570 1570] [ 593  594  595 ... 2876 2877 2878]
blarg [ 819  819  819 ... 1836 1836 1836] [ 875  876  877 ... 2173 2174 2175]
blarg [1898 1898 1898 ... 3489 3489 3489] [   5    6    7 ... 2164 2165 2166]
blarg [ 523  523  523 ... 2050 2050 2050] [3449 3450 3451 ... 4316 4317 4318]
blarg [ 279  279  279 ... 1927 1927 1927] [ 882  883  884 ... 2517 2518 2519]
blarg [1314 1314 1314 ... 1633 1633 1633] [469 470 471 ... 880 881 882]
blarg [1172 1172 1172 ... 1812 1812 1812] [1042 1043 1044 ... 2699 2700 2701]
Traceback (most recent call last):
  File "/home/fas/leonard/swk2/miniconda3/envs/maskRCNN/lib/python3.6/site-packages/keras/utils/data_utils.py", line 677, in _data_generator_task
    generator_output = next(self._generator)
  File "/home/fas/leonard/swk2/miniconda3/envs/maskRCNN/lib/python3.6/site-packages/mask_rcnn-2.1-py3.6.egg/mrcnn/model.py", line 1695, in data_generator
    use_mini_mask=config.USE_MINI_MASK)
  File "/home/fas/leonard/swk2/miniconda3/envs/maskRCNN/lib/python3.6/site-packages/mask_rcnn-2.1-py3.6.egg/mrcnn/model.py", line 1210, in load_image_gt
    mask, class_ids = dataset.load_mask(image_id)
  File "balloon.py", line 171, in load_mask
    mask[rr, cc, i] = 1
IndexError: index 2065 is out of bounds for axis 1 with size 2065
ERROR:root:Error processing image {'id': 'b29123082_0081.jpg', 'source': 'balloon', 'path': '../../datasets/illustrations/train/b29123082_0081.jpg', 'width': 2024, 'height': 3346, 'polygons': [{'name': 'rect', 'x': 23, 'y': 788, 'width': 1988, 'height': 1534}]}
Traceback (most recent call last):
  File "/home/fas/leonard/swk2/miniconda3/envs/maskRCNN/lib/python3.6/site-packages/mask_rcnn-2.1-py3.6.egg/mrcnn/model.py", line 1695, in data_generator
    use_mini_mask=config.USE_MINI_MASK)
  File "/home/fas/leonard/swk2/miniconda3/envs/maskRCNN/lib/python3.6/site-packages/mask_rcnn-2.1-py3.6.egg/mrcnn/model.py", line 1210, in load_image_gt
    mask, class_ids = dataset.load_mask(image_id)
  File "balloon.py", line 171, in load_mask
    mask[rr, cc, i] = 1
IndexError: index 2024 is out of bounds for axis 1 with size 2024
blarg [ 487  487  487 ... 1551 1551 1551] [ 991  992  993 ... 2271 2272 2273]
blarg [ 348  348  348 ... 2411 2411 2411] [ 556  557  558 ... 2210 2211 2212]
blarg [ 527  527  527 ... 2132 2132 2132] [2629 2630 2631 ... 3747 3748 3749]
blarg [ 665  665  665 ... 1660 1660 1660] [ 823  824  825 ... 2583 2584 2585]
blarg [  95   95   95 ... 2801 2801 2801] [ 942  943  944 ... 3552 3553 3554]
blarg [ 596  596  596 ... 2493 2493 2493] [ 618  619  620 ... 2066 2067 2068]
blarg [ 543  543  543 ... 2540 2540 2540] [2331 2332 2333 ... 3765 3766 3767]
blarg [  23   23   23 ... 2010 2010 2010] [ 788  789  790 ... 2319 2320 2321]
Traceback (most recent call last):
  File "/home/fas/leonard/swk2/miniconda3/envs/maskRCNN/lib/python3.6/site-packages/keras/utils/data_utils.py", line 677, in _data_generator_task
    generator_output = next(self._generator)
  File "/home/fas/leonard/swk2/miniconda3/envs/maskRCNN/lib/python3.6/site-packages/mask_rcnn-2.1-py3.6.egg/mrcnn/model.py", line 1695, in data_generator
    use_mini_mask=config.USE_MINI_MASK)
  File "/home/fas/leonard/swk2/miniconda3/envs/maskRCNN/lib/python3.6/site-packages/mask_rcnn-2.1-py3.6.egg/mrcnn/model.py", line 1210, in load_image_gt
    mask, class_ids = dataset.load_mask(image_id)
  File "balloon.py", line 171, in load_mask
    mask[rr, cc, i] = 1
IndexError: index 2024 is out of bounds for axis 1 with size 2024
ERROR:root:Error processing image {'id': 'textbookofdental00burc_0367.jpg', 'source': 'balloon', 'path': '../../datasets/illustrations/train/textbookofdental00burc_0367.jpg', 'width': 1990, 'height': 3381, 'polygons': [{'name': 'rect', 'x': 211, 'y': 905, 'width': 1568, 'height': 1276}]}
Traceback (most recent call last):
  File "/home/fas/leonard/swk2/miniconda3/envs/maskRCNN/lib/python3.6/site-packages/mask_rcnn-2.1-py3.6.egg/mrcnn/model.py", line 1695, in data_generator
    use_mini_mask=config.USE_MINI_MASK)
  File "/home/fas/leonard/swk2/miniconda3/envs/maskRCNN/lib/python3.6/site-packages/mask_rcnn-2.1-py3.6.egg/mrcnn/model.py", line 1210, in load_image_gt
    mask, class_ids = dataset.load_mask(image_id)
  File "balloon.py", line 171, in load_mask
    mask[rr, cc, i] = 1
IndexError: index 1990 is out of bounds for axis 1 with size 1990
blarg [ 227  227  227 ... 1621 1621 1621] [ 851  852  853 ... 1875 1876 1877]
blarg [ 263  263  263 ... 1351 1351 1351] [ 945  946  947 ... 1369 1370 1371]
blarg [ 169  169  169 ... 1101 1101 1101] [ 533  534  535 ... 1364 1365 1366]
blarg [1161 1161 1161 ... 2093 2093 2093] [ 547  548  549 ... 1360 1361 1362]
blarg [ 617  617  617 ... 1637 1637 1637] [1987 1988 1989 ... 2880 2881 2882]
blarg [ 198  198  198 ... 1506 1506 1506] [ 271  272  273 ... 1723 1724 1725]
blarg [ 270  270  270 ... 2237 2237 2237] [ 252  253  254 ... 1564 1565 1566]
blarg [ 297  297  297 ... 1381 1381 1381] [1011 1012 1013 ... 2037 2038 2039]
blarg [ 596  596  596 ... 2493 2493 2493] [ 618  619  620 ... 2066 2067 2068]
blarg [ 543  543  543 ... 2540 2540 2540] [2331 2332 2333 ... 3765 3766 3767]
blarg [ 782  782  782 ... 1154 1154 1154] [1881 1882 1883 ... 2263 2264 2265]
blarg [ 211  211  211 ... 1778 1778 1778] [ 905  906  907 ... 2178 2179 2180]
Traceback (most recent call last):
  File "/home/fas/leonard/swk2/miniconda3/envs/maskRCNN/lib/python3.6/site-packages/keras/utils/data_utils.py", line 677, in _data_generator_task
    generator_output = next(self._generator)
  File "/home/fas/leonard/swk2/miniconda3/envs/maskRCNN/lib/python3.6/site-packages/mask_rcnn-2.1-py3.6.egg/mrcnn/model.py", line 1695, in data_generator
    use_mini_mask=config.USE_MINI_MASK)
  File "/home/fas/leonard/swk2/miniconda3/envs/maskRCNN/lib/python3.6/site-packages/mask_rcnn-2.1-py3.6.egg/mrcnn/model.py", line 1210, in load_image_gt
    mask, class_ids = dataset.load_mask(image_id)
  File "balloon.py", line 171, in load_mask
    mask[rr, cc, i] = 1
IndexError: index 1990 is out of bounds for axis 1 with size 1990
Epoch 1/30

  1/100 [..............................] - ETA: 1:00:06 - loss: 3.5674 - rpn_class_loss: 0.0260 - rpn_bbox_loss: 3.2571 - mrcnn_class_loss: 0.2843 - mrcnn_bbox_loss: 0.0000e+00 - mrcnn_mask_loss: 0.0000e+00Traceback (most recent call last):
  File "balloon.py", line 371, in <module>
    train(model)
  File "balloon.py", line 206, in train
    layers='heads')
  File "/home/fas/leonard/swk2/miniconda3/envs/maskRCNN/lib/python3.6/site-packages/mask_rcnn-2.1-py3.6.egg/mrcnn/model.py", line 2328, in train
  File "/home/fas/leonard/swk2/miniconda3/envs/maskRCNN/lib/python3.6/site-packages/keras/legacy/interfaces.py", line 91, in wrapper
    return func(*args, **kwargs)
  File "/home/fas/leonard/swk2/miniconda3/envs/maskRCNN/lib/python3.6/site-packages/keras/engine/training.py", line 2194, in fit_generator
    generator_output = next(output_generator)
  File "/home/fas/leonard/swk2/miniconda3/envs/maskRCNN/lib/python3.6/site-packages/keras/utils/data_utils.py", line 793, in get
    six.reraise(value.__class__, value, value.__traceback__)
  File "/home/fas/leonard/swk2/miniconda3/envs/maskRCNN/lib/python3.6/site-packages/six.py", line 693, in reraise
    raise value
IndexError: index 2025 is out of bounds for axis 1 with size 2025
